Workbook
Name aa: #REF!
Name aaa: #REF!
Name asd: '[1]Market ( Mar) '!#REF!
Name atr: #REF!
Name b: #REF!
Name bb: #REF!
Name Beg_Bal: #REF!
Name Cash_Cr: #REF!
Name Cash_Dr: #REF!
Name cc: #REF!
Name ccc: #REF!
Name cr: #REF!
Name crs: #REF!
Name Data: #REF!
Name dd: #REF!
Name ddd: #REF!
Name dr: #REF!
Name drs: #REF!
Name End_Bal: #REF!
Name Extra_Pay: #REF!
Name fgf: #REF!
Name fgjhj: #REF!
Name Full_Print: #REF!
Name Header_Row: ROW(#REF!)
Name hjj: #REF!
Name hjkjk: #REF!
Name hmjhj: #REF!
Name Int: #REF!
Name Interest_Rate: #REF!
Name jbkjkl: #REF!
Name kdt: #REF!
Name Last_Row: IF(Values_Entered,Header_Row+Number_of_Payments,Header_Row)
Name Loan_Amount: #REF!
Name Loan_Start: #REF!
Name Loan_Years: #REF!
Name LSO: #REF!
Name lsoq: #REF!
Name mms: #REF!
Name neew: #REF!
Name New: #REF!
Name Num_Pmt_Per_Year: #REF!
Name Number_of_Payments: MATCH(0.01,End_Bal,-1)+1
Name Opening_Cr: #REF!
Name Opening_Dr: #REF!
Name Pay_Date: #REF!
Name Pay_Num: #REF!
Name Payment_Date: DATE(YEAR([0]!Loan_Start),MONTH([0]!Loan_Start)+Payment_Number,DAY([0]!Loan_Start))
Name Payment_Date: DATE(YEAR(Loan_Start),MONTH(Loan_Start)+Payment_Number,DAY(Loan_Start))
Name Princ: #REF!
Name Print_Area_Reset: OFFSET(Full_Print,0,0,Last_Row)
Name s: #REF!
Name Sched_Pay: #REF!
Name Scheduled_Extra_Payments: #REF!
Name Scheduled_Interest_Rate: #REF!
Name Scheduled_Monthly_Payment: #REF!
Name smm: #REF!
Name smmm: '[1]Market ( Mar) '!#REF!
Name tdk: #REF!
Name Total_Interest: #REF!
Name Total_Pay: #REF!

Sheet Table
A1: Stock ID | B1: Particular | C1: ml | D1: Qty | E1: Column1 | F1: Sales Price | H1: No | I1: ကုန်သည် | J1: လိပ်စာ | K1: Township | L1: Sales | N1: Particular | P1: Car No. | R1: PG Name | T1: Stock ID | U1: Particular | V1: ml | W1: Qty | X1: Column1 | Y1: Sales Price
A2: ZVK-700 | B2: "ဇေ" Vodka 700ml | C2: 0.7 | D2: 12 | E2: BE | F2: 2020 | H2: SC | I2: စံချိန် | J2: ရမည်းသင်း | K2: Yamethin | L2: WholeSales/Contract | N2: ကုန်ရောင်း(လက်ငင်း) | P2: 4R-2966 | R2: နီနီအောင် | T2: 700-Col | U2: Columbus Whisky 700 Ml | V2: 0.7 | W2: 12 | X2: Whisky | Y2: 4000
A3: Zay-640 | B3: ဇေ အရက်သန့် | C3: 0.64 | D3: 14 | E3: BE | F3: 1380 | H3: UWN | I3: ဦးဝင်းနိုင် | J3: လျှော်ပင် | K3: Wandwin | L3: WholeSales/Contract | N3: ကုန်ရောင်း(အကြွေး) | P3: 5H-1758 | R3: အေးသဇင်မြင့် | T3: 350-Col | U3: Columbus Whisky 350 Ml | V3: 0.35 | W3: 24 | X3: Whisky | Y3: 2000
A4: Zay 1000 | B4: ဇေ ကော် 1Ltr | C4: 1 | D4: 12 | E4: BE | F4: 1680 | H4: SM(NST) | I4: ရွှေမြင်း(ငွေစည်တော်) | J4: ဝမ်းတွင်း | K4: Wandwin | L4: WholeSales/Contract | N4: ကုန်ရောင်းပြန်သွင်း | P4: 4F-9227 | R4: မြင်မြတ်မျိုး | T4: 175-Col | U4: Columbus Whisky 175 Ml | V4: 0.175 | W4: 48 | X4: Whisky | Y4: 1100
A5: Zay 600 | B5: ဇေ ကော် .6 Ltr | C5: 0.6 | D5: 12 | E5: BE | F5: 1130 | H5: SM(STMT) | I5: ရွှေမြင်း(ရွှေတမာတန်း) | J5: ဝမ်းတွင်း | K5: Wandwin | L5: WholeSales/Contract | N5: ဈေးဟောင်းလျှော့ | P5: 3R-5803 | R5: မီမီဇော် | T5: 700-SRS | U5: Columbus Super Red Smooth 700 Ml | V5: 0.7 | W5: 12 | X5: Whisky | Y5: 5200
A6: KK 25% 1000 | B6: ကောင်းကြည် ကော် 25% (1Ltr ) | C6: 1 | D6: 12 | E6: BE | F6: 1530 | H6: SM(SNG) | I6: ရွှေမြင်း(ရွှေနဂါး) | J6: ဝမ်းတွင်း | K6: Wandwin | L6: WholeSales/Contract | N6: ကော်မရှင် | P6: 7F-9857 | R6: အေးချမ်းမို့မို့ | T6: 350-SRS | U6: Columbus Super Red Smooth 350 Ml | V6: 0.35 | W6: 24 | X6: Whisky | Y6: 2600
H7: SM(KTT) | I7: ရွှေမြင်း(ကိုထွန်းထွန်း) | J7: သဲတော | K7: Wandwin | L7: WholeSales/Contract | N7: အရက်ဖာကော်မရှင် | P7: 3I-1960 | R7: သိင်္ဂီရွှေ | T7: 175-SRS | U7: Columbus Super Red Smooth 175 Ml | V7: 0.175 | W7: 48 | X7: Whisky | Y7: 1450
A8: KK 25% 600 | B8: ကောင်းကြည် ကော် 25%(.6 Ltr) | C8: 0.6 | D8: 12 | E8: BE | F8: 1090 | H8: SM(KMM) | I8: ရွှေမြင်း(ကိုမျိုးမင်း) | J8: သာစည် | K8: Tharzi | L8: WholeSales/Contract | N8: အကွဲ | P8: 1G-8948 | R8: ဝေဝေနိုင် | T8: 700-FR | U8: Formula Rum 700ml | V8: 0.7 | W8: 12 | X8: Formula | Y8: 3600
H9: SM(TTW) | I9: ရွှေမြင်း(တိုးတက်ဝေ) | J9: သာစည် | K9: Tharzi | L9: WholeSales/Contract | N9: လက်ဆောင် | P9: 6Q-5306 | R9: သက်မွန်မြင့် | T9: 350-FR | U9: Formula Rum 350ml | V9: 0.35 | W9: 24 | X9: Formula | Y9: 2100
A10: SMT | B10: ရွှေမင်းသားခေါင်ရည် | C10: 0.64 | D10: 24 | E10: BE | F10: 800 | H10: SM(MBY) | I10: ရွှေမြင်း(မိဘရိပ်) | J10: သာစည် | K10: Tharzi | L10: WholeSales/Contract | N10: ဖောက်တိုက် | P10: 6Q-2768 | R10: ရင်ရင်သိန်း
H11: MM | I11: မြို့မ | J11: တောင်သာ | K11: Taungthar | L11: WholeSales/Contract | N11: FOC | P11: 7Q-8019 | R11: ခိုင်သဇင်ဝင်း
H12: SM(NL) | I12: ရွှေမြင်း(ကိုဉာဏ်လင်း) | J12: ပျော်ဘွယ် | K12: Pyawbwe | L12: WholeSales/Contract | N12: ကားကွဲ | P12: 6Q-3948
A13: SMT MK | B13: ရွှေမင်းသားမန်ကျည်းခေါင်ရည် | C13: 0.64 | D13: 14 | E13: BE | F13: 830 | H13: SM(KASM) | I13: ရွှေမြင်း(ကိုအောင်စန်းမြင့်) | J13: ပျော်ဘွယ် | K13: Pyawbwe | L13: WholeSales/Contract | N13: ကုန်သည်လက်ဆောင် | P13: 2R-8625
H14: SM(PG) | I14: ရွှေမြင်း(ပေါ်ကြီး) | J14: ပျော်ဘွယ် | K14: Pyawbwe | L14: WholeSales/Contract | N14: စစ်ဆေးရေးဂိတ်လက်ဆောင် | P14: 5D-9867
A15: Z red-700 | B15: ဇေယျဝတီ Red | C15: 0.7 | D15: 12 | E15: BE | F15: 1800 | H15: SM(MTN) | I15: ရွှေမြင်း(မင်းသက်နောင်) | J15: ပျော်ဘွယ် | K15: Pyawbwe | L15: WholeSales/Contract | P15: 3F-2352
A16: Z Red-1000 | B16: ဇေယျဝတီ Red | C16: 1 | D16: 12 | E16: BE | F16: 1680 | H16: SM(MT) | I16: ‌ရွှေမြင်း(မြို့တော်) | J16: ‌ပျော်ဘွယ် | K16: Pyawbwe | L16: WholeSales/Contract
A17: Z red-640 | B17: ဇေယျဝတီ Red | C17: 0.64 | D17: 14 | E17: BE | F17: 1330 | H17: SM(MSS) | I17: ရွှေမြင်း(မိတ်ဆွေစစ်) | J17: ပျော်ဘွယ် | K17: Pyawbwe | L17: WholeSales/Contract
H18: SM(Mka) | I18: ရွှေမြင်း(မေခ) | J18: ‌ပျော်ဘွယ် | K18: Pyawbwe | L18: WholeSales/Contract
A19: Z red-640 Army | B19: ဇေယျဝတီ Red ပု | C19: 0.64 | D19: 14 | E19: BE | F19: 1600 | H19: SM(SS) | I19: ရွှေမြင်း(ရွှေဆု) | J19: ‌ပျော်ဘွယ် | K19: Pyawbwe | L19: WholeSales/Contract
H20: SM(SMM) | I20: ရွှေမြင်း(ရွှေမြင့်မိုရ်) | J20: ပျော်ဘွယ် | K20: Pyawbwe | L20: WholeSales/Contract
A21: Z red-680 Army | B21: ဇေယျဝတီ Red ပု | C21: 0.68 | D21: 12 | E21: BE | F21: 1550 | H21: SM(ST) | I21: ရွှေမြင်း(ရှိုင်းစတား) | J21: ပျော်ဘွယ် | K21: Pyawbwe | L21: WholeSales/Contract
H22: UYM | I22: ဦးရဲမြင့် | J22: ပျော်ဘွယ် | K22: Pyawbwe | L22: WholeSales/Contract
A23: 2 in 1 | B23: 2 in 1 မန်ကျည်း | C23: 0.64 | D23: 14 | E23: BE | F23: 1350 | H23: SM(UMA) | I23: ရွှေမြင်း(ဦးမြင့်အောင်) | J23: ယင်းတော် | K23: Pyawbwe | L23: WholeSales/Contract
H24: KH | I24: ကောင်းဟိန်း | J24: ပခုက္ကူ | K24: Pakkoku | L24: WholeSales/Contract
A25: DGMK | B25: ဒဂုံမန်ကျည်း | C25: 0.64 | D25: 14 | E25: BE | F25: 1280 | H25: UTM | I25: ဦးတင်မောင် | J25: ပခုက္ကူ | K25: Pakkoku | L25: WholeSales/Contract
H26: SM(KMH) | I26: ရွှေမြင်း(မခင်မာဌေး) | J26: ကျွဲတပ်ဆုံ | K26: Meiktila | L26: WholeSales/Contract
A27: KK-640 | B27: ကောင်းကြည် | C27: 0.64 | D27: 14 | E27: BE | F27: 1330 | H27: SM(SLP) | I27: ရွှေမြင်း(ရွှေလွန်းပျံ) | J27: စက်မှုဇုံ | K27: Meiktila | L27: WholeSales/Contract
H28: SM(YMH) | I28: ရွှေမြင်း(ရဲမာန်ဟိန်း) | J28: စက်မှုဇုံ | K28: Meiktila | L28: WholeSales/Contract
A29: L | B29: သံပုရာအရက် | C29: 0.64 | D29: 14 | E29: BE | F29: 1330 | H29: SCT | I29: ‌ရွှေခြင်္သေ့ | J29: မိတ္ထီလာ | K29: Meiktila | L29: WholeSales/Contract
H30: SM | I30: ရွှေမြင်း | J30: မိတ္ထီလာ | K30: Meiktila | L30: WholeSales/Contract
A31: DGNN | B31: ဒဂုံနာနတ် | C31: 0.64 | D31: 24 | E31: BE | F31: 1330 | H31: SM(KCT) | I31: ရွှေမြင်း(ကျော်ချမ်းသာ) | J31: မိတ္ထီလာ | K31: Meiktila | L31: WholeSales/Contract
H32: SM(KMA) | I32: ရွှေမြင်း(ကိုမောင်အေး) | J32: မိတ္ထီလာ | K32: Meiktila | L32: WholeSales/Contract
A33: DGT | B33: ဒဂုံအရက်သန့် | C33: 0.64 | D33: 14 | E33: BE | F33: 1330 | H33: SM(HK) | I33: ရွှေမြင်း(ထူးကျော်) | J33: မိတ္ထီလာ | K33: Meiktila | L33: WholeSales/Contract
H34: SM(SCT) | I34: ရွှေမြင်း(ရွှေခြင်္သေ့) | J34: မိတ္ထီလာ | K34: Meiktila | L34: WholeSales/Contract
A35: WO | B35: လိမ္မော်ဖြူ | C35: 0.64 | D35: 24 | E35: BE | F35: 1330 | H35: SM(AYWD) | I35: ရွှေမြင်း(ဧရာဝတီ) | J35: မိတ္ထီလာ | K35: Meiktila | L35: WholeSales/Contract
A36: WO-1000 | B36: လိမ္မော်ဖြူ | C36: 1 | D36: 12 | E36: BE | H36: UAM(KT) | I36: ဦးအောင်မိုး(ကောင်းသန့်) | J36: မိတ္ထီလာ | K36: Meiktila | L36: WholeSales/Contract
A37: BC | B37: Black Cat | C37: 0.64 | D37: 24 | E37: BE | F37: 1330 | H37: KK | I37: ကျော်ကြား | J37: မလှိုင် | K37: Mahlaing | L37: WholeSales/Contract
H38: MYYA | I38: မယဉ်ယဉ်အေး | J38: မလှိုင် | K38: Mahlaing | L38: WholeSales/Contract
A39: KMK | B39: ကင်းမြီးကောက် | C39: 0.64 | D39: 14 | E39: BE | F39: 1330 | H39: SM(KK) | I39: ရွှေမြင်း(ကျော်ကြား) | J39: မလှိုင် | K39: Mahlaing | L39: WholeSales/Contract
H40: SM(SEIN) | I40: ရွှေမြင်း(စိန်) | J40: မလှိုင် | K40: Mahlaing | L40: WholeSales/Contract
...

Sheet DailySales
A1: Year | B1: Month | C1: Date | D1: Today | E1: Period | F1: BE/Whisky | G1: VoucherNo | H1: CarNo | I1: CustomerID | J1: ကုန်သည်အမည် | K1: Township | L1: လိပ်စာ | M1: Sales | N1: Particular | O1: StockID | P1: StockName | Q1: ML | R1: ပါဝင်မှု | S1: bottle | T1: Parking | U1: SalesPK | V1: SalesBot | W1: Liter | X1: နှုံး | Y1: သင့်ငွေ | Z1: စာရင်းဖွင့် | AA1: ဈေးဟောင်းလျှော့ | AB1: ‌ကော်မရှင် | AC1: ‌ဈေးလျှော့ | AD1: ကားခလျှော့ | AE1: ကားခ+ | AF1: ငွေရသည့်နေ့ | AG1: ကြွေးရငွေ | AH1: ငွေရသည့်နေ့(၂) | AI1: ကြွေးရငွေ2 | AJ1: ငွေရသည့်နေ့(၃) | AK1: ကြွေးရငွေ3 | AL1: ငွေရသည့်နေ့ ၄ | AM1: ကြွေးရငွေ4 | AN1: အကြွေးကျန်2
A2: =YEAR(C2) -> 2024 | B2: =MONTH(C2) -> 11 | C2: 45597 | D2: =TODAY() -> 46097 | E2: =DATEDIF(C2,D2,"M")&"-Months" -> 16-Months | F2: =VLOOKUP(O2,Stock[],5,FALSE) -> BE | I2: TZP | J2: =VLOOKUP(I2,Customers[],2,FALSE) -> သဇင်ဖြူ | K2: =VLOOKUP(I2,Customers[],4,FALSE) -> Meiktila | L2: =VLOOKUP(Table85[[#This Row],[CustomerID]],Table!H:K,3,0) -> မိတ္ထီလာ | M2: =VLOOKUP(I2,Customers[],5,FALSE) -> Van-2 | N2: ကုန်ရောင်း(အကြွေး) | O2: BE Debtors | P2: =VLOOKUP(O2,Stock[],2,FALSE) -> BE Debtors Opening | Q2: =VLOOKUP(O2,Stock[],3,FALSE) -> 0 | R2: =VLOOKUP(O2,Stock[],4,FALSE) -> 0 | V2: =+DailySales!$T2*DailySales!$R2 -> 0 | W2: =+DailySales!$V2*DailySales!$Q2 -> 0 | X2: =VLOOKUP(O2,Stock[],6,FALSE) -> 0 | Y2: =+DailySales!$V2*DailySales!$X2 -> 0 | Z2: 626550 | AN2: =Table85[[#This Row],[သင့်ငွေ]]+Table85[[#This Row],[စာရင်းဖွင့်]]-Table85[[#This Row],[ဈေးဟောင်းလျှော့]]-Table85[[#This Row],[‌ကော်မရှင်]]-Table85[[#This Row],[‌ဈေးလျှော့]]-Table85[[#This Row],[ကားခလျှော့]]+Table85[[#This Row],[ကားခ+]]-Table85[[#This Row],[ကြွေးရငွေ2]]-Table85[[#This Row],[ကြွေးရငွေ3]]-Table85[[#This Row],[ကြွေးရငွေ4]]-Table85[[#This Row],[ကြွေးရငွေ]] -> 626550
A3: =YEAR(C3) -> 2024 | B3: =MONTH(C3) -> 11 | C3: 45597 | D3: =TODAY() -> 46097 | E3: =DATEDIF(C3,D3,"M")&"-Months" -> 16-Months | F3: =VLOOKUP(O3,Stock[],5,FALSE) -> BE | I3: MKKW | J3: =VLOOKUP(I3,Customers[],2,FALSE) -> မကြည်ကြည်ဝင်း | K3: =VLOOKUP(I3,Customers[],4,FALSE) -> 0 | L3: =VLOOKUP(Table85[[#This Row],[CustomerID]],Table!H:K,3,0) -> 0 | M3: =VLOOKUP(I3,Customers[],5,FALSE) -> Van-2 | N3: ကုန်ရောင်း(အကြွေး) | O3: BE Debtors | P3: =VLOOKUP(O3,Stock[],2,FALSE) -> BE Debtors Opening | Q3: =VLOOKUP(O3,Stock[],3,FALSE) -> 0 | R3: =VLOOKUP(O3,Stock[],4,FALSE) -> 0 | V3: =+DailySales!$T3*DailySales!$R3 -> 0 | W3: =+DailySales!$V3*DailySales!$Q3 -> 0 | X3: =VLOOKUP(O3,Stock[],6,FALSE) -> 0 | Y3: =+DailySales!$V3*DailySales!$X3 -> 0 | Z3: 553800 | AN3: =Table85[[#This Row],[သင့်ငွေ]]+Table85[[#This Row],[စာရင်းဖွင့်]]-Table85[[#This Row],[ဈေးဟောင်းလျှော့]]-Table85[[#This Row],[‌ကော်မရှင်]]-Table85[[#This Row],[‌ဈေးလျှော့]]-Table85[[#This Row],[ကားခလျှော့]]+Table85[[#This Row],[ကားခ+]]-Table85[[#This Row],[ကြွေးရငွေ2]]-Table85[[#This Row],[ကြွေးရငွေ3]]-Table85[[#This Row],[ကြွေးရငွေ4]]-Table85[[#This Row],[ကြွေးရငွေ]] -> 553800
A4: =YEAR(C4) -> 2024 | B4: =MONTH(C4) -> 11 | C4: 45597 | D4: =TODAY() -> 46097 | E4: =DATEDIF(C4,D4,"M")&"-Months" -> 16-Months | F4: =VLOOKUP(O4,Stock[],5,FALSE) -> BE | I4: ASO | J4: =VLOOKUP(I4,Customers[],2,FALSE) -> အောင်ဆွေဦး | K4: =VLOOKUP(I4,Customers[],4,FALSE) -> 0 | L4: =VLOOKUP(Table85[[#This Row],[CustomerID]],Table!H:K,3,0) -> 0 | M4: =VLOOKUP(I4,Customers[],5,FALSE) -> Van-2 | N4: ကုန်ရောင်း(အကြွေး) | O4: BE Debtors | P4: =VLOOKUP(O4,Stock[],2,FALSE) -> BE Debtors Opening | Q4: =VLOOKUP(O4,Stock[],3,FALSE) -> 0 | R4: =VLOOKUP(O4,Stock[],4,FALSE) -> 0 | V4: =+DailySales!$T4*DailySales!$R4 -> 0 | W4: =+DailySales!$V4*DailySales!$Q4 -> 0 | X4: =VLOOKUP(O4,Stock[],6,FALSE) -> 0 | Y4: =+DailySales!$V4*DailySales!$X4 -> 0 | Z4: 1877190 | AN4: =Table85[[#This Row],[သင့်ငွေ]]+Table85[[#This Row],[စာရင်းဖွင့်]]-Table85[[#This Row],[ဈေးဟောင်းလျှော့]]-Table85[[#This Row],[‌ကော်မရှင်]]-Table85[[#This Row],[‌ဈေးလျှော့]]-Table85[[#This Row],[ကားခလျှော့]]+Table85[[#This Row],[ကားခ+]]-Table85[[#This Row],[ကြွေးရငွေ2]]-Table85[[#This Row],[ကြွေးရငွေ3]]-Table85[[#This Row],[ကြွေးရငွေ4]]-Table85[[#This Row],[ကြွေးရငွေ]] -> 1877190
A5: =YEAR(C5) -> 2024 | B5: =MONTH(C5) -> 11 | C5: 45597 | D5: =TODAY() -> 46097 | E5: =DATEDIF(C5,D5,"M")&"-Months" -> 16-Months | F5: =VLOOKUP(O5,Stock[],5,FALSE) -> BE | I5: KKHL | J5: =VLOOKUP(I5,Customers[],2,FALSE) -> ကိုကျော်ဌေးလွင် | K5: =VLOOKUP(I5,Customers[],4,FALSE) -> 0 | L5: =VLOOKUP(Table85[[#This Row],[CustomerID]],Table!H:K,3,0) -> 0 | M5: =VLOOKUP(I5,Customers[],5,FALSE) -> Van-2 | N5: ကုန်ရောင်း(အကြွေး) | O5: BE Debtors | P5: =VLOOKUP(O5,Stock[],2,FALSE) -> BE Debtors Opening | Q5: =VLOOKUP(O5,Stock[],3,FALSE) -> 0 | R5: =VLOOKUP(O5,Stock[],4,FALSE) -> 0 | V5: =+DailySales!$T5*DailySales!$R5 -> 0 | W5: =+DailySales!$V5*DailySales!$Q5 -> 0 | X5: =VLOOKUP(O5,Stock[],6,FALSE) -> 0 | Y5: =+DailySales!$V5*DailySales!$X5 -> 0 | Z5: 877060 | AN5: =Table85[[#This Row],[သင့်ငွေ]]+Table85[[#This Row],[စာရင်းဖွင့်]]-Table85[[#This Row],[ဈေးဟောင်းလျှော့]]-Table85[[#This Row],[‌ကော်မရှင်]]-Table85[[#This Row],[‌ဈေးလျှော့]]-Table85[[#This Row],[ကားခလျှော့]]+Table85[[#This Row],[ကားခ+]]-Table85[[#This Row],[ကြွေးရငွေ2]]-Table85[[#This Row],[ကြွေးရငွေ3]]-Table85[[#This Row],[ကြွေးရငွေ4]]-Table85[[#This Row],[ကြွေးရငွေ]] -> 877060
A6: =YEAR(C6) -> 2024 | B6: =MONTH(C6) -> 11 | C6: 45597 | D6: =TODAY() -> 46097 | E6: =DATEDIF(C6,D6,"M")&"-Months" -> 16-Months | F6: =VLOOKUP(O6,Stock[],5,FALSE) -> BE | I6: PTT | J6: =VLOOKUP(I6,Customers[],2,FALSE) -> ပစ်တိုင်းထောင် | K6: =VLOOKUP(I6,Customers[],4,FALSE) -> Meiktila | L6: =VLOOKUP(Table85[[#This Row],[CustomerID]],Table!H:K,3,0) -> မိတ္ထီလာ | M6: =VLOOKUP(I6,Customers[],5,FALSE) -> Van-2 | N6: ကုန်ရောင်း(အကြွေး) | O6: BE Debtors | P6: =VLOOKUP(O6,Stock[],2,FALSE) -> BE Debtors Opening | Q6: =VLOOKUP(O6,Stock[],3,FALSE) -> 0 | R6: =VLOOKUP(O6,Stock[],4,FALSE) -> 0 | V6: =+DailySales!$T6*DailySales!$R6 -> 0 | W6: =+DailySales!$V6*DailySales!$Q6 -> 0 | X6: =VLOOKUP(O6,Stock[],6,FALSE) -> 0 | Y6: =+DailySales!$V6*DailySales!$X6 -> 0 | Z6: 1555240 | AN6: =Table85[[#This Row],[သင့်ငွေ]]+Table85[[#This Row],[စာရင်းဖွင့်]]-Table85[[#This Row],[ဈေးဟောင်းလျှော့]]-Table85[[#This Row],[‌ကော်မရှင်]]-Table85[[#This Row],[‌ဈေးလျှော့]]-Table85[[#This Row],[ကားခလျှော့]]+Table85[[#This Row],[ကားခ+]]-Table85[[#This Row],[ကြွေးရငွေ2]]-Table85[[#This Row],[ကြွေးရငွေ3]]-Table85[[#This Row],[ကြွေးရငွေ4]]-Table85[[#This Row],[ကြွေးရငွေ]] -> 1555240
A7: =YEAR(C7) -> 2024 | B7: =MONTH(C7) -> 11 | C7: 45597 | D7: =TODAY() -> 46097 | E7: =DATEDIF(C7,D7,"M")&"-Months" -> 16-Months | F7: =VLOOKUP(O7,Stock[],5,FALSE) -> BE | I7: M-LC | J7: =VLOOKUP(I7,Customers[],2,FALSE) -> M Liquar City | K7: =VLOOKUP(I7,Customers[],4,FALSE) -> 0 | L7: =VLOOKUP(Table85[[#This Row],[CustomerID]],Table!H:K,3,0) -> 0 | M7: =VLOOKUP(I7,Customers[],5,FALSE) -> Van-2 | N7: ကုန်ရောင်း(အကြွေး) | O7: BE Debtors | P7: =VLOOKUP(O7,Stock[],2,FALSE) -> BE Debtors Opening | Q7: =VLOOKUP(O7,Stock[],3,FALSE) -> 0 | R7: =VLOOKUP(O7,Stock[],4,FALSE) -> 0 | V7: =+DailySales!$T7*DailySales!$R7 -> 0 | W7: =+DailySales!$V7*DailySales!$Q7 -> 0 | X7: =VLOOKUP(O7,Stock[],6,FALSE) -> 0 | Y7: =+DailySales!$V7*DailySales!$X7 -> 0 | Z7: 330150 | AN7: =Table85[[#This Row],[သင့်ငွေ]]+Table85[[#This Row],[စာရင်းဖွင့်]]-Table85[[#This Row],[ဈေးဟောင်းလျှော့]]-Table85[[#This Row],[‌ကော်မရှင်]]-Table85[[#This Row],[‌ဈေးလျှော့]]-Table85[[#This Row],[ကားခလျှော့]]+Table85[[#This Row],[ကားခ+]]-Table85[[#This Row],[ကြွေးရငွေ2]]-Table85[[#This Row],[ကြွေးရငွေ3]]-Table85[[#This Row],[ကြွေးရငွေ4]]-Table85[[#This Row],[ကြွေးရငွေ]] -> 330150
A8: =YEAR(C8) -> 2025 | B8: =MONTH(C8) -> 9 | C8: 45924 | D8: =TODAY() -> 46097 | E8: =DATEDIF(C8,D8,"M")&"-Months" -> 5-Months | F8: =VLOOKUP(O8,Stock[],5,FALSE) -> BE | G8: 10013 | I8: ZYM | J8: =VLOOKUP(I8,Customers[],2,FALSE) -> ဇင်ယော်မေ | K8: =VLOOKUP(I8,Customers[],4,FALSE) -> Bagan | L8: =VLOOKUP(Table85[[#This Row],[CustomerID]],Table!H:K,3,0) -> ညောင်ဦး | M8: =VLOOKUP(I8,Customers[],5,FALSE) -> Van-1 | N8: ကုန်ရောင်း(အကြွေး) | O8: BE Debtors | P8: =VLOOKUP(O8,Stock[],2,FALSE) -> BE Debtors Opening | Q8: =VLOOKUP(O8,Stock[],3,FALSE) -> 0 | R8: =VLOOKUP(O8,Stock[],4,FALSE) -> 0 | V8: =+DailySales!$T8*DailySales!$R8 -> 0 | W8: =+DailySales!$V8*DailySales!$Q8 -> 0 | X8: =VLOOKUP(O8,Stock[],6,FALSE) -> 0 | Y8: =+DailySales!$V8*DailySales!$X8 -> 0 | Z8: -9800 | AN8: =Table85[[#This Row],[သင့်ငွေ]]+Table85[[#This Row],[စာရင်းဖွင့်]]-Table85[[#This Row],[ဈေးဟောင်းလျှော့]]-Table85[[#This Row],[‌ကော်မရှင်]]-Table85[[#This Row],[‌ဈေးလျှော့]]-Table85[[#This Row],[ကားခလျှော့]]+Table85[[#This Row],[ကားခ+]]-Table85[[#This Row],[ကြွေးရငွေ2]]-Table85[[#This Row],[ကြွေးရငွေ3]]-Table85[[#This Row],[ကြွေးရငွေ4]]-Table85[[#This Row],[ကြွေးရငွေ]] -> -9800
A9: =YEAR(C9) -> 2025 | B9: =MONTH(C9) -> 11 | C9: 45986 | D9: =TODAY() -> 46097 | E9: =DATEDIF(C9,D9,"M")&"-Months" -> 3-Months | F9: =VLOOKUP(O9,Stock[],5,FALSE) -> BE | G9: 11877 | I9: PTH | J9: =VLOOKUP(I9,Customers[],2,FALSE) -> ဖိုးသာထူး | K9: =VLOOKUP(I9,Customers[],4,FALSE) -> Meiktila | L9: =VLOOKUP(Table85[[#This Row],[CustomerID]],Table!H:K,3,0) -> ကျွဲတပ်ဆုံ | M9: =VLOOKUP(I9,Customers[],5,FALSE) -> Van-2 | N9: ကုန်ရောင်း(အကြွေး) | O9: BE Debtors | P9: =VLOOKUP(O9,Stock[],2,FALSE) -> BE Debtors Opening | Q9: =VLOOKUP(O9,Stock[],3,FALSE) -> 0 | R9: =VLOOKUP(O9,Stock[],4,FALSE) -> 0 | V9: =+DailySales!$T9*DailySales!$R9 -> 0 | W9: =+DailySales!$V9*DailySales!$Q9 -> 0 | X9: =VLOOKUP(O9,Stock[],6,FALSE) -> 0 | Y9: =+DailySales!$V9*DailySales!$X9 -> 0 | Z9: 556000 | AH9: 46037 | AI9: 556000 | AN9: =Table85[[#This Row],[သင့်ငွေ]]+Table85[[#This Row],[စာရင်းဖွင့်]]-Table85[[#This Row],[ဈေးဟောင်းလျှော့]]-Table85[[#This Row],[‌ကော်မရှင်]]-Table85[[#This Row],[‌ဈေးလျှော့]]-Table85[[#This Row],[ကားခလျှော့]]+Table85[[#This Row],[ကားခ+]]-Table85[[#This Row],[ကြွေးရငွေ2]]-Table85[[#This Row],[ကြွေးရငွေ3]]-Table85[[#This Row],[ကြွေးရငွေ4]]-Table85[[#This Row],[ကြွေးရငွေ]] -> 0
A10: =YEAR(C10) -> 2025 | B10: =MONTH(C10) -> 11 | C10: 45990 | D10: =TODAY() -> 46097 | E10: =DATEDIF(C10,D10,"M")&"-Months" -> 3-Months | F10: =VLOOKUP(O10,Stock[],5,FALSE) -> BE | G10: 12014 | I10: USW | J10: =VLOOKUP(I10,Customers[],2,FALSE) -> ဦးစိုးဝင်း | K10: =VLOOKUP(I10,Customers[],4,FALSE) -> Kyukpadaung | L10: =VLOOKUP(Table85[[#This Row],[CustomerID]],Table!H:K,3,0) -> ကျောက်ပန်းတောင်း | M10: =VLOOKUP(I10,Customers[],5,FALSE) -> WholeSales/Contract | N10: ကုန်ရောင်း(အကြွေး) | O10: BE Debtors | P10: =VLOOKUP(O10,Stock[],2,FALSE) -> BE Debtors Opening | Q10: =VLOOKUP(O10,Stock[],3,FALSE) -> 0 | R10: =VLOOKUP(O10,Stock[],4,FALSE) -> 0 | V10: =+DailySales!$T10*DailySales!$R10 -> 0 | W10: =+DailySales!$V10*DailySales!$Q10 -> 0 | X10: =VLOOKUP(O10,Stock[],6,FALSE) -> 0 | Y10: =+DailySales!$V10*DailySales!$X10 -> 0 | Z10: 4276470 | AH10: 46025 | AI10: 4276470 | AN10: =Table85[[#This Row],[သင့်ငွေ]]+Table85[[#This Row],[စာရင်းဖွင့်]]-Table85[[#This Row],[ဈေးဟောင်းလျှော့]]-Table85[[#This Row],[‌ကော်မရှင်]]-Table85[[#This Row],[‌ဈေးလျှော့]]-Table85[[#This Row],[ကားခလျှော့]]+Table85[[#This Row],[ကားခ+]]-Table85[[#This Row],[ကြွေးရငွေ2]]-Table85[[#This Row],[ကြွေးရငွေ3]]-Table85[[#This Row],[ကြွေးရငွေ4]]-Table85[[#This Row],[ကြွေးရငွေ]] -> 0
A11: =YEAR(C11) -> 2025 | B11: =MONTH(C11) -> 11 | C11: 45990 | D11: =TODAY() -> 46097 | E11: =DATEDIF(C11,D11,"M")&"-Months" -> 3-Months | F11: =VLOOKUP(O11,Stock[],5,FALSE) -> BE | G11: 12015 | I11: USW | J11: =VLOOKUP(I11,Customers[],2,FALSE) -> ဦးစိုးဝင်း | K11: =VLOOKUP(I11,Customers[],4,FALSE) -> Kyukpadaung | L11: =VLOOKUP(Table85[[#This Row],[CustomerID]],Table!H:K,3,0) -> ကျောက်ပန်းတောင်း | M11: =VLOOKUP(I11,Customers[],5,FALSE) -> WholeSales/Contract | N11: ကုန်ရောင်း(အကြွေး) | O11: BE Debtors | P11: =VLOOKUP(O11,Stock[],2,FALSE) -> BE Debtors Opening | Q11: =VLOOKUP(O11,Stock[],3,FALSE) -> 0 | R11: =VLOOKUP(O11,Stock[],4,FALSE) -> 0 | V11: =+DailySales!$T11*DailySales!$R11 -> 0 | W11: =+DailySales!$V11*DailySales!$Q11 -> 0 | X11: =VLOOKUP(O11,Stock[],6,FALSE) -> 0 | Y11: =+DailySales!$V11*DailySales!$X11 -> 0 | Z11: 6405000 | AH11: 46025 | AI11: 1385280 | AJ11: 46027 | AK11: 4300000 | AL11: 46027 | AM11: 719720 | AN11: =Table85[[#This Row],[သင့်ငွေ]]+Table85[[#This Row],[စာရင်းဖွင့်]]-Table85[[#This Row],[ဈေးဟောင်းလျှော့]]-Table85[[#This Row],[‌ကော်မရှင်]]-Table85[[#This Row],[‌ဈေးလျှော့]]-Table85[[#This Row],[ကားခလျှော့]]+Table85[[#This Row],[ကားခ+]]-Table85[[#This Row],[ကြွေးရငွေ2]]-Table85[[#This Row],[ကြွေးရငွေ3]]-Table85[[#This Row],[ကြွေးရငွေ4]]-Table85[[#This Row],[ကြွေးရငွေ]] -> 0
A12: =YEAR(C12) -> 2025 | B12: =MONTH(C12) -> 12 | C12: 45992 | D12: =TODAY() -> 46097 | E12: =DATEDIF(C12,D12,"M")&"-Months" -> 3-Months | F12: =VLOOKUP(O12,Stock[],5,FALSE) -> BE | G12: 12036 | I12: SM(SCT) | J12: =VLOOKUP(I12,Customers[],2,FALSE) -> ရွှေမြင်း(ရွှေခြင်္သေ့) | K12: =VLOOKUP(I12,Customers[],4,FALSE) -> Meiktila | L12: =VLOOKUP(Table85[[#This Row],[CustomerID]],Table!H:K,3,0) -> မိတ္ထီလာ | M12: =VLOOKUP(I12,Customers[],5,FALSE) -> WholeSales/Contract | N12: ကုန်ရောင်း(အကြွေး) | O12: BE Debtors | P12: =VLOOKUP(O12,Stock[],2,FALSE) -> BE Debtors Opening | Q12: =VLOOKUP(O12,Stock[],3,FALSE) -> 0 | R12: =VLOOKUP(O12,Stock[],4,FALSE) -> 0 | V12: =+DailySales!$T12*DailySales!$R12 -> 0 | W12: =+DailySales!$V12*DailySales!$Q12 -> 0 | X12: =VLOOKUP(O12,Stock[],6,FALSE) -> 0 | Y12: =+DailySales!$V12*DailySales!$X12 -> 0 | Z12: 590695 | AH12: 46034 | AI12: 590695 | AN12: =Table85[[#This Row],[သင့်ငွေ]]+Table85[[#This Row],[စာရင်းဖွင့်]]-Table85[[#This Row],[ဈေးဟောင်းလျှော့]]-Table85[[#This Row],[‌ကော်မရှင်]]-Table85[[#This Row],[‌ဈေးလျှော့]]-Table85[[#This Row],[ကားခလျှော့]]+Table85[[#This Row],[ကားခ+]]-Table85[[#This Row],[ကြွေးရငွေ2]]-Table85[[#This Row],[ကြွေးရငွေ3]]-Table85[[#This Row],[ကြွေးရငွေ4]]-Table85[[#This Row],[ကြွေးရငွေ]] -> 0
A13: =YEAR(C13) -> 2025 | B13: =MONTH(C13) -> 12 | C13: 45992 | D13: =TODAY() -> 46097 | E13: =DATEDIF(C13,D13,"M")&"-Months" -> 3-Months | F13: =VLOOKUP(O13,Stock[],5,FALSE) -> BE | G13: 12036 | I13: SM(SCT) | J13: =VLOOKUP(I13,Customers[],2,FALSE) -> ရွှေမြင်း(ရွှေခြင်္သေ့) | K13: =VLOOKUP(I13,Customers[],4,FALSE) -> Meiktila | L13: =VLOOKUP(Table85[[#This Row],[CustomerID]],Table!H:K,3,0) -> မိတ္ထီလာ | M13: =VLOOKUP(I13,Customers[],5,FALSE) -> WholeSales/Contract | N13: ကုန်ရောင်း(အကြွေး) | O13: BE Debtors | P13: =VLOOKUP(O13,Stock[],2,FALSE) -> BE Debtors Opening | Q13: =VLOOKUP(O13,Stock[],3,FALSE) -> 0 | R13: =VLOOKUP(O13,Stock[],4,FALSE) -> 0 | V13: =+DailySales!$T13*DailySales!$R13 -> 0 | W13: =+DailySales!$V13*DailySales!$Q13 -> 0 | X13: =VLOOKUP(O13,Stock[],6,FALSE) -> 0 | Y13: =+DailySales!$V13*DailySales!$X13 -> 0 | Z13: 96600 | AH13: 46034 | AI13: 96600 | AN13: =Table85[[#This Row],[သင့်ငွေ]]+Table85[[#This Row],[စာရင်းဖွင့်]]-Table85[[#This Row],[ဈေးဟောင်းလျှော့]]-Table85[[#This Row],[‌ကော်မရှင်]]-Table85[[#This Row],[‌ဈေးလျှော့]]-Table85[[#This Row],[ကားခလျှော့]]+Table85[[#This Row],[ကားခ+]]-Table85[[#This Row],[ကြွေးရငွေ2]]-Table85[[#This Row],[ကြွေးရငွေ3]]-Table85[[#This Row],[ကြွေးရငွေ4]]-Table85[[#This Row],[ကြွေးရငွေ]] -> 0
A14: =YEAR(C14) -> 2025 | B14: =MONTH(C14) -> 12 | C14: 45992 | D14: =TODAY() -> 46097 | E14: =DATEDIF(C14,D14,"M")&"-Months" -> 3-Months | F14: =VLOOKUP(O14,Stock[],5,FALSE) -> BE | G14: 12036 | I14: SM(SCT) | J14: =VLOOKUP(I14,Customers[],2,FALSE) -> ရွှေမြင်း(ရွှေခြင်္သေ့) | K14: =VLOOKUP(I14,Customers[],4,FALSE) -> Meiktila | L14: =VLOOKUP(Table85[[#This Row],[CustomerID]],Table!H:K,3,0) -> မိတ္ထီလာ | M14: =VLOOKUP(I14,Customers[],5,FALSE) -> WholeSales/Contract | N14: ကုန်ရောင်း(အကြွေး) | O14: BE Debtors | P14: =VLOOKUP(O14,Stock[],2,FALSE) -> BE Debtors Opening | Q14: =VLOOKUP(O14,Stock[],3,FALSE) -> 0 | R14: =VLOOKUP(O14,Stock[],4,FALSE) -> 0 | V14: =+DailySales!$T14*DailySales!$R14 -> 0 | W14: =+DailySales!$V14*DailySales!$Q14 -> 0 | X14: =VLOOKUP(O14,Stock[],6,FALSE) -> 0 | Y14: =+DailySales!$V14*DailySales!$X14 -> 0 | Z14: 91800 | AH14: 46034 | AI14: 91800 | AN14: =Table85[[#This Row],[သင့်ငွေ]]+Table85[[#This Row],[စာရင်းဖွင့်]]-Table85[[#This Row],[ဈေးဟောင်းလျှော့]]-Table85[[#This Row],[‌ကော်မရှင်]]-Table85[[#This Row],[‌ဈေးလျှော့]]-Table85[[#This Row],[ကားခလျှော့]]+Table85[[#This Row],[ကားခ+]]-Table85[[#This Row],[ကြွေးရငွေ2]]-Table85[[#This Row],[ကြွေးရငွေ3]]-Table85[[#This Row],[ကြွေးရငွေ4]]-Table85[[#This Row],[ကြွေးရငွေ]] -> 0
A15: =YEAR(C15) -> 2025 | B15: =MONTH(C15) -> 12 | C15: 45992 | D15: =TODAY() -> 46097 | E15: =DATEDIF(C15,D15,"M")&"-Months" -> 3-Months | F15: =VLOOKUP(O15,Stock[],5,FALSE) -> BE | G15: 12036 | I15: SM(SCT) | J15: =VLOOKUP(I15,Customers[],2,FALSE) -> ရွှေမြင်း(ရွှေခြင်္သေ့) | K15: =VLOOKUP(I15,Customers[],4,FALSE) -> Meiktila | L15: =VLOOKUP(Table85[[#This Row],[CustomerID]],Table!H:K,3,0) -> မိတ္ထီလာ | M15: =VLOOKUP(I15,Customers[],5,FALSE) -> WholeSales/Contract | N15: ကုန်ရောင်း(အကြွေး) | O15: BE Debtors | P15: =VLOOKUP(O15,Stock[],2,FALSE) -> BE Debtors Opening | Q15: =VLOOKUP(O15,Stock[],3,FALSE) -> 0 | R15: =VLOOKUP(O15,Stock[],4,FALSE) -> 0 | V15: =+DailySales!$T15*DailySales!$R15 -> 0 | W15: =+DailySales!$V15*DailySales!$Q15 -> 0 | X15: =VLOOKUP(O15,Stock[],6,FALSE) -> 0 | Y15: =+DailySales!$V15*DailySales!$X15 -> 0 | Z15: 210000 | AH15: 46034 | AI15: 210000 | AN15: =Table85[[#This Row],[သင့်ငွေ]]+Table85[[#This Row],[စာရင်းဖွင့်]]-Table85[[#This Row],[ဈေးဟောင်းလျှော့]]-Table85[[#This Row],[‌ကော်မရှင်]]-Table85[[#This Row],[‌ဈေးလျှော့]]-Table85[[#This Row],[ကားခလျှော့]]+Table85[[#This Row],[ကားခ+]]-Table85[[#This Row],[ကြွေးရငွေ2]]-Table85[[#This Row],[ကြွေးရငွေ3]]-Table85[[#This Row],[ကြွေးရငွေ4]]-Table85[[#This Row],[ကြွေးရငွေ]] -> 0
A16: =YEAR(C16) -> 2025 | B16: =MONTH(C16) -> 12 | C16: 45992 | D16: =TODAY() -> 46097 | E16: =DATEDIF(C16,D16,"M")&"-Months" -> 3-Months | F16: =VLOOKUP(O16,Stock[],5,FALSE) -> BE | G16: 12041 | I16: SM | J16: =VLOOKUP(I16,Customers[],2,FALSE) -> ရွှေမြင်း | K16: =VLOOKUP(I16,Customers[],4,FALSE) -> Meiktila | L16: =VLOOKUP(Table85[[#This Row],[CustomerID]],Table!H:K,3,0) -> မိတ္ထီလာ | M16: =VLOOKUP(I16,Customers[],5,FALSE) -> WholeSales/Contract | N16: ကုန်ရောင်း(အကြွေး) | O16: BE Debtors | P16: =VLOOKUP(O16,Stock[],2,FALSE) -> BE Debtors Opening | Q16: =VLOOKUP(O16,Stock[],3,FALSE) -> 0 | R16: =VLOOKUP(O16,Stock[],4,FALSE) -> 0 | V16: =+DailySales!$T16*DailySales!$R16 -> 0 | W16: =+DailySales!$V16*DailySales!$Q16 -> 0 | X16: =VLOOKUP(O16,Stock[],6,FALSE) -> 0 | Y16: =+DailySales!$V16*DailySales!$X16 -> 0 | Z16: 575400 | AH16: 46034 | AI16: 575400 | AN16: =Table85[[#This Row],[သင့်ငွေ]]+Table85[[#This Row],[စာရင်းဖွင့်]]-Table85[[#This Row],[ဈေးဟောင်းလျှော့]]-Table85[[#This Row],[‌ကော်မရှင်]]-Table85[[#This Row],[‌ဈေးလျှော့]]-Table85[[#This Row],[ကားခလျှော့]]+Table85[[#This Row],[ကားခ+]]-Table85[[#This Row],[ကြွေးရငွေ2]]-Table85[[#This Row],[ကြွေးရငွေ3]]-Table85[[#This Row],[ကြွေးရငွေ4]]-Table85[[#This Row],[ကြွေးရငွေ]] -> 0
A17: =YEAR(C17) -> 2025 | B17: =MONTH(C17) -> 12 | C17: 45992 | D17: =TODAY() -> 46097 | E17: =DATEDIF(C17,D17,"M")&"-Months" -> 3-Months | F17: =VLOOKUP(O17,Stock[],5,FALSE) -> BE | G17: 12041 | I17: SM | J17: =VLOOKUP(I17,Customers[],2,FALSE) -> ရွှေမြင်း | K17: =VLOOKUP(I17,Customers[],4,FALSE) -> Meiktila | L17: =VLOOKUP(Table85[[#This Row],[CustomerID]],Table!H:K,3,0) -> မိတ္ထီလာ | M17: =VLOOKUP(I17,Customers[],5,FALSE) -> WholeSales/Contract | N17: ကုန်ရောင်း(အကြွေး) | O17: BE Debtors | P17: =VLOOKUP(O17,Stock[],2,FALSE) -> BE Debtors Opening | Q17: =VLOOKUP(O17,Stock[],3,FALSE) -> 0 | R17: =VLOOKUP(O17,Stock[],4,FALSE) -> 0 | V17: =+DailySales!$T17*DailySales!$R17 -> 0 | W17: =+DailySales!$V17*DailySales!$Q17 -> 0 | X17: =VLOOKUP(O17,Stock[],6,FALSE) -> 0 | Y17: =+DailySales!$V17*DailySales!$X17 -> 0 | Z17: 1915200 | AH17: 46034 | AI17: 1915200 | AN17: =Table85[[#This Row],[သင့်ငွေ]]+Table85[[#This Row],[စာရင်းဖွင့်]]-Table85[[#This Row],[ဈေးဟောင်းလျှော့]]-Table85[[#This Row],[‌ကော်မရှင်]]-Table85[[#This Row],[‌ဈေးလျှော့]]-Table85[[#This Row],[ကားခလျှော့]]+Table85[[#This Row],[ကားခ+]]-Table85[[#This Row],[ကြွေးရငွေ2]]-Table85[[#This Row],[ကြွေးရငွေ3]]-Table85[[#This Row],[ကြွေးရငွေ4]]-Table85[[#This Row],[ကြွေးရငွေ]] -> 0
A18: =YEAR(C18) -> 2025 | B18: =MONTH(C18) -> 12 | C18: 45992 | D18: =TODAY() -> 46097 | E18: =DATEDIF(C18,D18,"M")&"-Months" -> 3-Months | F18: =VLOOKUP(O18,Stock[],5,FALSE) -> BE | G18: 12041 | I18: SM | J18: =VLOOKUP(I18,Customers[],2,FALSE) -> ရွှေမြင်း | K18: =VLOOKUP(I18,Customers[],4,FALSE) -> Meiktila | L18: =VLOOKUP(Table85[[#This Row],[CustomerID]],Table!H:K,3,0) -> မိတ္ထီလာ | M18: =VLOOKUP(I18,Customers[],5,FALSE) -> WholeSales/Contract | N18: ကုန်ရောင်း(အကြွေး) | O18: BE Debtors | P18: =VLOOKUP(O18,Stock[],2,FALSE) -> BE Debtors Opening | Q18: =VLOOKUP(O18,Stock[],3,FALSE) -> 0 | R18: =VLOOKUP(O18,Stock[],4,FALSE) -> 0 | V18: =+DailySales!$T18*DailySales!$R18 -> 0 | W18: =+DailySales!$V18*DailySales!$Q18 -> 0 | X18: =VLOOKUP(O18,Stock[],6,FALSE) -> 0 | Y18: =+DailySales!$V18*DailySales!$X18 -> 0 | Z18: 744800 | AH18: 46034 | AI18: 744800 | AN18: =Table85[[#This Row],[သင့်ငွေ]]+Table85[[#This Row],[စာရင်းဖွင့်]]-Table85[[#This Row],[ဈေးဟောင်းလျှော့]]-Table85[[#This Row],[‌ကော်မရှင်]]-Table85[[#This Row],[‌ဈေးလျှော့]]-Table85[[#This Row],[ကားခလျှော့]]+Table85[[#This Row],[ကားခ+]]-Table85[[#This Row],[ကြွေးရငွေ2]]-Table85[[#This Row],[ကြွေးရငွေ3]]-Table85[[#This Row],[ကြွေးရငွေ4]]-Table85[[#This Row],[ကြွေးရငွေ]] -> 0
A19: =YEAR(C19) -> 2025 | B19: =MONTH(C19) -> 12 | C19: 45992 | D19: =TODAY() -> 46097 | E19: =DATEDIF(C19,D19,"M")&"-Months" -> 3-Months | F19: =VLOOKUP(O19,Stock[],5,FALSE) -> BE | G19: 12041 | I19: SM | J19: =VLOOKUP(I19,Customers[],2,FALSE) -> ရွှေမြင်း | K19: =VLOOKUP(I19,Customers[],4,FALSE) -> Meiktila | L19: =VLOOKUP(Table85[[#This Row],[CustomerID]],Table!H:K,3,0) -> မိတ္ထီလာ | M19: =VLOOKUP(I19,Customers[],5,FALSE) -> WholeSales/Contract | N19: ကုန်ရောင်း(အကြွေး) | O19: BE Debtors | P19: =VLOOKUP(O19,Stock[],2,FALSE) -> BE Debtors Opening | Q19: =VLOOKUP(O19,Stock[],3,FALSE) -> 0 | R19: =VLOOKUP(O19,Stock[],4,FALSE) -> 0 | V19: =+DailySales!$T19*DailySales!$R19 -> 0 | W19: =+DailySales!$V19*DailySales!$Q19 -> 0 | X19: =VLOOKUP(O19,Stock[],6,FALSE) -> 0 | Y19: =+DailySales!$V19*DailySales!$X19 -> 0 | Z19: 550800 | AH19: 46034 | AI19: 550800 | AN19: =Table85[[#This Row],[သင့်ငွေ]]+Table85[[#This Row],[စာရင်းဖွင့်]]-Table85[[#This Row],[ဈေးဟောင်းလျှော့]]-Table85[[#This Row],[‌ကော်မရှင်]]-Table85[[#This Row],[‌ဈေးလျှော့]]-Table85[[#This Row],[ကားခလျှော့]]+Table85[[#This Row],[ကားခ+]]-Table85[[#This Row],[ကြွေးရငွေ2]]-Table85[[#This Row],[ကြွေးရငွေ3]]-Table85[[#This Row],[ကြွေးရငွေ4]]-Table85[[#This Row],[ကြွေးရငွေ]] -> 0
A20: =YEAR(C20) -> 2025 | B20: =MONTH(C20) -> 12 | C20: 45992 | D20: =TODAY() -> 46097 | E20: =DATEDIF(C20,D20,"M")&"-Months" -> 3-Months | F20: =VLOOKUP(O20,Stock[],5,FALSE) -> BE | G20: 12041 | I20: SM | J20: =VLOOKUP(I20,Customers[],2,FALSE) -> ရွှေမြင်း | K20: =VLOOKUP(I20,Customers[],4,FALSE) -> Meiktila | L20: =VLOOKUP(Table85[[#This Row],[CustomerID]],Table!H:K,3,0) -> မိတ္ထီလာ | M20: =VLOOKUP(I20,Customers[],5,FALSE) -> WholeSales/Contract | N20: ကုန်ရောင်း(အကြွေး) | O20: BE Debtors | P20: =VLOOKUP(O20,Stock[],2,FALSE) -> BE Debtors Opening | Q20: =VLOOKUP(O20,Stock[],3,FALSE) -> 0 | R20: =VLOOKUP(O20,Stock[],4,FALSE) -> 0 | V20: =+DailySales!$T20*DailySales!$R20 -> 0 | W20: =+DailySales!$V20*DailySales!$Q20 -> 0 | X20: =VLOOKUP(O20,Stock[],6,FALSE) -> 0 | Y20: =+DailySales!$V20*DailySales!$X20 -> 0 | Z20: 420000 | AH20: 46034 | AI20: 420000 | AN20: =Table85[[#This Row],[သင့်ငွေ]]+Table85[[#This Row],[စာရင်းဖွင့်]]-Table85[[#This Row],[ဈေးဟောင်းလျှော့]]-Table85[[#This Row],[‌ကော်မရှင်]]-Table85[[#This Row],[‌ဈေးလျှော့]]-Table85[[#This Row],[ကားခလျှော့]]+Table85[[#This Row],[ကားခ+]]-Table85[[#This Row],[ကြွေးရငွေ2]]-Table85[[#This Row],[ကြွေးရငွေ3]]-Table85[[#This Row],[ကြွေးရငွေ4]]-Table85[[#This Row],[ကြွေးရငွေ]] -> 0
A21: =YEAR(C21) -> 2025 | B21: =MONTH(C21) -> 12 | C21: 45992 | D21: =TODAY() -> 46097 | E21: =DATEDIF(C21,D21,"M")&"-Months" -> 3-Months | F21: =VLOOKUP(O21,Stock[],5,FALSE) -> BE | G21: 12042 | I21: SM | J21: =VLOOKUP(I21,Customers[],2,FALSE) -> ရွှေမြင်း | K21: =VLOOKUP(I21,Customers[],4,FALSE) -> Meiktila | L21: =VLOOKUP(Table85[[#This Row],[CustomerID]],Table!H:K,3,0) -> မိတ္ထီလာ | M21: =VLOOKUP(I21,Customers[],5,FALSE) -> WholeSales/Contract | N21: ကုန်ရောင်း(အကြွေး) | O21: BE Debtors | P21: =VLOOKUP(O21,Stock[],2,FALSE) -> BE Debtors Opening | Q21: =VLOOKUP(O21,Stock[],3,FALSE) -> 0 | R21: =VLOOKUP(O21,Stock[],4,FALSE) -> 0 | V21: =+DailySales!$T21*DailySales!$R21 -> 0 | W21: =+DailySales!$V21*DailySales!$Q21 -> 0 | X21: =VLOOKUP(O21,Stock[],6,FALSE) -> 0 | Y21: =+DailySales!$V21*DailySales!$X21 -> 0 | Z21: 558600 | AH21: 46034 | AI21: 558600 | AN21: =Table85[[#This Row],[သင့်ငွေ]]+Table85[[#This Row],[စာရင်းဖွင့်]]-Table85[[#This Row],[ဈေးဟောင်းလျှော့]]-Table85[[#This Row],[‌ကော်မရှင်]]-Table85[[#This Row],[‌ဈေးလျှော့]]-Table85[[#This Row],[ကားခလျှော့]]+Table85[[#This Row],[ကားခ+]]-Table85[[#This Row],[ကြွေးရငွေ2]]-Table85[[#This Row],[ကြွေးရငွေ3]]-Table85[[#This Row],[ကြွေးရငွေ4]]-Table85[[#This Row],[ကြွေးရငွေ]] -> 0
A22: =YEAR(C22) -> 2025 | B22: =MONTH(C22) -> 12 | C22: 45992 | D22: =TODAY() -> 46097 | E22: =DATEDIF(C22,D22,"M")&"-Months" -> 3-Months | F22: =VLOOKUP(O22,Stock[],5,FALSE) -> BE | G22: 12042 | I22: SM | J22: =VLOOKUP(I22,Customers[],2,FALSE) -> ရွှေမြင်း | K22: =VLOOKUP(I22,Customers[],4,FALSE) -> Meiktila | L22: =VLOOKUP(Table85[[#This Row],[CustomerID]],Table!H:K,3,0) -> မိတ္ထီလာ | M22: =VLOOKUP(I22,Customers[],5,FALSE) -> WholeSales/Contract | N22: ကုန်ရောင်း(အကြွေး) | O22: BE Debtors | P22: =VLOOKUP(O22,Stock[],2,FALSE) -> BE Debtors Opening | Q22: =VLOOKUP(O22,Stock[],3,FALSE) -> 0 | R22: =VLOOKUP(O22,Stock[],4,FALSE) -> 0 | V22: =+DailySales!$T22*DailySales!$R22 -> 0 | W22: =+DailySales!$V22*DailySales!$Q22 -> 0 | X22: =VLOOKUP(O22,Stock[],6,FALSE) -> 0 | Y22: =+DailySales!$V22*DailySales!$X22 -> 0 | Z22: 575400 | AH22: 46034 | AI22: 575400 | AN22: =Table85[[#This Row],[သင့်ငွေ]]+Table85[[#This Row],[စာရင်းဖွင့်]]-Table85[[#This Row],[ဈေးဟောင်းလျှော့]]-Table85[[#This Row],[‌ကော်မရှင်]]-Table85[[#This Row],[‌ဈေးလျှော့]]-Table85[[#This Row],[ကားခလျှော့]]+Table85[[#This Row],[ကားခ+]]-Table85[[#This Row],[ကြွေးရငွေ2]]-Table85[[#This Row],[ကြွေးရငွေ3]]-Table85[[#This Row],[ကြွေးရငွေ4]]-Table85[[#This Row],[ကြွေးရငွေ]] -> 0
A23: =YEAR(C23) -> 2025 | B23: =MONTH(C23) -> 12 | C23: 45992 | D23: =TODAY() -> 46097 | E23: =DATEDIF(C23,D23,"M")&"-Months" -> 3-Months | F23: =VLOOKUP(O23,Stock[],5,FALSE) -> BE | G23: 12042 | I23: SM | J23: =VLOOKUP(I23,Customers[],2,FALSE) -> ရွှေမြင်း | K23: =VLOOKUP(I23,Customers[],4,FALSE) -> Meiktila | L23: =VLOOKUP(Table85[[#This Row],[CustomerID]],Table!H:K,3,0) -> မိတ္ထီလာ | M23: =VLOOKUP(I23,Customers[],5,FALSE) -> WholeSales/Contract | N23: ကုန်ရောင်း(အကြွေး) | O23: BE Debtors | P23: =VLOOKUP(O23,Stock[],2,FALSE) -> BE Debtors Opening | Q23: =VLOOKUP(O23,Stock[],3,FALSE) -> 0 | R23: =VLOOKUP(O23,Stock[],4,FALSE) -> 0 | V23: =+DailySales!$T23*DailySales!$R23 -> 0 | W23: =+DailySales!$V23*DailySales!$Q23 -> 0 | X23: =VLOOKUP(O23,Stock[],6,FALSE) -> 0 | Y23: =+DailySales!$V23*DailySales!$X23 -> 0 | Z23: 957600 | AH23: 46034 | AI23: 957600 | AN23: =Table85[[#This Row],[သင့်ငွေ]]+Table85[[#This Row],[စာရင်းဖွင့်]]-Table85[[#This Row],[ဈေးဟောင်းလျှော့]]-Table85[[#This Row],[‌ကော်မရှင်]]-Table85[[#This Row],[‌ဈေးလျှော့]]-Table85[[#This Row],[ကားခလျှော့]]+Table85[[#This Row],[ကားခ+]]-Table85[[#This Row],[ကြွေးရငွေ2]]-Table85[[#This Row],[ကြွေးရငွေ3]]-Table85[[#This Row],[ကြွေးရငွေ4]]-Table85[[#This Row],[ကြွေးရငွေ]] -> 0
... A124: =YEAR(C124) -> 2025 | B124: =MONTH(C124) -> 12 | C124: 45997 | D124: =TODAY() -> 46097 | E124: =DATEDIF(C124,D124,"M")&"-Months" -> 3-Months | F124: =VLOOKUP(O124,Stock[],5,FALSE) -> BE | G124: 12383 | I124: SM(KK) | J124: =VLOOKUP(I124,Customers[],2,FALSE) -> ရွှေမြင်း(ကျော်ကြား) | K124: =VLOOKUP(I124,Customers[],4,FALSE) -> Mahlaing | L124: =VLOOKUP(Table85[[#This Row],[CustomerID]],Table!H:K,3,0) -> မလှိုင် | M124: =VLOOKUP(I124,Customers[],5,FALSE) -> WholeSales/Contract | N124: ကုန်ရောင်း(အကြွေး) | O124: BE Debtors | P124: =VLOOKUP(O124,Stock[],2,FALSE) -> BE Debtors Opening | Q124: =VLOOKUP(O124,Stock[],3,FALSE) -> 0 | R124: =VLOOKUP(O124,Stock[],4,FALSE) -> 0 | V124: =+DailySales!$T124*DailySales!$R124 -> 0 | W124: =+DailySales!$V124*DailySales!$Q124 -> 0 | X124: =VLOOKUP(O124,Stock[],6,FALSE) -> 0 | Y124: =+DailySales!$V124*DailySales!$X124 -> 0 | Z124: 558600 | AH124: 46034 | AI124: 558600 | AN124: =Table85[[#This Row],[သင့်ငွေ]]+Table85[[#This Row],[စာရင်းဖွင့်]]-Table85[[#This Row],[ဈေးဟောင်းလျှော့]]-Table85[[#This Row],[‌ကော်မရှင်]]-Table85[[#This Row],[‌ဈေးလျှော့]]-Table85[[#This Row],[ကားခလျှော့]]+Table85[[#This Row],[ကားခ+]]-Table85[[#This Row],[ကြွေးရငွေ2]]-Table85[[#This Row],[ကြွေးရငွေ3]]-Table85[[#This Row],[ကြွေးရငွေ4]]-Table85[[#This Row],[ကြွေးရငွေ]] -> 0
A125: =YEAR(C125) -> 2025 | B125: =MONTH(C125) -> 12 | C125: 45999 | D125: =TODAY() -> 46097 | E125: =DATEDIF(C125,D125,"M")&"-Months" -> 3-Months | F125: =VLOOKUP(O125,Stock[],5,FALSE) -> BE | G125: 12385 | I125: USW | J125: =VLOOKUP(I125,Customers[],2,FALSE) -> ဦးစိုးဝင်း | K125: =VLOOKUP(I125,Customers[],4,FALSE) -> Kyukpadaung | L125: =VLOOKUP(Table85[[#This Row],[CustomerID]],Table!H:K,3,0) -> ကျောက်ပန်းတောင်း | M125: =VLOOKUP(I125,Customers[],5,FALSE) -> WholeSales/Contract | N125: ကုန်ရောင်း(အကြွေး) | O125: BE Debtors | P125: =VLOOKUP(O125,Stock[],2,FALSE) -> BE Debtors Opening | Q125: =VLOOKUP(O125,Stock[],3,FALSE) -> 0 | R125: =VLOOKUP(O125,Stock[],4,FALSE) -> 0 | V125: =+DailySales!$T125*DailySales!$R125 -> 0 | W125: =+DailySales!$V125*DailySales!$Q125 -> 0 | X125: =VLOOKUP(O125,Stock[],6,FALSE) -> 0 | Y125: =+DailySales!$V125*DailySales!$X125 -> 0 | Z125: 969600 | AL125: 46027 | AM125: 969600 | AN125: =Table85[[#This Row],[သင့်ငွေ]]+Table85[[#This Row],[စာရင်းဖွင့်]]-Table85[[#This Row],[ဈေးဟောင်းလျှော့]]-Table85[[#This Row],[‌ကော်မရှင်]]-Table85[[#This Row],[‌ဈေးလျှော့]]-Table85[[#This Row],[ကားခလျှော့]]+Table85[[#This Row],[ကားခ+]]-Table85[[#This Row],[ကြွေးရငွေ2]]-Table85[[#This Row],[ကြွေးရငွေ3]]-Table85[[#This Row],[ကြွေးရငွေ4]]-Table85[[#This Row],[ကြွေးရငွေ]] -> 0
A126: =YEAR(C126) -> 2025 | B126: =MONTH(C126) -> 12 | C126: 45999 | D126: =TODAY() -> 46097 | E126: =DATEDIF(C126,D126,"M")&"-Months" -> 3-Months | F126: =VLOOKUP(O126,Stock[],5,FALSE) -> BE | G126: 12385 | I126: USW | J126: =VLOOKUP(I126,Customers[],2,FALSE) -> ဦးစိုးဝင်း | K126: =VLOOKUP(I126,Customers[],4,FALSE) -> Kyukpadaung | L126: =VLOOKUP(Table85[[#This Row],[CustomerID]],Table!H:K,3,0) -> ကျောက်ပန်းတောင်း | M126: =VLOOKUP(I126,Customers[],5,FALSE) -> WholeSales/Contract | N126: ကုန်ရောင်း(အကြွေး) | O126: BE Debtors | P126: =VLOOKUP(O126,Stock[],2,FALSE) -> BE Debtors Opening | Q126: =VLOOKUP(O126,Stock[],3,FALSE) -> 0 | R126: =VLOOKUP(O126,Stock[],4,FALSE) -> 0 | V126: =+DailySales!$T126*DailySales!$R126 -> 0 | W126: =+DailySales!$V126*DailySales!$Q126 -> 0 | X126: =VLOOKUP(O126,Stock[],6,FALSE) -> 0 | Y126: =+DailySales!$V126*DailySales!$X126 -> 0 | Z126: 4917500 | AH126: 46043 | AI126: 3345070 | AL126: 46027 | AM126: 1572430 | AN126: =Table85[[#This Row],[သင့်ငွေ]]+Table85[[#This Row],[စာရင်းဖွင့်]]-Table85[[#This Row],[ဈေးဟောင်းလျှော့]]-Table85[[#This Row],[‌ကော်မရှင်]]-Table85[[#This Row],[‌ဈေးလျှော့]]-Table85[[#This Row],[ကားခလျှော့]]+Table85[[#This Row],[ကားခ+]]-Table85[[#This Row],[ကြွေးရငွေ2]]-Table85[[#This Row],[ကြွေးရငွေ3]]-Table85[[#This Row],[ကြွေးရငွေ4]]-Table85[[#This Row],[ကြွေးရငွေ]] -> 0
A127: =YEAR(C127) -> 2025 | B127: =MONTH(C127) -> 12 | C127: 45999 | D127: =TODAY() -> 46097 | E127: =DATEDIF(C127,D127,"M")&"-Months" -> 3-Months | F127: =VLOOKUP(O127,Stock[],5,FALSE) -> BE | G127: 12385 | I127: USW | J127: =VLOOKUP(I127,Customers[],2,FALSE) -> ဦးစိုးဝင်း | K127: =VLOOKUP(I127,Customers[],4,FALSE) -> Kyukpadaung | L127: =VLOOKUP(Table85[[#This Row],[CustomerID]],Table!H:K,3,0) -> ကျောက်ပန်းတောင်း | M127: =VLOOKUP(I127,Customers[],5,FALSE) -> WholeSales/Contract | N127: ကုန်ရောင်း(အကြွေး) | O127: BE Debtors | P127: =VLOOKUP(O127,Stock[],2,FALSE) -> BE Debtors Opening | Q127: =VLOOKUP(O127,Stock[],3,FALSE) -> 0 | R127: =VLOOKUP(O127,Stock[],4,FALSE) -> 0 | V127: =+DailySales!$T127*DailySales!$R127 -> 0 | W127: =+DailySales!$V127*DailySales!$Q127 -> 0 | X127: =VLOOKUP(O127,Stock[],6,FALSE) -> 0 | Y127: =+DailySales!$V127*DailySales!$X127 -> 0 | Z127: 9355000 | AH127: 46043 | AI127: 9355000 | AN127: =Table85[[#This Row],[သင့်ငွေ]]+Table85[[#This Row],[စာရင်းဖွင့်]]-Table85[[#This Row],[ဈေးဟောင်းလျှော့]]-Table85[[#This Row],[‌ကော်မရှင်]]-Table85[[#This Row],[‌ဈေးလျှော့]]-Table85[[#This Row],[ကားခလျှော့]]+Table85[[#This Row],[ကားခ+]]-Table85[[#This Row],[ကြွေးရငွေ2]]-Table85[[#This Row],[ကြွေးရငွေ3]]-Table85[[#This Row],[ကြွေးရငွေ4]]-Table85[[#This Row],[ကြွေးရငွေ]] -> 0
A128: =YEAR(C128) -> 2025 | B128: =MONTH(C128) -> 12 | C128: 45999 | D128: =TODAY() -> 46097 | E128: =DATEDIF(C128,D128,"M")&"-Months" -> 3-Months | F128: =VLOOKUP(O128,Stock[],5,FALSE) -> BE | G128: 12387 | I128: SM(SCT) | J128: =VLOOKUP(I128,Customers[],2,FALSE) -> ရွှေမြင်း(ရွှေခြင်္သေ့) | K128: =VLOOKUP(I128,Customers[],4,FALSE) -> Meiktila | L128: =VLOOKUP(Table85[[#This Row],[CustomerID]],Table!H:K,3,0) -> မိတ္ထီလာ | M128: =VLOOKUP(I128,Customers[],5,FALSE) -> WholeSales/Contract | N128: ကုန်ရောင်း(အကြွေး) | O128: BE Debtors | P128: =VLOOKUP(O128,Stock[],2,FALSE) -> BE Debtors Opening | Q128: =VLOOKUP(O128,Stock[],3,FALSE) -> 0 | R128: =VLOOKUP(O128,Stock[],4,FALSE) -> 0 | V128: =+DailySales!$T128*DailySales!$R128 -> 0 | W128: =+DailySales!$V128*DailySales!$Q128 -> 0 | X128: =VLOOKUP(O128,Stock[],6,FALSE) -> 0 | Y128: =+DailySales!$V128*DailySales!$X128 -> 0 | Z128: 479500 | AH128: 46034 | AI128: 479500 | AN128: =Table85[[#This Row],[သင့်ငွေ]]+Table85[[#This Row],[စာရင်းဖွင့်]]-Table85[[#This Row],[ဈေးဟောင်းလျှော့]]-Table85[[#This Row],[‌ကော်မရှင်]]-Table85[[#This Row],[‌ဈေးလျှော့]]-Table85[[#This Row],[ကားခလျှော့]]+Table85[[#This Row],[ကားခ+]]-Table85[[#This Row],[ကြွေးရငွေ2]]-Table85[[#This Row],[ကြွေးရငွေ3]]-Table85[[#This Row],[ကြွေးရငွေ4]]-Table85[[#This Row],[ကြွေးရငွေ]] -> 0
A129: =YEAR(C129) -> 2025 | B129: =MONTH(C129) -> 12 | C129: 45999 | D129: =TODAY() -> 46097 | E129: =DATEDIF(C129,D129,"M")&"-Months" -> 3-Months | F129: =VLOOKUP(O129,Stock[],5,FALSE) -> BE | G129: 12387 | I129: SM(SCT) | J129: =VLOOKUP(I129,Customers[],2,FALSE) -> ရွှေမြင်း(ရွှေခြင်္သေ့) | K129: =VLOOKUP(I129,Customers[],4,FALSE) -> Meiktila | L129: =VLOOKUP(Table85[[#This Row],[CustomerID]],Table!H:K,3,0) -> မိတ္ထီလာ | M129: =VLOOKUP(I129,Customers[],5,FALSE) -> WholeSales/Contract | N129: ကုန်ရောင်း(အကြွေး) | O129: BE Debtors | P129: =VLOOKUP(O129,Stock[],2,FALSE) -> BE Debtors Opening | Q129: =VLOOKUP(O129,Stock[],3,FALSE) -> 0 | R129: =VLOOKUP(O129,Stock[],4,FALSE) -> 0 | V129: =+DailySales!$T129*DailySales!$R129 -> 0 | W129: =+DailySales!$V129*DailySales!$Q129 -> 0 | X129: =VLOOKUP(O129,Stock[],6,FALSE) -> 0 | Y129: =+DailySales!$V129*DailySales!$X129 -> 0 | Z129: 638400 | AH129: 46034 | AI129: 638400 | AN129: =Table85[[#This Row],[သင့်ငွေ]]+Table85[[#This Row],[စာရင်းဖွင့်]]-Table85[[#This Row],[ဈေးဟောင်းလျှော့]]-Table85[[#This Row],[‌ကော်မရှင်]]-Table85[[#This Row],[‌ဈေးလျှော့]]-Table85[[#This Row],[ကားခလျှော့]]+Table85[[#This Row],[ကားခ+]]-Table85[[#This Row],[ကြွေးရငွေ2]]-Table85[[#This Row],[ကြွေးရငွေ3]]-Table85[[#This Row],[ကြွေးရငွေ4]]-Table85[[#This Row],[ကြွေးရငွေ]] -> 0
A130: =YEAR(C130) -> 2025 | B130: =MONTH(C130) -> 12 | C130: 45999 | D130: =TODAY() -> 46097 | E130: =DATEDIF(C130,D130,"M")&"-Months" -> 3-Months | F130: =VLOOKUP(O130,Stock[],5,FALSE) -> BE | G130: 12387 | I130: SM(SCT) | J130: =VLOOKUP(I130,Customers[],2,FALSE) -> ရွှေမြင်း(ရွှေခြင်္သေ့) | K130: =VLOOKUP(I130,Customers[],4,FALSE) -> Meiktila | L130: =VLOOKUP(Table85[[#This Row],[CustomerID]],Table!H:K,3,0) -> မိတ္ထီလာ | M130: =VLOOKUP(I130,Customers[],5,FALSE) -> WholeSales/Contract | N130: ကုန်ရောင်း(အကြွေး) | O130: BE Debtors | P130: =VLOOKUP(O130,Stock[],2,FALSE) -> BE Debtors Opening | Q130: =VLOOKUP(O130,Stock[],3,FALSE) -> 0 | R130: =VLOOKUP(O130,Stock[],4,FALSE) -> 0 | V130: =+DailySales!$T130*DailySales!$R130 -> 0 | W130: =+DailySales!$V130*DailySales!$Q130 -> 0 | X130: =VLOOKUP(O130,Stock[],6,FALSE) -> 0 | Y130: =+DailySales!$V130*DailySales!$X130 -> 0 | Z130: 386400 | AH130: 46034 | AI130: 386400 | AN130: =Table85[[#This Row],[သင့်ငွေ]]+Table85[[#This Row],[စာရင်းဖွင့်]]-Table85[[#This Row],[ဈေးဟောင်းလျှော့]]-Table85[[#This Row],[‌ကော်မရှင်]]-Table85[[#This Row],[‌ဈေးလျှော့]]-Table85[[#This Row],[ကားခလျှော့]]+Table85[[#This Row],[ကားခ+]]-Table85[[#This Row],[ကြွေးရငွေ2]]-Table85[[#This Row],[ကြွေးရငွေ3]]-Table85[[#This Row],[ကြွေးရငွေ4]]-Table85[[#This Row],[ကြွေးရငွေ]] -> 0
A131: =YEAR(C131) -> 2025 | B131: =MONTH(C131) -> 12 | C131: 45999 | D131: =TODAY() -> 46097 | E131: =DATEDIF(C131,D131,"M")&"-Months" -> 3-Months | F131: =VLOOKUP(O131,Stock[],5,FALSE) -> BE | G131: 12387 | I131: SM(SCT) | J131: =VLOOKUP(I131,Customers[],2,FALSE) -> ရွှေမြင်း(ရွှေခြင်္သေ့) | K131: =VLOOKUP(I131,Customers[],4,FALSE) -> Meiktila | L131: =VLOOKUP(Table85[[#This Row],[CustomerID]],Table!H:K,3,0) -> မိတ္ထီလာ | M131: =VLOOKUP(I131,Customers[],5,FALSE) -> WholeSales/Contract | N131: ကုန်ရောင်း(အကြွေး) | O131: BE Debtors | P131: =VLOOKUP(O131,Stock[],2,FALSE) -> BE Debtors Opening | Q131: =VLOOKUP(O131,Stock[],3,FALSE) -> 0 | R131: =VLOOKUP(O131,Stock[],4,FALSE) -> 0 | V131: =+DailySales!$T131*DailySales!$R131 -> 0 | W131: =+DailySales!$V131*DailySales!$Q131 -> 0 | X131: =VLOOKUP(O131,Stock[],6,FALSE) -> 0 | Y131: =+DailySales!$V131*DailySales!$X131 -> 0 | Z131: 93100 | AH131: 46034 | AI131: 93100 | AN131: =Table85[[#This Row],[သင့်ငွေ]]+Table85[[#This Row],[စာရင်းဖွင့်]]-Table85[[#This Row],[ဈေးဟောင်းလျှော့]]-Table85[[#This Row],[‌ကော်မရှင်]]-Table85[[#This Row],[‌ဈေးလျှော့]]-Table85[[#This Row],[ကားခလျှော့]]+Table85[[#This Row],[ကားခ+]]-Table85[[#This Row],[ကြွေးရငွေ2]]-Table85[[#This Row],[ကြွေးရငွေ3]]-Table85[[#This Row],[ကြွေးရငွေ4]]-Table85[[#This Row],[ကြွေးရငွေ]] -> 0
A132: =YEAR(C132) -> 2025 | B132: =MONTH(C132) -> 12 | C132: 45999 | D132: =TODAY() -> 46097 | E132: =DATEDIF(C132,D132,"M")&"-Months" -> 3-Months | F132: =VLOOKUP(O132,Stock[],5,FALSE) -> BE | G132: 12387 | I132: SM(SCT) | J132: =VLOOKUP(I132,Customers[],2,FALSE) -> ရွှေမြင်း(ရွှေခြင်္သေ့) | K132: =VLOOKUP(I132,Customers[],4,FALSE) -> Meiktila | L132: =VLOOKUP(Table85[[#This Row],[CustomerID]],Table!H:K,3,0) -> မိတ္ထီလာ | M132: =VLOOKUP(I132,Customers[],5,FALSE) -> WholeSales/Contract | N132: ကုန်ရောင်း(အကြွေး) | O132: BE Debtors | P132: =VLOOKUP(O132,Stock[],2,FALSE) -> BE Debtors Opening | Q132: =VLOOKUP(O132,Stock[],3,FALSE) -> 0 | R132: =VLOOKUP(O132,Stock[],4,FALSE) -> 0 | V132: =+DailySales!$T132*DailySales!$R132 -> 0 | W132: =+DailySales!$V132*DailySales!$Q132 -> 0 | X132: =VLOOKUP(O132,Stock[],6,FALSE) -> 0 | Y132: =+DailySales!$V132*DailySales!$X132 -> 0 | Z132: 105000 | AH132: 46034 | AI132: 105000 | AN132: =Table85[[#This Row],[သင့်ငွေ]]+Table85[[#This Row],[စာရင်းဖွင့်]]-Table85[[#This Row],[ဈေးဟောင်းလျှော့]]-Table85[[#This Row],[‌ကော်မရှင်]]-Table85[[#This Row],[‌ဈေးလျှော့]]-Table85[[#This Row],[ကားခလျှော့]]+Table85[[#This Row],[ကားခ+]]-Table85[[#This Row],[ကြွေးရငွေ2]]-Table85[[#This Row],[ကြွေးရငွေ3]]-Table85[[#This Row],[ကြွေးရငွေ4]]-Table85[[#This Row],[ကြွေးရငွေ]] -> 0
A133: =YEAR(C133) -> 2025 | B133: =MONTH(C133) -> 12 | C133: 45999 | D133: =TODAY() -> 46097 | E133: =DATEDIF(C133,D133,"M")&"-Months" -> 3-Months | F133: =VLOOKUP(O133,Stock[],5,FALSE) -> BE | G133: 12387 | I133: SM(SCT) | J133: =VLOOKUP(I133,Customers[],2,FALSE) -> ရွှေမြင်း(ရွှေခြင်္သေ့) | K133: =VLOOKUP(I133,Customers[],4,FALSE) -> Meiktila | L133: =VLOOKUP(Table85[[#This Row],[CustomerID]],Table!H:K,3,0) -> မိတ္ထီလာ | M133: =VLOOKUP(I133,Customers[],5,FALSE) -> WholeSales/Contract | N133: ကုန်ရောင်း(အကြွေး) | O133: BE Debtors | P133: =VLOOKUP(O133,Stock[],2,FALSE) -> BE Debtors Opening | Q133: =VLOOKUP(O133,Stock[],3,FALSE) -> 0 | R133: =VLOOKUP(O133,Stock[],4,FALSE) -> 0 | V133: =+DailySales!$T133*DailySales!$R133 -> 0 | W133: =+DailySales!$V133*DailySales!$Q133 -> 0 | X133: =VLOOKUP(O133,Stock[],6,FALSE) -> 0 | Y133: =+DailySales!$V133*DailySales!$X133 -> 0 | Z133: 91800 | AH133: 46034 | AI133: 91800 | AN133: =Table85[[#This Row],[သင့်ငွေ]]+Table85[[#This Row],[စာရင်းဖွင့်]]-Table85[[#This Row],[ဈေးဟောင်းလျှော့]]-Table85[[#This Row],[‌ကော်မရှင်]]-Table85[[#This Row],[‌ဈေးလျှော့]]-Table85[[#This Row],[ကားခလျှော့]]+Table85[[#This Row],[ကားခ+]]-Table85[[#This Row],[ကြွေးရငွေ2]]-Table85[[#This Row],[ကြွေးရငွေ3]]-Table85[[#This Row],[ကြွေးရငွေ4]]-Table85[[#This Row],[ကြွေးရငွေ]] -> 0
A134: =YEAR(C134) -> 2025 | B134: =MONTH(C134) -> 12 | C134: 45999 | D134: =TODAY() -> 46097 | E134: =DATEDIF(C134,D134,"M")&"-Months" -> 3-Months | F134: =VLOOKUP(O134,Stock[],5,FALSE) -> BE | G134: 12389 | I134: SM(KMH) | J134: =VLOOKUP(I134,Customers[],2,FALSE) -> ရွှေမြင်း(မခင်မာဌေး) | K134: =VLOOKUP(I134,Customers[],4,FALSE) -> Meiktila | L134: =VLOOKUP(Table85[[#This Row],[CustomerID]],Table!H:K,3,0) -> ကျွဲတပ်ဆုံ | M134: =VLOOKUP(I134,Customers[],5,FALSE) -> WholeSales/Contract | N134: ကုန်ရောင်း(အကြွေး) | O134: BE Debtors | P134: =VLOOKUP(O134,Stock[],2,FALSE) -> BE Debtors Opening | Q134: =VLOOKUP(O134,Stock[],3,FALSE) -> 0 | R134: =VLOOKUP(O134,Stock[],4,FALSE) -> 0 | V134: =+DailySales!$T134*DailySales!$R134 -> 0 | W134: =+DailySales!$V134*DailySales!$Q134 -> 0 | X134: =VLOOKUP(O134,Stock[],6,FALSE) -> 0 | Y134: =+DailySales!$V134*DailySales!$X134 -> 0 | Z134: 2160000 | AH134: 46034 | AI134: 2160000 | AN134: =Table85[[#This Row],[သင့်ငွေ]]+Table85[[#This Row],[စာရင်းဖွင့်]]-Table85[[#This Row],[ဈေးဟောင်းလျှော့]]-Table85[[#This Row],[‌ကော်မရှင်]]-Table85[[#This Row],[‌ဈေးလျှော့]]-Table85[[#This Row],[ကားခလျှော့]]+Table85[[#This Row],[ကားခ+]]-Table85[[#This Row],[ကြွေးရငွေ2]]-Table85[[#This Row],[ကြွေးရငွေ3]]-Table85[[#This Row],[ကြွေးရငွေ4]]-Table85[[#This Row],[ကြွေးရငွေ]] -> 0
A135: =YEAR(C135) -> 2025 | B135: =MONTH(C135) -> 12 | C135: 45999 | D135: =TODAY() -> 46097 | E135: =DATEDIF(C135,D135,"M")&"-Months" -> 3-Months | F135: =VLOOKUP(O135,Stock[],5,FALSE) -> BE | G135: 12389 | I135: SM(KMH) | J135: =VLOOKUP(I135,Customers[],2,FALSE) -> ရွှေမြင်း(မခင်မာဌေး) | K135: =VLOOKUP(I135,Customers[],4,FALSE) -> Meiktila | L135: =VLOOKUP(Table85[[#This Row],[CustomerID]],Table!H:K,3,0) -> ကျွဲတပ်ဆုံ | M135: =VLOOKUP(I135,Customers[],5,FALSE) -> WholeSales/Contract | N135: ကုန်ရောင်း(အကြွေး) | O135: BE Debtors | P135: =VLOOKUP(O135,Stock[],2,FALSE) -> BE Debtors Opening | Q135: =VLOOKUP(O135,Stock[],3,FALSE) -> 0 | R135: =VLOOKUP(O135,Stock[],4,FALSE) -> 0 | V135: =+DailySales!$T135*DailySales!$R135 -> 0 | W135: =+DailySales!$V135*DailySales!$Q135 -> 0 | X135: =VLOOKUP(O135,Stock[],6,FALSE) -> 0 | Y135: =+DailySales!$V135*DailySales!$X135 -> 0 | Z135: 1596000 | AH135: 46034 | AI135: 1596000 | AN135: =Table85[[#This Row],[သင့်ငွေ]]+Table85[[#This Row],[စာရင်းဖွင့်]]-Table85[[#This Row],[ဈေးဟောင်းလျှော့]]-Table85[[#This Row],[‌ကော်မရှင်]]-Table85[[#This Row],[‌ဈေးလျှော့]]-Table85[[#This Row],[ကားခလျှော့]]+Table85[[#This Row],[ကားခ+]]-Table85[[#This Row],[ကြွေးရငွေ2]]-Table85[[#This Row],[ကြွေးရငွေ3]]-Table85[[#This Row],[ကြွေးရငွေ4]]-Table85[[#This Row],[ကြွေးရငွေ]] -> 0
A136: =YEAR(C136) -> 2025 | B136: =MONTH(C136) -> 12 | C136: 45999 | D136: =TODAY() -> 46097 | E136: =DATEDIF(C136,D136,"M")&"-Months" -> 3-Months | F136: =VLOOKUP(O136,Stock[],5,FALSE) -> BE | G136: 12398 | I136: SM(SCT) | J136: =VLOOKUP(I136,Customers[],2,FALSE) -> ရွှေမြင်း(ရွှေခြင်္သေ့) | K136: =VLOOKUP(I136,Customers[],4,FALSE) -> Meiktila | L136: =VLOOKUP(Table85[[#This Row],[CustomerID]],Table!H:K,3,0) -> မိတ္ထီလာ | M136: =VLOOKUP(I136,Customers[],5,FALSE) -> WholeSales/Contract | N136: ကုန်ရောင်း(အကြွေး) | O136: BE Debtors | P136: =VLOOKUP(O136,Stock[],2,FALSE) -> BE Debtors Opening | Q136: =VLOOKUP(O136,Stock[],3,FALSE) -> 0 | R136: =VLOOKUP(O136,Stock[],4,FALSE) -> 0 | V136: =+DailySales!$T136*DailySales!$R136 -> 0 | W136: =+DailySales!$V136*DailySales!$Q136 -> 0 | X136: =VLOOKUP(O136,Stock[],6,FALSE) -> 0 | Y136: =+DailySales!$V136*DailySales!$X136 -> 0 | Z136: 93100 | AH136: 46034 | AI136: 93100 | AN136: =Table85[[#This Row],[သင့်ငွေ]]+Table85[[#This Row],[စာရင်းဖွင့်]]-Table85[[#This Row],[ဈေးဟောင်းလျှော့]]-Table85[[#This Row],[‌ကော်မရှင်]]-Table85[[#This Row],[‌ဈေးလျှော့]]-Table85[[#This Row],[ကားခလျှော့]]+Table85[[#This Row],[ကားခ+]]-Table85[[#This Row],[ကြွေးရငွေ2]]-Table85[[#This Row],[ကြွေးရငွေ3]]-Table85[[#This Row],[ကြွေးရငွေ4]]-Table85[[#This Row],[ကြွေးရငွေ]] -> 0
A137: =YEAR(C137) -> 2025 | B137: =MONTH(C137) -> 12 | C137: 45999 | D137: =TODAY() -> 46097 | E137: =DATEDIF(C137,D137,"M")&"-Months" -> 3-Months | F137: =VLOOKUP(O137,Stock[],5,FALSE) -> BE | G137: 12398 | I137: SM(SCT) | J137: =VLOOKUP(I137,Customers[],2,FALSE) -> ရွှေမြင်း(ရွှေခြင်္သေ့) | K137: =VLOOKUP(I137,Customers[],4,FALSE) -> Meiktila | L137: =VLOOKUP(Table85[[#This Row],[CustomerID]],Table!H:K,3,0) -> မိတ္ထီလာ | M137: =VLOOKUP(I137,Customers[],5,FALSE) -> WholeSales/Contract | N137: ကုန်ရောင်း(အကြွေး) | O137: BE Debtors | P137: =VLOOKUP(O137,Stock[],2,FALSE) -> BE Debtors Opening | Q137: =VLOOKUP(O137,Stock[],3,FALSE) -> 0 | R137: =VLOOKUP(O137,Stock[],4,FALSE) -> 0 | V137: =+DailySales!$T137*DailySales!$R137 -> 0 | W137: =+DailySales!$V137*DailySales!$Q137 -> 0 | X137: =VLOOKUP(O137,Stock[],6,FALSE) -> 0 | Y137: =+DailySales!$V137*DailySales!$X137 -> 0 | Z137: 287700 | AH137: 46034 | AI137: 287700 | AN137: =Table85[[#This Row],[သင့်ငွေ]]+Table85[[#This Row],[စာရင်းဖွင့်]]-Table85[[#This Row],[ဈေးဟောင်းလျှော့]]-Table85[[#This Row],[‌ကော်မရှင်]]-Table85[[#This Row],[‌ဈေးလျှော့]]-Table85[[#This Row],[ကားခလျှော့]]+Table85[[#This Row],[ကားခ+]]-Table85[[#This Row],[ကြွေးရငွေ2]]-Table85[[#This Row],[ကြွေးရငွေ3]]-Table85[[#This Row],[ကြွေးရငွေ4]]-Table85[[#This Row],[ကြွေးရငွေ]] -> 0
A138: =YEAR(C138) -> 2025 | B138: =MONTH(C138) -> 12 | C138: 45999 | D138: =TODAY() -> 46097 | E138: =DATEDIF(C138,D138,"M")&"-Months" -> 3-Months | F138: =VLOOKUP(O138,Stock[],5,FALSE) -> BE | G138: 12398 | I138: SM(SCT) | J138: =VLOOKUP(I138,Customers[],2,FALSE) -> ရွှေမြင်း(ရွှေခြင်္သေ့) | K138: =VLOOKUP(I138,Customers[],4,FALSE) -> Meiktila | L138: =VLOOKUP(Table85[[#This Row],[CustomerID]],Table!H:K,3,0) -> မိတ္ထီလာ | M138: =VLOOKUP(I138,Customers[],5,FALSE) -> WholeSales/Contract | N138: ကုန်ရောင်း(အကြွေး) | O138: BE Debtors | P138: =VLOOKUP(O138,Stock[],2,FALSE) -> BE Debtors Opening | Q138: =VLOOKUP(O138,Stock[],3,FALSE) -> 0 | R138: =VLOOKUP(O138,Stock[],4,FALSE) -> 0 | V138: =+DailySales!$T138*DailySales!$R138 -> 0 | W138: =+DailySales!$V138*DailySales!$Q138 -> 0 | X138: =VLOOKUP(O138,Stock[],6,FALSE) -> 0 | Y138: =+DailySales!$V138*DailySales!$X138 -> 0 | Z138: 957600 | AH138: 46034 | AI138: 957600 | AN138: =Table85[[#This Row],[သင့်ငွေ]]+Table85[[#This Row],[စာရင်းဖွင့်]]-Table85[[#This Row],[ဈေးဟောင်းလျှော့]]-Table85[[#This Row],[‌ကော်မရှင်]]-Table85[[#This Row],[‌ဈေးလျှော့]]-Table85[[#This Row],[ကားခလျှော့]]+Table85[[#This Row],[ကားခ+]]-Table85[[#This Row],[ကြွေးရငွေ2]]-Table85[[#This Row],[ကြွေးရငွေ3]]-Table85[[#This Row],[ကြွေးရငွေ4]]-Table85[[#This Row],[ကြွေးရငွေ]] -> 0
... A256: =YEAR(C256) -> 2025 | B256: =MONTH(C256) -> 12 | C256: 46003 | D256: =TODAY() -> 46097 | E256: =DATEDIF(C256,D256,"M")&"-Months" -> 3-Months | F256: =VLOOKUP(O256,Stock[],5,FALSE) -> BE | G256: 12563 | I256: UWN | J256: =VLOOKUP(I256,Customers[],2,FALSE) -> ဦးဝင်းနိုင် | K256: =VLOOKUP(I256,Customers[],4,FALSE) -> Wandwin | L256: =VLOOKUP(Table85[[#This Row],[CustomerID]],Table!H:K,3,0) -> လျှော်ပင် | M256: =VLOOKUP(I256,Customers[],5,FALSE) -> WholeSales/Contract | N256: ကုန်ရောင်း(အကြွေး) | O256: BE Debtors | P256: =VLOOKUP(O256,Stock[],2,FALSE) -> BE Debtors Opening | Q256: =VLOOKUP(O256,Stock[],3,FALSE) -> 0 | R256: =VLOOKUP(O256,Stock[],4,FALSE) -> 0 | V256: =+DailySales!$T256*DailySales!$R256 -> 0 | W256: =+DailySales!$V256*DailySales!$Q256 -> 0 | X256: =VLOOKUP(O256,Stock[],6,FALSE) -> 0 | Y256: =+DailySales!$V256*DailySales!$X256 -> 0 | Z256: 1342600 | AH256: 46025 | AI256: 1342600 | AN256: =Table85[[#This Row],[သင့်ငွေ]]+Table85[[#This Row],[စာရင်းဖွင့်]]-Table85[[#This Row],[ဈေးဟောင်းလျှော့]]-Table85[[#This Row],[‌ကော်မရှင်]]-Table85[[#This Row],[‌ဈေးလျှော့]]-Table85[[#This Row],[ကားခလျှော့]]+Table85[[#This Row],[ကားခ+]]-Table85[[#This Row],[ကြွေးရငွေ2]]-Table85[[#This Row],[ကြွေးရငွေ3]]-Table85[[#This Row],[ကြွေးရငွေ4]]-Table85[[#This Row],[ကြွေးရငွေ]] -> 0
A257: =YEAR(C257) -> 2025 | B257: =MONTH(C257) -> 12 | C257: 46003 | D257: =TODAY() -> 46097 | E257: =DATEDIF(C257,D257,"M")&"-Months" -> 3-Months | F257: =VLOOKUP(O257,Stock[],5,FALSE) -> BE | G257: 12563 | I257: UWN | J257: =VLOOKUP(I257,Customers[],2,FALSE) -> ဦးဝင်းနိုင် | K257: =VLOOKUP(I257,Customers[],4,FALSE) -> Wandwin | L257: =VLOOKUP(Table85[[#This Row],[CustomerID]],Table!H:K,3,0) -> လျှော်ပင် | M257: =VLOOKUP(I257,Customers[],5,FALSE) -> WholeSales/Contract | N257: ကုန်ရောင်း(အကြွေး) | O257: BE Debtors | P257: =VLOOKUP(O257,Stock[],2,FALSE) -> BE Debtors Opening | Q257: =VLOOKUP(O257,Stock[],3,FALSE) -> 0 | R257: =VLOOKUP(O257,Stock[],4,FALSE) -> 0 | V257: =+DailySales!$T257*DailySales!$R257 -> 0 | W257: =+DailySales!$V257*DailySales!$Q257 -> 0 | X257: =VLOOKUP(O257,Stock[],6,FALSE) -> 0 | Y257: =+DailySales!$V257*DailySales!$X257 -> 0 | Z257: 478800 | AH257: 46025 | AI257: 159285 | AJ257: 46027 | AK257: 319515 | AN257: =Table85[[#This Row],[သင့်ငွေ]]+Table85[[#This Row],[စာရင်းဖွင့်]]-Table85[[#This Row],[ဈေးဟောင်းလျှော့]]-Table85[[#This Row],[‌ကော်မရှင်]]-Table85[[#This Row],[‌ဈေးလျှော့]]-Table85[[#This Row],[ကားခလျှော့]]+Table85[[#This Row],[ကားခ+]]-Table85[[#This Row],[ကြွေးရငွေ2]]-Table85[[#This Row],[ကြွေးရငွေ3]]-Table85[[#This Row],[ကြွေးရငွေ4]]-Table85[[#This Row],[ကြွေးရငွေ]] -> 0
...

Sheet Sheet1
A2: MHL-2026 March | B2: Bot | E2: Liter
B3: Target | C3: Sale | D3: Ach% | E3: Target | F3: Sale | G3: Ach%
A4: 1 to 14 WS+SWS+Van | B4: 1003247 | C4: 366870 | D4: =C4/B4 -> 0.36568263 | E4: 664538 | F4: 245015.28 | G4: =F4/E4 -> 0.36870018
