Workbook
Name aa: #REF!
Name aa: #REF!
Name aa: #REF!
Name aa: #REF!
Name aa: #REF!
Name aa: #REF!
Name aaa: #REF!
Name aaa: #REF!
Name aaa: #REF!
Name aaaaaaa: #REF!
Name asd: '[1]Market ( Mar) '!#REF!
Name asd: '[1]Market ( Mar) '!#REF!
Name asd: '[1]Market ( Mar) '!#REF!
Name atr: #REF!
Name atr: #REF!
Name atr: #REF!
Name b: #REF!
Name b: #REF!
Name b: #REF!
Name bb: #REF!
Name bb: #REF!
Name bb: #REF!
Name Beg_Bal: #REF!
Name Beg_Bal: #REF!
Name Beg_Bal: #REF!
Name Cash_Cr: #REF!
Name Cash_Cr: #REF!
Name Cash_Cr: #REF!
Name Cash_Dr: #REF!
Name Cash_Dr: #REF!
Name Cash_Dr: #REF!
Name cc: #REF!
Name cc: #REF!
Name cc: #REF!
Name ccc: #REF!
Name ccc: #REF!
Name ccc: #REF!
Name cr: #REF!
Name cr: #REF!
Name cr: #REF!
Name crs: #REF!
Name crs: #REF!
Name crs: #REF!
Name Data: #REF!
Name Data: #REF!
Name Data: #REF!
Name dd: #REF!
Name dd: #REF!
Name dd: #REF!
Name ddd: #REF!
Name ddd: #REF!
Name ddd: #REF!
Name dr: #REF!
Name dr: #REF!
Name dr: #REF!
Name drs: #REF!
Name drs: #REF!
Name drs: #REF!
Name End_Bal: #REF!
Name End_Bal: #REF!

Sheet Table
A1: Stock ID | B1: Particular | C1: ml | D1: Qty | E1: Column1 | F1: Sales Price | I1: No | J1: ကုန်သည် | K1: လိပ်စာ | L1: Township | M1: Sales | O1: Particular | Q1: Car No
A2: Zay Vodka-12 | B2: ဇေ Vodka | C2: 0.7 | D2: 12 | E2: BE | F2: 1870 | I2: Kyaw Star | J2: ကျော်စတား | K2: ရေး | L2: Yay | M2: WholeSales | O2: ကုန်ရောင်း(လက်ငင်း) | Q2: 7F-9918
A3: Zay Vodka-12-(8.2.2025) | B3: ဇေ Vodka | C3: 0.7 | D3: 12 | E3: BE | F3: 2020 | I3: Daw New New Yee | J3: ဒေါ်နွယ်နွယ်ရီ(ရွှေတောင်ကြား) | K3: ရေး | L3: Yay | M3: WholeSales | O3: ကုန်ရောင်း(အကြွေး) | Q3: 6Q-5159
A4: Zay Vodka-14 | B4: ဇေ Vodka | C4: 0.64 | D4: 14 | E4: BE | F4: 1250 | I4: Pyae Hlan | J4: ပြည့်လျှံ | K4: ဈေးကြို | L4: Maw La Myaing | M4: WholeSales | O4: ကုန်ရောင်းပြန်သွင်း | Q4: 6Q-5326 | S4: Van-1
A5: Zay Vodka-1(8.3.2025) | B5: ဇေ Vodka | C5: 0.64 | D5: 14 | E5: BE | F5: 1400 | I5: Ko Myo Aung | J5: ကိုမျိုးအောင် | K5: ဈေးကြို | L5: Maw La Myaing | M5: WholeSales | O5: ဈေးဟောင်းလျှော့ | Q5: 3R-4271
A6: Zay -14-001 | B6: ဇေ အရက်သန့် | C6: 0.64 | D6: 14 | E6: BE | F6: 1150 | I6: Ko Htike Soe | J6: ကိုထိုက်စိုး | K6: အစင် | L6: Yay | M6: WholeSales | O6: ကော်မရှင်
A7: Zay -14 | B7: ဇေ အရက်သန့် | C7: 0.64 | D7: 14 | E7: BE | F7: 1250 | I7: U Min Lwin | J7: ဦးမင်းလွင် | K7: ဈေးကြီး | L7: Maw La Myaing | M7: WholeSales | O7: အရက်ဖာကော်မရှင်
A8: Zay .35li-12 | B8: "ဇေ" ကော်ဘူး (0.35Liter) | C8: 0.35 | D8: 40 | E8: BE | F8: 750 | I8: Ko Htun Naing | J8: ကိုထွန်းနိုင် | K8: ရေး(ကျောင်းရွာ) | L8: Yay | M8: WholeSales | O8: အကွဲ
A9: Zay .35li-12(8.3.2025) | B9: "ဇေ" ကော်ဘူး (0.35Liter) | C9: 0.35 | D9: 40 | E9: BE | F9: 780 | I9: Daw Htun May | J9: ဒေါ်ထွန်းမေ | K9: ဈေးကြို | L9: Maw La Myaing | M9: WholeSales | O9: လက်ဆောင်
A10: Zay .1Li-12-001 | B10: "ဇေ" ကော်ဘူး (1 Liter) | C10: 1 | D10: 12 | E10: BE | F10: 1475 | I10: Ma Wint War Htike | J10: မဝင့်ဝါထိုက်(ရွှေပင်လယ်) | K10: အစင် | L10: Yay | M10: WholeSales | O10: ဖောက်တိုက်
A11: Zay .1Li-12-002 | B11: "ဇေ" ကော်ဘူး (1 Liter) | C11: 1 | D11: 12 | E11: BE | F11: 1575 | I11: Ko Nyi Nyi Swe | J11: ကိုညီညီဆွေ | K11: ဈေးကြို | L11: Maw La Myaing | M11: WholeSales | O11: ကြိုရောင်း
A12: Zay .1Li-12-003(8.3.2025) | B12: "ဇေ" ကော်ဘူး (1 Liter) | C12: 1 | D12: 12 | E12: BE | F12: 1675 | I12: Lin Thit | J12: လင်းသစ် | K12: ရေး | L12: Yay | M12: WholeSales
A13: Zay Red 1Li-001 | B13: ဇေယျဝတီ Red (1 Liter) 30% | C13: 1 | D13: 12 | E13: BE | F13: 1510 | I13: Ko Mg+Ma Thu Zar | J13: ကိုမောင်+မသူဇာ | K13: လမိုင်း | L13: Yay | M13: WholeSales
A14: Zay Red 1Li-002 | B14: ဇေယျဝတီ Red (1 Liter) 30% | C14: 1 | D14: 12 | E14: BE | F14: 1610 | I14: Moe San Char Li | J14: မိုးဆန်းချာလီ | K14: သိမ်ဇရပ် | L14: Thein Zayet | M14: WholeSales
A15: Zay Red 1Li-003(8.3.2025) | B15: ဇေယျဝတီ Red (1 Liter) 30% | C15: 1 | D15: 12 | E15: BE | F15: 1710 | I15: Ko Mya Khat | J15: ကိုမြခက် | K15: ရေး(ကျောင်းရွာ) | L15: Yay | M15: WholeSales
A16: Zay 0.6Li | B16: ဇေသန့် 0.6Li | C16: 0.6 | D16: 12 | E16: BE | F16: 1100 | I16: Win Aung Shwe | J16: ၀င်းအောင်ရွှေ | K16: ဇာသပြင် | L16: Hpa-an | M16: SemiWholeSales
A17: DGN 1Li-12 | B17: ဒဂုံမန်ကျည်း ကော်ဘူး (1 Liter) | C17: 1 | D17: 12 | E17: BE | F17: 1500 | I17: U Aye Myint | J17: ဦးအေးမြင့် | K17: သိမ်ဇရပ် | L17: Thein Zayet | M17: SemiWholeSales
A18: DGN 1Li-12(8.3.2025) | B18: ဒဂုံမန်ကျည်း ကော်ဘူး (1 Liter) | C18: 1 | D18: 12 | E18: BE | F18: 1600 | I18: Ko Mon Lay | J18: ကိုမွန်လေး | K18: ရေး | L18: Yay | M18: SemiWholeSales
A19: Zay Red-14 | B19: ဇေယျဝတီ Red | C19: 0.64 | D19: 14 | E19: BE | F19: 1250 | I19: Ko Kyaw Shwe | J19: ကိုကျော်ရွှေ | K19: မုဒုံ | L19: Mudon | M19: SemiWholeSales
A20: Zay Red-14-1 | B20: ဇေယျဝတီ Red-1 | C20: 0.64 | D20: 14 | E20: BE | F20: 1270 | I20: Ko Kyaw Naing Soe | J20: ကိုကျော်နိုင်စိုး | K20: ဇီးဖြူသောင် | L20: Yay | M20: SemiWholeSales
A21: Zay Red-14-001 | B21: ဇေယျဝတီ Red | C21: 0.64 | D21: 14 | E21: BE | F21: 1150 | I21: Ko Bar Buu | J21: ကိုဘာဘူ | K21: ဇာသပြင် | L21: Hpa-an | M21: SemiWholeSales
A22: Zay Red-14-004 | B22: ဇေယျဝတီ Red | C22: 0.64 | D22: 14 | E22: BE | F22: 1080 | I22: Taw Win | J22: တော်၀င် | K22: တောင်စွန်း | L22: Belin | M22: SemiWholeSales
A23: Zay Red-14-003 | B23: ဇေယျဝတီ Red | C23: 0.64 | D23: 14 | E23: BE | F23: 1270 | I23: Ma Maw | J23: မမော် | K23: စစ်မှုထမ်းဟောင်း | L23: Hpa-an | M23: SemiWholeSales
... A41: Shwe man | B41: ရွှေမန်း | C41: 0.64 | D41: 14 | E41: BE | F41: 1500 | I41: U Hla Win | J41: ဦးလှ၀င်း | K41: စစ်မှုထမ်းဟောင်း | L41: Hpa-an | M41: Mini Whole Sales
A42: Shwe man-1Li | B42: ရွှေမန်း | C42: 1 | D42: 12 | E42: BE | I42: Mon Lay | J42: မွန်လေး | K42: မြိုင်သာယာ | L42: Maw La Myaing | M42: Mini Whole Sales
A43: DG-24-003(8.3.2025) | B43: ဒဂုံအရက်သန့် | C43: 0.64 | D43: 24 | E43: BE | F43: 1350 | I43: War Eain | J43: ဝါးအိမ် | K43: သိမ်ဇရပ်(၀ါးဒတ်ကွင်း) | L43: Thein Zayet | M43: Mini Whole Sales
A44: Mone Nae Kon Ki | B44: မိုးနဲကွန်ကီ | C44: 0.64 | D44: 14 | E44: BE | F44: 1500 | I44: Say Thitsar | J44: ဆေးသစ္စာ | K44: ဒေါင်းဇရပ် | L44: Maw La Myaing | M44: Mini Whole Sales
A45: Mone Nae Kon Ki-1 | B45: မိုးနဲကွန်ကီ | C45: 0.64 | D45: 14 | E45: BE | F45: 1700 | I45: Ye Nyunt Aung | J45: ရဲညွှန့်အောင် | K45: ကျိုက်ထို | L45: Kyaikto | M45: Mini Whole Sales
A46: Zay Red High-14-001 | B46: ဇေယျဝတီ High 43% | C46: 0.64 | D46: 14 | E46: BE | F46: 1250 | I46: La Pyae | J46: လပြည့် | K46: ဒုံ၀န်း | L46: ThaHtone | M46: Mini Whole Sales
A47: Zay Red High-14-002 | B47: ဇေယျဝတီ High 43% | C47: 0.64 | D47: 14 | E47: BE | F47: 1400 | I47: Ko Kyaw Soe | J47: ကိုကျော်စိုး (နံ့သာ) | K47: သထုံ | L47: ThaHtone | M47: Mini Whole Sales
A48: Zay Red High-14-003 | B48: ဇေယျဝတီ High 43% | C48: 0.64 | D48: 14 | E48: BE | F48: 1420 | I48: One Dollar | J48: ၀မ်းဒေါ်လာ | K48: မုဒုံ | L48: Mudon | M48: Mini Whole Sales
A49: Zay Red High-14-004(8.3.2025) | B49: ဇေယျဝတီ High 43% | C49: 0.64 | D49: 14 | E49: BE | F49: 1500 | I49: Ko Maung Oo | J49: ကိုမောင်ဦး | K49: တောင်၀ိုင်း(နတ်စင်ရှေ့) | L49: Maw La Myaing | M49: Mini Whole Sales
A50: Zay Red High-14-005 | B50: ဇေယျဝတီ High 43% | C50: 0.64 | D50: 14 | E50: BE | F50: 1550 | I50: Daw Sein Yone | J50: ဒေါ်စိန်ယုံ | K50: မုဒုံ | L50: Mudon | M50: Mini Whole Sales
A51: FR-700-12 | B51: Formula Rum 700ml | C51: 0.7 | D51: 12 | E51: Formula | F51: 3600 | I51: Nan Tha Zin | J51: နန်းသဇင် | K51: ဈေးကြို | L51: Maw La Myaing | M51: Mini Whole Sales
A52: Col-700 | B52: Col-700ml | C52: 0.7 | D52: 12 | E52: Whisky | F52: 5200 | I52: A Nae Gyi | J52: အနဲကြီး | K52: မြိုင်သာယာ | L52: Maw La Myaing | M52: Mini Whole Sales
A53: Col-700-1 | B53: Col-700ml-1 | C53: 0.7 | D53: 12 | E53: Whisky | F53: 4000 | I53: Ko Soe Naing | J53: ကိုစိုးနိုင် | K53: ကြခတ်ငူ | L53: Paung | M53: Van Sales
A54: Col-700-2 | B54: Col-700ml-2 | C54: 0.7 | D54: 12 | E54: Whisky | F54: 4500 | I54: Min Min Htun | J54: မင်းမင်းထွန်း | K54: မုတ္တမ | L54: Paung | M54: Van Sales
... A63: FR-350-24 | B63: Formula Rum 350ml | C63: 0.35 | D63: 24 | E63: Formula | F63: 1500 | I63: Daw Mya Sein | J63: ဒေါ်မြစိန် | K63: ဘုရားသုံးဆူ | L63: Bagoda-3 | M63: Van Sales
A64: FR-350-24-1 | B64: Formula Rum 350ml | C64: 0.35 | D64: 24 | E64: Formula | F64: 2100 | I64: 745 | J64: 745 | K64: မုဒုံ | L64: Mudon | M64: Van Sales
A65: BE Debtors Opening | B65: BE | E65: BE | I65: A Maung | J65: အမောင် | K65: မုဒုံ | L65: Mudon | M65: Van Sales
...

Sheet DailySales
A1: Year | B1: Month | C1: Date | D1: Today | E1: Period | F1: Column1 | G1: VoucherNo | H1: CarNo | I1: CustomerID | J1: ကုန်သည်အမည် | K1: Township | L1: WholeSales | M1: Particular | N1: StockID | O1: StockName | P1: ML | Q1: ပါဝင်မှု | R1: Bottle | S1: Parking | T1: SalesPK | U1: SalesBot | V1: Liter | W1: နှုံး | X1: သင့်ငွေ | Y1: စာရင်းဖွင့် | Z1: ဈေးဟောင်းလျှော့ | AA1: ‌ကော်မရှင် | AB1: ငွေရသည့်နေ့ | AC1: ကြွေးရငွေ | AD1: ငွေရသည့်နေ့(၂) | AE1: ကြွေးရငွေ2 | AF1: အကြွေးကျန်2 | AH1: Date | AI1: Month | AJ1: Year | AK1: Customer Name | AL1: Township | AM1: Team | AN1: Particular | AO1: Stock Name | AP1: Sales Ctns | AQ1: Sales Bot; | AR1: Sales Liter
A2: =YEAR(C2) -> 2026 | B2: =MONTH(C2) -> 1 | C2: 46023 | D2: =TODAY() -> 46097 | E2: =DATEDIF(C2,D2,"M")&"-Months" -> 2-Months | F2: =VLOOKUP(N2,Stock[#Data],5,FALSE) -> BE | I2: Daw Htun May | J2: =VLOOKUP(I2,Customers[#Data],2,FALSE) -> ဒေါ်ထွန်းမေ | K2: =VLOOKUP(I2,Customers[#Data],4,FALSE) -> Maw La Myaing | L2: =VLOOKUP(I2,Customers[#Data],5,FALSE) -> WholeSales | M2: ကုန်ရောင်း(အကြွေး) | N2: BE Debtors Opening | O2: =VLOOKUP(N2,Stock[#Data],2,FALSE) -> BE | P2: =VLOOKUP(N2,Stock[#Data],3,FALSE) -> 0 | Q2: =VLOOKUP(N2,Stock[#Data],4,FALSE) -> 0 | S2: =IFERROR(Table4[[#This Row],[Bottle]]/Table4[[#This Row],[ပါဝင်မှု]]+Table4[[#This Row],[SalesPK]],0) -> 0 | U2: =Table4[[#This Row],[ပါဝင်မှု]]*Table4[[#This Row],[SalesPK]]+Table4[[#This Row],[Bottle]] -> 0 | V2: =Table4[[#This Row],[SalesBot]]*Table4[[#This Row],[ML]] -> 0 | W2: =VLOOKUP(N2,Stock[#Data],6,FALSE) -> 0 | X2: =+Table4[[#This Row],[SalesBot]]*Table4[[#This Row],[နှုံး]] -> 0 | Y2: 1944000 | AB2: 46024 | AC2: 1944000 | AF2: =Table4[[#This Row],[စာရင်းဖွင့်]]+Table4[[#This Row],[သင့်ငွေ]]-Table4[[#This Row],[ဈေးဟောင်းလျှော့]]-Table4[[#This Row],[‌ကော်မရှင်]]-Table4[[#This Row],[ကြွေးရငွေ]]-Table4[[#This Row],[ကြွေးရငွေ2]] -> 0 | AH2: =Table4[[#This Row],[Date]] -> 46023 | AI2: =TEXT(AH2,"mmm") -> Jan | AJ2: =TEXT(AH2,"yyyy") -> 2026 | AK2: =Table4[[#This Row],[ကုန်သည်အမည်]] -> ဒေါ်ထွန်းမေ | AL2: =Table4[[#This Row],[Township]] -> Maw La Myaing | AM2: =Table4[[#This Row],[WholeSales]] -> WholeSales | AN2: =Table4[[#This Row],[Particular]] -> ကုန်ရောင်း(အကြွေး) | AO2: =Table4[[#This Row],[StockName]] -> BE | AP2: =Table4[[#This Row],[Parking]] -> 0 | AQ2: =Table4[[#This Row],[SalesBot]] -> 0 | AR2: =Table4[[#This Row],[Liter]] -> 0
A3: =YEAR(C3) -> 2026 | B3: =MONTH(C3) -> 1 | C3: 46023 | D3: =TODAY() -> 46097 | E3: =DATEDIF(C3,D3,"M")&"-Months" -> 2-Months | F3: =VLOOKUP(N3,Stock[#Data],5,FALSE) -> BE | I3: Daw New New Yee | J3: =VLOOKUP(I3,Customers[#Data],2,FALSE) -> ဒေါ်နွယ်နွယ်ရီ(ရွှေတောင်ကြား) | K3: =VLOOKUP(I3,Customers[#Data],4,FALSE) -> Yay | L3: =VLOOKUP(I3,Customers[#Data],5,FALSE) -> WholeSales | M3: ကုန်ရောင်း(အကြွေး) | N3: BE Debtors Opening | O3: =VLOOKUP(N3,Stock[#Data],2,FALSE) -> BE | P3: =VLOOKUP(N3,Stock[#Data],3,FALSE) -> 0 | Q3: =VLOOKUP(N3,Stock[#Data],4,FALSE) -> 0 | S3: =IFERROR(Table4[[#This Row],[Bottle]]/Table4[[#This Row],[ပါဝင်မှု]]+Table4[[#This Row],[SalesPK]],0) -> 0 | U3: =Table4[[#This Row],[ပါဝင်မှု]]*Table4[[#This Row],[SalesPK]]+Table4[[#This Row],[Bottle]] -> 0 | V3: =Table4[[#This Row],[SalesBot]]*Table4[[#This Row],[ML]] -> 0 | W3: =VLOOKUP(N3,Stock[#Data],6,FALSE) -> 0 | X3: =+Table4[[#This Row],[SalesBot]]*Table4[[#This Row],[နှုံး]] -> 0 | Y3: 9450000 | AB3: 46028 | AC3: 2052000 | AD3: 46031 | AE3: =5752000+1646000 -> 7398000 | AF3: =Table4[[#This Row],[စာရင်းဖွင့်]]+Table4[[#This Row],[သင့်ငွေ]]-Table4[[#This Row],[ဈေးဟောင်းလျှော့]]-Table4[[#This Row],[‌ကော်မရှင်]]-Table4[[#This Row],[ကြွေးရငွေ]]-Table4[[#This Row],[ကြွေးရငွေ2]] -> 0 | AH3: =Table4[[#This Row],[Date]] -> 46023 | AI3: =TEXT(AH3,"mmm") -> Jan | AJ3: =TEXT(AH3,"yyyy") -> 2026 | AK3: =Table4[[#This Row],[ကုန်သည်အမည်]] -> ဒေါ်နွယ်နွယ်ရီ(ရွှေတောင်ကြား) | AL3: =Table4[[#This Row],[Township]] -> Yay | AM3: =Table4[[#This Row],[WholeSales]] -> WholeSales | AN3: =Table4[[#This Row],[Particular]] -> ကုန်ရောင်း(အကြွေး) | AO3: =Table4[[#This Row],[StockName]] -> BE | AP3: =Table4[[#This Row],[Parking]] -> 0 | AQ3: =Table4[[#This Row],[SalesBot]] -> 0 | AR3: =Table4[[#This Row],[Liter]] -> 0
A4: =YEAR(C4) -> 2026 | B4: =MONTH(C4) -> 1 | C4: 46023 | D4: =TODAY() -> 46097 | E4: =DATEDIF(C4,D4,"M")&"-Months" -> 2-Months | F4: =VLOOKUP(N4,Stock[#Data],5,FALSE) -> BE | I4: Daw New New Yee | J4: =VLOOKUP(I4,Customers[#Data],2,FALSE) -> ဒေါ်နွယ်နွယ်ရီ(ရွှေတောင်ကြား) | K4: =VLOOKUP(I4,Customers[#Data],4,FALSE) -> Yay | L4: =VLOOKUP(I4,Customers[#Data],5,FALSE) -> WholeSales | M4: ကုန်ရောင်း(အကြွေး) | N4: BE Debtors Opening | O4: =VLOOKUP(N4,Stock[#Data],2,FALSE) -> BE | P4: =VLOOKUP(N4,Stock[#Data],3,FALSE) -> 0 | Q4: =VLOOKUP(N4,Stock[#Data],4,FALSE) -> 0 | S4: =IFERROR(Table4[[#This Row],[Bottle]]/Table4[[#This Row],[ပါဝင်မှု]]+Table4[[#This Row],[SalesPK]],0) -> 0 | U4: =Table4[[#This Row],[ပါဝင်မှု]]*Table4[[#This Row],[SalesPK]]+Table4[[#This Row],[Bottle]] -> 0 | V4: =Table4[[#This Row],[SalesBot]]*Table4[[#This Row],[ML]] -> 0 | W4: =VLOOKUP(N4,Stock[#Data],6,FALSE) -> 0 | X4: =+Table4[[#This Row],[SalesBot]]*Table4[[#This Row],[နှုံး]] -> 0 | Y4: 9450000 | AB4: 46034 | AC4: 6156000 | AD4: 46037 | AE4: =2052000+1242000 -> 3294000 | AF4: =Table4[[#This Row],[စာရင်းဖွင့်]]+Table4[[#This Row],[သင့်ငွေ]]-Table4[[#This Row],[ဈေးဟောင်းလျှော့]]-Table4[[#This Row],[‌ကော်မရှင်]]-Table4[[#This Row],[ကြွေးရငွေ]]-Table4[[#This Row],[ကြွေးရငွေ2]] -> 0 | AH4: =Table4[[#This Row],[Date]] -> 46023 | AI4: =TEXT(AH4,"mmm") -> Jan | AJ4: =TEXT(AH4,"yyyy") -> 2026 | AK4: =Table4[[#This Row],[ကုန်သည်အမည်]] -> ဒေါ်နွယ်နွယ်ရီ(ရွှေတောင်ကြား) | AL4: =Table4[[#This Row],[Township]] -> Yay | AM4: =Table4[[#This Row],[WholeSales]] -> WholeSales | AN4: =Table4[[#This Row],[Particular]] -> ကုန်ရောင်း(အကြွေး) | AO4: =Table4[[#This Row],[StockName]] -> BE | AP4: =Table4[[#This Row],[Parking]] -> 0 | AQ4: =Table4[[#This Row],[SalesBot]] -> 0 | AR4: =Table4[[#This Row],[Liter]] -> 0
A5: =YEAR(C5) -> 2026 | B5: =MONTH(C5) -> 1 | C5: 46023 | D5: =TODAY() -> 46097 | E5: =DATEDIF(C5,D5,"M")&"-Months" -> 2-Months | F5: =VLOOKUP(N5,Stock[#Data],5,FALSE) -> BE | I5: Daw New New Yee | J5: =VLOOKUP(I5,Customers[#Data],2,FALSE) -> ဒေါ်နွယ်နွယ်ရီ(ရွှေတောင်ကြား) | K5: =VLOOKUP(I5,Customers[#Data],4,FALSE) -> Yay | L5: =VLOOKUP(I5,Customers[#Data],5,FALSE) -> WholeSales | M5: ကုန်ရောင်း(အကြွေး) | N5: BE Debtors Opening | O5: =VLOOKUP(N5,Stock[#Data],2,FALSE) -> BE | P5: =VLOOKUP(N5,Stock[#Data],3,FALSE) -> 0 | Q5: =VLOOKUP(N5,Stock[#Data],4,FALSE) -> 0 | S5: =IFERROR(Table4[[#This Row],[Bottle]]/Table4[[#This Row],[ပါဝင်မှု]]+Table4[[#This Row],[SalesPK]],0) -> 0 | U5: =Table4[[#This Row],[ပါဝင်မှု]]*Table4[[#This Row],[SalesPK]]+Table4[[#This Row],[Bottle]] -> 0 | V5: =Table4[[#This Row],[SalesBot]]*Table4[[#This Row],[ML]] -> 0 | W5: =VLOOKUP(N5,Stock[#Data],6,FALSE) -> 0 | X5: =+Table4[[#This Row],[SalesBot]]*Table4[[#This Row],[နှုံး]] -> 0 | Y5: 1890000 | AB5: 46039 | AC5: 1890000 | AF5: =Table4[[#This Row],[စာရင်းဖွင့်]]+Table4[[#This Row],[သင့်ငွေ]]-Table4[[#This Row],[ဈေးဟောင်းလျှော့]]-Table4[[#This Row],[‌ကော်မရှင်]]-Table4[[#This Row],[ကြွေးရငွေ]]-Table4[[#This Row],[ကြွေးရငွေ2]] -> 0 | AH5: =Table4[[#This Row],[Date]] -> 46023 | AI5: =TEXT(AH5,"mmm") -> Jan | AJ5: =TEXT(AH5,"yyyy") -> 2026 | AK5: =Table4[[#This Row],[ကုန်သည်အမည်]] -> ဒေါ်နွယ်နွယ်ရီ(ရွှေတောင်ကြား) | AL5: =Table4[[#This Row],[Township]] -> Yay | AM5: =Table4[[#This Row],[WholeSales]] -> WholeSales | AN5: =Table4[[#This Row],[Particular]] -> ကုန်ရောင်း(အကြွေး) | AO5: =Table4[[#This Row],[StockName]] -> BE | AP5: =Table4[[#This Row],[Parking]] -> 0 | AQ5: =Table4[[#This Row],[SalesBot]] -> 0 | AR5: =Table4[[#This Row],[Liter]] -> 0
A6: =YEAR(C6) -> 2026 | B6: =MONTH(C6) -> 1 | C6: 46023 | D6: =TODAY() -> 46097 | E6: =DATEDIF(C6,D6,"M")&"-Months" -> 2-Months | F6: =VLOOKUP(N6,Stock[#Data],5,FALSE) -> BE | I6: Daw New New Yee | J6: =VLOOKUP(I6,Customers[#Data],2,FALSE) -> ဒေါ်နွယ်နွယ်ရီ(ရွှေတောင်ကြား) | K6: =VLOOKUP(I6,Customers[#Data],4,FALSE) -> Yay | L6: =VLOOKUP(I6,Customers[#Data],5,FALSE) -> WholeSales | M6: ကုန်ရောင်း(အကြွေး) | N6: BE Debtors Opening | O6: =VLOOKUP(N6,Stock[#Data],2,FALSE) -> BE | P6: =VLOOKUP(N6,Stock[#Data],3,FALSE) -> 0 | Q6: =VLOOKUP(N6,Stock[#Data],4,FALSE) -> 0 | S6: =IFERROR(Table4[[#This Row],[Bottle]]/Table4[[#This Row],[ပါဝင်မှု]]+Table4[[#This Row],[SalesPK]],0) -> 0 | U6: =Table4[[#This Row],[ပါဝင်မှု]]*Table4[[#This Row],[SalesPK]]+Table4[[#This Row],[Bottle]] -> 0 | V6: =Table4[[#This Row],[SalesBot]]*Table4[[#This Row],[ML]] -> 0 | W6: =VLOOKUP(N6,Stock[#Data],6,FALSE) -> 0 | X6: =+Table4[[#This Row],[SalesBot]]*Table4[[#This Row],[နှုံး]] -> 0 | Y6: 7560000 | AB6: 46039 | AC6: 7560000 | AF6: =Table4[[#This Row],[စာရင်းဖွင့်]]+Table4[[#This Row],[သင့်ငွေ]]-Table4[[#This Row],[ဈေးဟောင်းလျှော့]]-Table4[[#This Row],[‌ကော်မရှင်]]-Table4[[#This Row],[ကြွေးရငွေ]]-Table4[[#This Row],[ကြွေးရငွေ2]] -> 0 | AH6: =Table4[[#This Row],[Date]] -> 46023 | AI6: =TEXT(AH6,"mmm") -> Jan | AJ6: =TEXT(AH6,"yyyy") -> 2026 | AK6: =Table4[[#This Row],[ကုန်သည်အမည်]] -> ဒေါ်နွယ်နွယ်ရီ(ရွှေတောင်ကြား) | AL6: =Table4[[#This Row],[Township]] -> Yay | AM6: =Table4[[#This Row],[WholeSales]] -> WholeSales | AN6: =Table4[[#This Row],[Particular]] -> ကုန်ရောင်း(အကြွေး) | AO6: =Table4[[#This Row],[StockName]] -> BE | AP6: =Table4[[#This Row],[Parking]] -> 0 | AQ6: =Table4[[#This Row],[SalesBot]] -> 0 | AR6: =Table4[[#This Row],[Liter]] -> 0
A7: =YEAR(C7) -> 2026 | B7: =MONTH(C7) -> 1 | C7: 46023 | D7: =TODAY() -> 46097 | E7: =DATEDIF(C7,D7,"M")&"-Months" -> 2-Months | F7: =VLOOKUP(N7,Stock[#Data],5,FALSE) -> BE | I7: Daw New New Yee | J7: =VLOOKUP(I7,Customers[#Data],2,FALSE) -> ဒေါ်နွယ်နွယ်ရီ(ရွှေတောင်ကြား) | K7: =VLOOKUP(I7,Customers[#Data],4,FALSE) -> Yay | L7: =VLOOKUP(I7,Customers[#Data],5,FALSE) -> WholeSales | M7: ကုန်ရောင်း(အကြွေး) | N7: BE Debtors Opening | O7: =VLOOKUP(N7,Stock[#Data],2,FALSE) -> BE | P7: =VLOOKUP(N7,Stock[#Data],3,FALSE) -> 0 | Q7: =VLOOKUP(N7,Stock[#Data],4,FALSE) -> 0 | S7: =IFERROR(Table4[[#This Row],[Bottle]]/Table4[[#This Row],[ပါဝင်မှု]]+Table4[[#This Row],[SalesPK]],0) -> 0 | U7: =Table4[[#This Row],[ပါဝင်မှု]]*Table4[[#This Row],[SalesPK]]+Table4[[#This Row],[Bottle]] -> 0 | V7: =Table4[[#This Row],[SalesBot]]*Table4[[#This Row],[ML]] -> 0 | W7: =VLOOKUP(N7,Stock[#Data],6,FALSE) -> 0 | X7: =+Table4[[#This Row],[SalesBot]]*Table4[[#This Row],[နှုံး]] -> 0 | Y7: 9450000 | AB7: 46039 | AC7: 810000 | AD7: 46043 | AE7: 3740000 | AF7: =Table4[[#This Row],[စာရင်းဖွင့်]]+Table4[[#This Row],[သင့်ငွေ]]-Table4[[#This Row],[ဈေးဟောင်းလျှော့]]-Table4[[#This Row],[‌ကော်မရှင်]]-Table4[[#This Row],[ကြွေးရငွေ]]-Table4[[#This Row],[ကြွေးရငွေ2]] -> 4900000 | AH7: =Table4[[#This Row],[Date]] -> 46023 | AI7: =TEXT(AH7,"mmm") -> Jan | AJ7: =TEXT(AH7,"yyyy") -> 2026 | AK7: =Table4[[#This Row],[ကုန်သည်အမည်]] -> ဒေါ်နွယ်နွယ်ရီ(ရွှေတောင်ကြား) | AL7: =Table4[[#This Row],[Township]] -> Yay | AM7: =Table4[[#This Row],[WholeSales]] -> WholeSales | AN7: =Table4[[#This Row],[Particular]] -> ကုန်ရောင်း(အကြွေး) | AO7: =Table4[[#This Row],[StockName]] -> BE | AP7: =Table4[[#This Row],[Parking]] -> 0 | AQ7: =Table4[[#This Row],[SalesBot]] -> 0 | AR7: =Table4[[#This Row],[Liter]] -> 0
A8: =YEAR(C8) -> 2026 | B8: =MONTH(C8) -> 1 | C8: 46023 | D8: =TODAY() -> 46097 | E8: =DATEDIF(C8,D8,"M")&"-Months" -> 2-Months | F8: =VLOOKUP(N8,Stock[#Data],5,FALSE) -> BE | I8: Daw New New Yee | J8: =VLOOKUP(I8,Customers[#Data],2,FALSE) -> ဒေါ်နွယ်နွယ်ရီ(ရွှေတောင်ကြား) | K8: =VLOOKUP(I8,Customers[#Data],4,FALSE) -> Yay | L8: =VLOOKUP(I8,Customers[#Data],5,FALSE) -> WholeSales | M8: ကုန်ရောင်း(အကြွေး) | N8: BE Debtors Opening | O8: =VLOOKUP(N8,Stock[#Data],2,FALSE) -> BE | P8: =VLOOKUP(N8,Stock[#Data],3,FALSE) -> 0 | Q8: =VLOOKUP(N8,Stock[#Data],4,FALSE) -> 0 | S8: =IFERROR(Table4[[#This Row],[Bottle]]/Table4[[#This Row],[ပါဝင်မှု]]+Table4[[#This Row],[SalesPK]],0) -> 0 | U8: =Table4[[#This Row],[ပါဝင်မှု]]*Table4[[#This Row],[SalesPK]]+Table4[[#This Row],[Bottle]] -> 0 | V8: =Table4[[#This Row],[SalesBot]]*Table4[[#This Row],[ML]] -> 0 | W8: =VLOOKUP(N8,Stock[#Data],6,FALSE) -> 0 | X8: =+Table4[[#This Row],[SalesBot]]*Table4[[#This Row],[နှုံး]] -> 0 | Y8: 2052000 | AB8: 46043 | AC8: 2052000 | AF8: =Table4[[#This Row],[စာရင်းဖွင့်]]+Table4[[#This Row],[သင့်ငွေ]]-Table4[[#This Row],[ဈေးဟောင်းလျှော့]]-Table4[[#This Row],[‌ကော်မရှင်]]-Table4[[#This Row],[ကြွေးရငွေ]]-Table4[[#This Row],[ကြွေးရငွေ2]] -> 0 | AH8: =Table4[[#This Row],[Date]] -> 46023 | AI8: =TEXT(AH8,"mmm") -> Jan | AJ8: =TEXT(AH8,"yyyy") -> 2026 | AK8: =Table4[[#This Row],[ကုန်သည်အမည်]] -> ဒေါ်နွယ်နွယ်ရီ(ရွှေတောင်ကြား) | AL8: =Table4[[#This Row],[Township]] -> Yay | AM8: =Table4[[#This Row],[WholeSales]] -> WholeSales | AN8: =Table4[[#This Row],[Particular]] -> ကုန်ရောင်း(အကြွေး) | AO8: =Table4[[#This Row],[StockName]] -> BE | AP8: =Table4[[#This Row],[Parking]] -> 0 | AQ8: =Table4[[#This Row],[SalesBot]] -> 0 | AR8: =Table4[[#This Row],[Liter]] -> 0
A9: =YEAR(C9) -> 2026 | B9: =MONTH(C9) -> 1 | C9: 46023 | D9: =TODAY() -> 46097 | E9: =DATEDIF(C9,D9,"M")&"-Months" -> 2-Months | F9: =VLOOKUP(N9,Stock[#Data],5,FALSE) -> BE | I9: Ko Htun Naing | J9: =VLOOKUP(I9,Customers[#Data],2,FALSE) -> ကိုထွန်းနိုင် | K9: =VLOOKUP(I9,Customers[#Data],4,FALSE) -> Yay | L9: =VLOOKUP(I9,Customers[#Data],5,FALSE) -> WholeSales | M9: ကုန်ရောင်း(အကြွေး) | N9: BE Debtors Opening | O9: =VLOOKUP(N9,Stock[#Data],2,FALSE) -> BE | P9: =VLOOKUP(N9,Stock[#Data],3,FALSE) -> 0 | Q9: =VLOOKUP(N9,Stock[#Data],4,FALSE) -> 0 | S9: =IFERROR(Table4[[#This Row],[Bottle]]/Table4[[#This Row],[ပါဝင်မှု]]+Table4[[#This Row],[SalesPK]],0) -> 0 | U9: =Table4[[#This Row],[ပါဝင်မှု]]*Table4[[#This Row],[SalesPK]]+Table4[[#This Row],[Bottle]] -> 0 | V9: =Table4[[#This Row],[SalesBot]]*Table4[[#This Row],[ML]] -> 0 | W9: =VLOOKUP(N9,Stock[#Data],6,FALSE) -> 0 | X9: =+Table4[[#This Row],[SalesBot]]*Table4[[#This Row],[နှုံး]] -> 0 | Y9: 3861000 | AB9: 46028 | AC9: 3861000 | AF9: =Table4[[#This Row],[စာရင်းဖွင့်]]+Table4[[#This Row],[သင့်ငွေ]]-Table4[[#This Row],[ဈေးဟောင်းလျှော့]]-Table4[[#This Row],[‌ကော်မရှင်]]-Table4[[#This Row],[ကြွေးရငွေ]]-Table4[[#This Row],[ကြွေးရငွေ2]] -> 0 | AH9: =Table4[[#This Row],[Date]] -> 46023 | AI9: =TEXT(AH9,"mmm") -> Jan | AJ9: =TEXT(AH9,"yyyy") -> 2026 | AK9: =Table4[[#This Row],[ကုန်သည်အမည်]] -> ကိုထွန်းနိုင် | AL9: =Table4[[#This Row],[Township]] -> Yay | AM9: =Table4[[#This Row],[WholeSales]] -> WholeSales | AN9: =Table4[[#This Row],[Particular]] -> ကုန်ရောင်း(အကြွေး) | AO9: =Table4[[#This Row],[StockName]] -> BE | AP9: =Table4[[#This Row],[Parking]] -> 0 | AQ9: =Table4[[#This Row],[SalesBot]] -> 0 | AR9: =Table4[[#This Row],[Liter]] -> 0
A10: =YEAR(C10) -> 2026 | B10: =MONTH(C10) -> 1 | C10: 46023 | D10: =TODAY() -> 46097 | E10: =DATEDIF(C10,D10,"M")&"-Months" -> 2-Months | F10: =VLOOKUP(N10,Stock[#Data],5,FALSE) -> BE | I10: Kyaw Star | J10: =VLOOKUP(I10,Customers[#Data],2,FALSE) -> ကျော်စတား | K10: =VLOOKUP(I10,Customers[#Data],4,FALSE) -> Yay | L10: =VLOOKUP(I10,Customers[#Data],5,FALSE) -> WholeSales | M10: ကုန်ရောင်း(အကြွေး) | N10: BE Debtors Opening | O10: =VLOOKUP(N10,Stock[#Data],2,FALSE) -> BE | P10: =VLOOKUP(N10,Stock[#Data],3,FALSE) -> 0 | Q10: =VLOOKUP(N10,Stock[#Data],4,FALSE) -> 0 | S10: =IFERROR(Table4[[#This Row],[Bottle]]/Table4[[#This Row],[ပါဝင်မှု]]+Table4[[#This Row],[SalesPK]],0) -> 0 | U10: =Table4[[#This Row],[ပါဝင်မှု]]*Table4[[#This Row],[SalesPK]]+Table4[[#This Row],[Bottle]] -> 0 | V10: =Table4[[#This Row],[SalesBot]]*Table4[[#This Row],[ML]] -> 0 | W10: =VLOOKUP(N10,Stock[#Data],6,FALSE) -> 0 | X10: =+Table4[[#This Row],[SalesBot]]*Table4[[#This Row],[နှုံး]] -> 0 | Y10: 4509000 | AB10: 46025 | AC10: 4509000 | AF10: =Table4[[#This Row],[စာရင်းဖွင့်]]+Table4[[#This Row],[သင့်ငွေ]]-Table4[[#This Row],[ဈေးဟောင်းလျှော့]]-Table4[[#This Row],[‌ကော်မရှင်]]-Table4[[#This Row],[ကြွေးရငွေ]]-Table4[[#This Row],[ကြွေးရငွေ2]] -> 0 | AH10: =Table4[[#This Row],[Date]] -> 46023 | AI10: =TEXT(AH10,"mmm") -> Jan | AJ10: =TEXT(AH10,"yyyy") -> 2026 | AK10: =Table4[[#This Row],[ကုန်သည်အမည်]] -> ကျော်စတား | AL10: =Table4[[#This Row],[Township]] -> Yay | AM10: =Table4[[#This Row],[WholeSales]] -> WholeSales | AN10: =Table4[[#This Row],[Particular]] -> ကုန်ရောင်း(အကြွေး) | AO10: =Table4[[#This Row],[StockName]] -> BE | AP10: =Table4[[#This Row],[Parking]] -> 0 | AQ10: =Table4[[#This Row],[SalesBot]] -> 0 | AR10: =Table4[[#This Row],[Liter]] -> 0
A11: =YEAR(C11) -> 2026 | B11: =MONTH(C11) -> 1 | C11: 46023 | D11: =TODAY() -> 46097 | E11: =DATEDIF(C11,D11,"M")&"-Months" -> 2-Months | F11: =VLOOKUP(N11,Stock[#Data],5,FALSE) -> BE | I11: Kyaw Star | J11: =VLOOKUP(I11,Customers[#Data],2,FALSE) -> ကျော်စတား | K11: =VLOOKUP(I11,Customers[#Data],4,FALSE) -> Yay | L11: =VLOOKUP(I11,Customers[#Data],5,FALSE) -> WholeSales | M11: ကုန်ရောင်း(အကြွေး) | N11: BE Debtors Opening | O11: =VLOOKUP(N11,Stock[#Data],2,FALSE) -> BE | P11: =VLOOKUP(N11,Stock[#Data],3,FALSE) -> 0 | Q11: =VLOOKUP(N11,Stock[#Data],4,FALSE) -> 0 | S11: =IFERROR(Table4[[#This Row],[Bottle]]/Table4[[#This Row],[ပါဝင်မှု]]+Table4[[#This Row],[SalesPK]],0) -> 0 | U11: =Table4[[#This Row],[ပါဝင်မှု]]*Table4[[#This Row],[SalesPK]]+Table4[[#This Row],[Bottle]] -> 0 | V11: =Table4[[#This Row],[SalesBot]]*Table4[[#This Row],[ML]] -> 0 | W11: =VLOOKUP(N11,Stock[#Data],6,FALSE) -> 0 | X11: =+Table4[[#This Row],[SalesBot]]*Table4[[#This Row],[နှုံး]] -> 0 | Y11: 5076000 | AB11: 46025 | AC11: 5076000 | AF11: =Table4[[#This Row],[စာရင်းဖွင့်]]+Table4[[#This Row],[သင့်ငွေ]]-Table4[[#This Row],[ဈေးဟောင်းလျှော့]]-Table4[[#This Row],[‌ကော်မရှင်]]-Table4[[#This Row],[ကြွေးရငွေ]]-Table4[[#This Row],[ကြွေးရငွေ2]] -> 0 | AH11: =Table4[[#This Row],[Date]] -> 46023 | AI11: =TEXT(AH11,"mmm") -> Jan | AJ11: =TEXT(AH11,"yyyy") -> 2026 | AK11: =Table4[[#This Row],[ကုန်သည်အမည်]] -> ကျော်စတား | AL11: =Table4[[#This Row],[Township]] -> Yay | AM11: =Table4[[#This Row],[WholeSales]] -> WholeSales | AN11: =Table4[[#This Row],[Particular]] -> ကုန်ရောင်း(အကြွေး) | AO11: =Table4[[#This Row],[StockName]] -> BE | AP11: =Table4[[#This Row],[Parking]] -> 0 | AQ11: =Table4[[#This Row],[SalesBot]] -> 0 | AR11: =Table4[[#This Row],[Liter]] -> 0
A12: =YEAR(C12) -> 2026 | B12: =MONTH(C12) -> 1 | C12: 46023 | D12: =TODAY() -> 46097 | E12: =DATEDIF(C12,D12,"M")&"-Months" -> 2-Months | F12: =VLOOKUP(N12,Stock[#Data],5,FALSE) -> BE | I12: Kyaw Star | J12: =VLOOKUP(I12,Customers[#Data],2,FALSE) -> ကျော်စတား | K12: =VLOOKUP(I12,Customers[#Data],4,FALSE) -> Yay | L12: =VLOOKUP(I12,Customers[#Data],5,FALSE) -> WholeSales | M12: ကုန်ရောင်း(အကြွေး) | N12: BE Debtors Opening | O12: =VLOOKUP(N12,Stock[#Data],2,FALSE) -> BE | P12: =VLOOKUP(N12,Stock[#Data],3,FALSE) -> 0 | Q12: =VLOOKUP(N12,Stock[#Data],4,FALSE) -> 0 | S12: =IFERROR(Table4[[#This Row],[Bottle]]/Table4[[#This Row],[ပါဝင်မှု]]+Table4[[#This Row],[SalesPK]],0) -> 0 | U12: =Table4[[#This Row],[ပါဝင်မှု]]*Table4[[#This Row],[SalesPK]]+Table4[[#This Row],[Bottle]] -> 0 | V12: =Table4[[#This Row],[SalesBot]]*Table4[[#This Row],[ML]] -> 0 | W12: =VLOOKUP(N12,Stock[#Data],6,FALSE) -> 0 | X12: =+Table4[[#This Row],[SalesBot]]*Table4[[#This Row],[နှုံး]] -> 0 | Y12: 3942000 | AB12: 46028 | AC12: 3942000 | AF12: =Table4[[#This Row],[စာရင်းဖွင့်]]+Table4[[#This Row],[သင့်ငွေ]]-Table4[[#This Row],[ဈေးဟောင်းလျှော့]]-Table4[[#This Row],[‌ကော်မရှင်]]-Table4[[#This Row],[ကြွေးရငွေ]]-Table4[[#This Row],[ကြွေးရငွေ2]] -> 0 | AH12: =Table4[[#This Row],[Date]] -> 46023 | AI12: =TEXT(AH12,"mmm") -> Jan | AJ12: =TEXT(AH12,"yyyy") -> 2026 | AK12: =Table4[[#This Row],[ကုန်သည်အမည်]] -> ကျော်စတား | AL12: =Table4[[#This Row],[Township]] -> Yay | AM12: =Table4[[#This Row],[WholeSales]] -> WholeSales | AN12: =Table4[[#This Row],[Particular]] -> ကုန်ရောင်း(အကြွေး) | AO12: =Table4[[#This Row],[StockName]] -> BE | AP12: =Table4[[#This Row],[Parking]] -> 0 | AQ12: =Table4[[#This Row],[SalesBot]] -> 0 | AR12: =Table4[[#This Row],[Liter]] -> 0
A13: =YEAR(C13) -> 2026 | B13: =MONTH(C13) -> 1 | C13: 46023 | D13: =TODAY() -> 46097 | E13: =DATEDIF(C13,D13,"M")&"-Months" -> 2-Months | F13: =VLOOKUP(N13,Stock[#Data],5,FALSE) -> BE | I13: Kyaw Star | J13: =VLOOKUP(I13,Customers[#Data],2,FALSE) -> ကျော်စတား | K13: =VLOOKUP(I13,Customers[#Data],4,FALSE) -> Yay | L13: =VLOOKUP(I13,Customers[#Data],5,FALSE) -> WholeSales | M13: ကုန်ရောင်း(အကြွေး) | N13: BE Debtors Opening | O13: =VLOOKUP(N13,Stock[#Data],2,FALSE) -> BE | P13: =VLOOKUP(N13,Stock[#Data],3,FALSE) -> 0 | Q13: =VLOOKUP(N13,Stock[#Data],4,FALSE) -> 0 | S13: =IFERROR(Table4[[#This Row],[Bottle]]/Table4[[#This Row],[ပါဝင်မှု]]+Table4[[#This Row],[SalesPK]],0) -> 0 | U13: =Table4[[#This Row],[ပါဝင်မှု]]*Table4[[#This Row],[SalesPK]]+Table4[[#This Row],[Bottle]] -> 0 | V13: =Table4[[#This Row],[SalesBot]]*Table4[[#This Row],[ML]] -> 0 | W13: =VLOOKUP(N13,Stock[#Data],6,FALSE) -> 0 | X13: =+Table4[[#This Row],[SalesBot]]*Table4[[#This Row],[နှုံး]] -> 0 | Y13: 6763500 | AB13: 46028 | AC13: 6763500 | AF13: =Table4[[#This Row],[စာရင်းဖွင့်]]+Table4[[#This Row],[သင့်ငွေ]]-Table4[[#This Row],[ဈေးဟောင်းလျှော့]]-Table4[[#This Row],[‌ကော်မရှင်]]-Table4[[#This Row],[ကြွေးရငွေ]]-Table4[[#This Row],[ကြွေးရငွေ2]] -> 0 | AH13: =Table4[[#This Row],[Date]] -> 46023 | AI13: =TEXT(AH13,"mmm") -> Jan | AJ13: =TEXT(AH13,"yyyy") -> 2026 | AK13: =Table4[[#This Row],[ကုန်သည်အမည်]] -> ကျော်စတား | AL13: =Table4[[#This Row],[Township]] -> Yay | AM13: =Table4[[#This Row],[WholeSales]] -> WholeSales | AN13: =Table4[[#This Row],[Particular]] -> ကုန်ရောင်း(အကြွေး) | AO13: =Table4[[#This Row],[StockName]] -> BE | AP13: =Table4[[#This Row],[Parking]] -> 0 | AQ13: =Table4[[#This Row],[SalesBot]] -> 0 | AR13: =Table4[[#This Row],[Liter]] -> 0
A14: =YEAR(C14) -> 2026 | B14: =MONTH(C14) -> 1 | C14: 46023 | D14: =TODAY() -> 46097 | E14: =DATEDIF(C14,D14,"M")&"-Months" -> 2-Months | F14: =VLOOKUP(N14,Stock[#Data],5,FALSE) -> BE | I14: Kyaw Star | J14: =VLOOKUP(I14,Customers[#Data],2,FALSE) -> ကျော်စတား | K14: =VLOOKUP(I14,Customers[#Data],4,FALSE) -> Yay | L14: =VLOOKUP(I14,Customers[#Data],5,FALSE) -> WholeSales | M14: ကုန်ရောင်း(အကြွေး) | N14: BE Debtors Opening | O14: =VLOOKUP(N14,Stock[#Data],2,FALSE) -> BE | P14: =VLOOKUP(N14,Stock[#Data],3,FALSE) -> 0 | Q14: =VLOOKUP(N14,Stock[#Data],4,FALSE) -> 0 | S14: =IFERROR(Table4[[#This Row],[Bottle]]/Table4[[#This Row],[ပါဝင်မှု]]+Table4[[#This Row],[SalesPK]],0) -> 0 | U14: =Table4[[#This Row],[ပါဝင်မှု]]*Table4[[#This Row],[SalesPK]]+Table4[[#This Row],[Bottle]] -> 0 | V14: =Table4[[#This Row],[SalesBot]]*Table4[[#This Row],[ML]] -> 0 | W14: =VLOOKUP(N14,Stock[#Data],6,FALSE) -> 0 | X14: =+Table4[[#This Row],[SalesBot]]*Table4[[#This Row],[နှုံး]] -> 0 | Y14: 4225500 | AB14: 46030 | AC14: 4225500 | AF14: =Table4[[#This Row],[စာရင်းဖွင့်]]+Table4[[#This Row],[သင့်ငွေ]]-Table4[[#This Row],[ဈေးဟောင်းလျှော့]]-Table4[[#This Row],[‌ကော်မရှင်]]-Table4[[#This Row],[ကြွေးရငွေ]]-Table4[[#This Row],[ကြွေးရငွေ2]] -> 0 | AH14: =Table4[[#This Row],[Date]] -> 46023 | AI14: =TEXT(AH14,"mmm") -> Jan | AJ14: =TEXT(AH14,"yyyy") -> 2026 | AK14: =Table4[[#This Row],[ကုန်သည်အမည်]] -> ကျော်စတား | AL14: =Table4[[#This Row],[Township]] -> Yay | AM14: =Table4[[#This Row],[WholeSales]] -> WholeSales | AN14: =Table4[[#This Row],[Particular]] -> ကုန်ရောင်း(အကြွေး) | AO14: =Table4[[#This Row],[StockName]] -> BE | AP14: =Table4[[#This Row],[Parking]] -> 0 | AQ14: =Table4[[#This Row],[SalesBot]] -> 0 | AR14: =Table4[[#This Row],[Liter]] -> 0
A15: =YEAR(C15) -> 2026 | B15: =MONTH(C15) -> 1 | C15: 46023 | D15: =TODAY() -> 46097 | E15: =DATEDIF(C15,D15,"M")&"-Months" -> 2-Months | F15: =VLOOKUP(N15,Stock[#Data],5,FALSE) -> BE | I15: Kyaw Star | J15: =VLOOKUP(I15,Customers[#Data],2,FALSE) -> ကျော်စတား | K15: =VLOOKUP(I15,Customers[#Data],4,FALSE) -> Yay | L15: =VLOOKUP(I15,Customers[#Data],5,FALSE) -> WholeSales | M15: ကုန်ရောင်း(အကြွေး) | N15: BE Debtors Opening | O15: =VLOOKUP(N15,Stock[#Data],2,FALSE) -> BE | P15: =VLOOKUP(N15,Stock[#Data],3,FALSE) -> 0 | Q15: =VLOOKUP(N15,Stock[#Data],4,FALSE) -> 0 | S15: =IFERROR(Table4[[#This Row],[Bottle]]/Table4[[#This Row],[ပါဝင်မှု]]+Table4[[#This Row],[SalesPK]],0) -> 0 | U15: =Table4[[#This Row],[ပါဝင်မှု]]*Table4[[#This Row],[SalesPK]]+Table4[[#This Row],[Bottle]] -> 0 | V15: =Table4[[#This Row],[SalesBot]]*Table4[[#This Row],[ML]] -> 0 | W15: =VLOOKUP(N15,Stock[#Data],6,FALSE) -> 0 | X15: =+Table4[[#This Row],[SalesBot]]*Table4[[#This Row],[နှုံး]] -> 0 | Y15: 2835000 | AB15: 46030 | AC15: 2835000 | AF15: =Table4[[#This Row],[စာရင်းဖွင့်]]+Table4[[#This Row],[သင့်ငွေ]]-Table4[[#This Row],[ဈေးဟောင်းလျှော့]]-Table4[[#This Row],[‌ကော်မရှင်]]-Table4[[#This Row],[ကြွေးရငွေ]]-Table4[[#This Row],[ကြွေးရငွေ2]] -> 0 | AH15: =Table4[[#This Row],[Date]] -> 46023 | AI15: =TEXT(AH15,"mmm") -> Jan | AJ15: =TEXT(AH15,"yyyy") -> 2026 | AK15: =Table4[[#This Row],[ကုန်သည်အမည်]] -> ကျော်စတား | AL15: =Table4[[#This Row],[Township]] -> Yay | AM15: =Table4[[#This Row],[WholeSales]] -> WholeSales | AN15: =Table4[[#This Row],[Particular]] -> ကုန်ရောင်း(အကြွေး) | AO15: =Table4[[#This Row],[StockName]] -> BE | AP15: =Table4[[#This Row],[Parking]] -> 0 | AQ15: =Table4[[#This Row],[SalesBot]] -> 0 | AR15: =Table4[[#This Row],[Liter]] -> 0
A16: =YEAR(C16) -> 2026 | B16: =MONTH(C16) -> 1 | C16: 46023 | D16: =TODAY() -> 46097 | E16: =DATEDIF(C16,D16,"M")&"-Months" -> 2-Months | F16: =VLOOKUP(N16,Stock[#Data],5,FALSE) -> BE | I16: Kyaw Star | J16: =VLOOKUP(I16,Customers[#Data],2,FALSE) -> ကျော်စတား | K16: =VLOOKUP(I16,Customers[#Data],4,FALSE) -> Yay | L16: =VLOOKUP(I16,Customers[#Data],5,FALSE) -> WholeSales | M16: ကုန်ရောင်း(အကြွေး) | N16: BE Debtors Opening | O16: =VLOOKUP(N16,Stock[#Data],2,FALSE) -> BE | P16: =VLOOKUP(N16,Stock[#Data],3,FALSE) -> 0 | Q16: =VLOOKUP(N16,Stock[#Data],4,FALSE) -> 0 | S16: =IFERROR(Table4[[#This Row],[Bottle]]/Table4[[#This Row],[ပါဝင်မှု]]+Table4[[#This Row],[SalesPK]],0) -> 0 | U16: =Table4[[#This Row],[ပါဝင်မှု]]*Table4[[#This Row],[SalesPK]]+Table4[[#This Row],[Bottle]] -> 0 | V16: =Table4[[#This Row],[SalesBot]]*Table4[[#This Row],[ML]] -> 0 | W16: =VLOOKUP(N16,Stock[#Data],6,FALSE) -> 0 | X16: =+Table4[[#This Row],[SalesBot]]*Table4[[#This Row],[နှုံး]] -> 0 | Y16: 3942000 | AB16: 46034 | AC16: 3942000 | AF16: =Table4[[#This Row],[စာရင်းဖွင့်]]+Table4[[#This Row],[သင့်ငွေ]]-Table4[[#This Row],[ဈေးဟောင်းလျှော့]]-Table4[[#This Row],[‌ကော်မရှင်]]-Table4[[#This Row],[ကြွေးရငွေ]]-Table4[[#This Row],[ကြွေးရငွေ2]] -> 0 | AH16: =Table4[[#This Row],[Date]] -> 46023 | AI16: =TEXT(AH16,"mmm") -> Jan | AJ16: =TEXT(AH16,"yyyy") -> 2026 | AK16: =Table4[[#This Row],[ကုန်သည်အမည်]] -> ကျော်စတား | AL16: =Table4[[#This Row],[Township]] -> Yay | AM16: =Table4[[#This Row],[WholeSales]] -> WholeSales | AN16: =Table4[[#This Row],[Particular]] -> ကုန်ရောင်း(အကြွေး) | AO16: =Table4[[#This Row],[StockName]] -> BE | AP16: =Table4[[#This Row],[Parking]] -> 0 | AQ16: =Table4[[#This Row],[SalesBot]] -> 0 | AR16: =Table4[[#This Row],[Liter]] -> 0
A17: =YEAR(C17) -> 2026 | B17: =MONTH(C17) -> 1 | C17: 46023 | D17: =TODAY() -> 46097 | E17: =DATEDIF(C17,D17,"M")&"-Months" -> 2-Months | F17: =VLOOKUP(N17,Stock[#Data],5,FALSE) -> BE | I17: Kyaw Star | J17: =VLOOKUP(I17,Customers[#Data],2,FALSE) -> ကျော်စတား | K17: =VLOOKUP(I17,Customers[#Data],4,FALSE) -> Yay | L17: =VLOOKUP(I17,Customers[#Data],5,FALSE) -> WholeSales | M17: ကုန်ရောင်း(အကြွေး) | N17: BE Debtors Opening | O17: =VLOOKUP(N17,Stock[#Data],2,FALSE) -> BE | P17: =VLOOKUP(N17,Stock[#Data],3,FALSE) -> 0 | Q17: =VLOOKUP(N17,Stock[#Data],4,FALSE) -> 0 | S17: =IFERROR(Table4[[#This Row],[Bottle]]/Table4[[#This Row],[ပါဝင်မှု]]+Table4[[#This Row],[SalesPK]],0) -> 0 | U17: =Table4[[#This Row],[ပါဝင်မှု]]*Table4[[#This Row],[SalesPK]]+Table4[[#This Row],[Bottle]] -> 0 | V17: =Table4[[#This Row],[SalesBot]]*Table4[[#This Row],[ML]] -> 0 | W17: =VLOOKUP(N17,Stock[#Data],6,FALSE) -> 0 | X17: =+Table4[[#This Row],[SalesBot]]*Table4[[#This Row],[နှုံး]] -> 0 | Y17: 3564000 | AB17: 46034 | AC17: 3564000 | AF17: =Table4[[#This Row],[စာရင်းဖွင့်]]+Table4[[#This Row],[သင့်ငွေ]]-Table4[[#This Row],[ဈေးဟောင်းလျှော့]]-Table4[[#This Row],[‌ကော်မရှင်]]-Table4[[#This Row],[ကြွေးရငွေ]]-Table4[[#This Row],[ကြွေးရငွေ2]] -> 0 | AH17: =Table4[[#This Row],[Date]] -> 46023 | AI17: =TEXT(AH17,"mmm") -> Jan | AJ17: =TEXT(AH17,"yyyy") -> 2026 | AK17: =Table4[[#This Row],[ကုန်သည်အမည်]] -> ကျော်စတား | AL17: =Table4[[#This Row],[Township]] -> Yay | AM17: =Table4[[#This Row],[WholeSales]] -> WholeSales | AN17: =Table4[[#This Row],[Particular]] -> ကုန်ရောင်း(အကြွေး) | AO17: =Table4[[#This Row],[StockName]] -> BE | AP17: =Table4[[#This Row],[Parking]] -> 0 | AQ17: =Table4[[#This Row],[SalesBot]] -> 0 | AR17: =Table4[[#This Row],[Liter]] -> 0
A18: =YEAR(C18) -> 2026 | B18: =MONTH(C18) -> 1 | C18: 46023 | D18: =TODAY() -> 46097 | E18: =DATEDIF(C18,D18,"M")&"-Months" -> 2-Months | F18: =VLOOKUP(N18,Stock[#Data],5,FALSE) -> BE | I18: Kyaw Star | J18: =VLOOKUP(I18,Customers[#Data],2,FALSE) -> ကျော်စတား | K18: =VLOOKUP(I18,Customers[#Data],4,FALSE) -> Yay | L18: =VLOOKUP(I18,Customers[#Data],5,FALSE) -> WholeSales | M18: ကုန်ရောင်း(အကြွေး) | N18: BE Debtors Opening | O18: =VLOOKUP(N18,Stock[#Data],2,FALSE) -> BE | P18: =VLOOKUP(N18,Stock[#Data],3,FALSE) -> 0 | Q18: =VLOOKUP(N18,Stock[#Data],4,FALSE) -> 0 | S18: =IFERROR(Table4[[#This Row],[Bottle]]/Table4[[#This Row],[ပါဝင်မှု]]+Table4[[#This Row],[SalesPK]],0) -> 0 | U18: =Table4[[#This Row],[ပါဝင်မှု]]*Table4[[#This Row],[SalesPK]]+Table4[[#This Row],[Bottle]] -> 0 | V18: =Table4[[#This Row],[SalesBot]]*Table4[[#This Row],[ML]] -> 0 | W18: =VLOOKUP(N18,Stock[#Data],6,FALSE) -> 0 | X18: =+Table4[[#This Row],[SalesBot]]*Table4[[#This Row],[နှုံး]] -> 0 | Y18: 1890000 | AB18: 46035 | AC18: 1890000 | AF18: =Table4[[#This Row],[စာရင်းဖွင့်]]+Table4[[#This Row],[သင့်ငွေ]]-Table4[[#This Row],[ဈေးဟောင်းလျှော့]]-Table4[[#This Row],[‌ကော်မရှင်]]-Table4[[#This Row],[ကြွေးရငွေ]]-Table4[[#This Row],[ကြွေးရငွေ2]] -> 0 | AH18: =Table4[[#This Row],[Date]] -> 46023 | AI18: =TEXT(AH18,"mmm") -> Jan | AJ18: =TEXT(AH18,"yyyy") -> 2026 | AK18: =Table4[[#This Row],[ကုန်သည်အမည်]] -> ကျော်စတား | AL18: =Table4[[#This Row],[Township]] -> Yay | AM18: =Table4[[#This Row],[WholeSales]] -> WholeSales | AN18: =Table4[[#This Row],[Particular]] -> ကုန်ရောင်း(အကြွေး) | AO18: =Table4[[#This Row],[StockName]] -> BE | AP18: =Table4[[#This Row],[Parking]] -> 0 | AQ18: =Table4[[#This Row],[SalesBot]] -> 0 | AR18: =Table4[[#This Row],[Liter]] -> 0
A19: =YEAR(C19) -> 2026 | B19: =MONTH(C19) -> 1 | C19: 46023 | D19: =TODAY() -> 46097 | E19: =DATEDIF(C19,D19,"M")&"-Months" -> 2-Months | F19: =VLOOKUP(N19,Stock[#Data],5,FALSE) -> BE | I19: Kyaw Star | J19: =VLOOKUP(I19,Customers[#Data],2,FALSE) -> ကျော်စတား | K19: =VLOOKUP(I19,Customers[#Data],4,FALSE) -> Yay | L19: =VLOOKUP(I19,Customers[#Data],5,FALSE) -> WholeSales | M19: ကုန်ရောင်း(အကြွေး) | N19: BE Debtors Opening | O19: =VLOOKUP(N19,Stock[#Data],2,FALSE) -> BE | P19: =VLOOKUP(N19,Stock[#Data],3,FALSE) -> 0 | Q19: =VLOOKUP(N19,Stock[#Data],4,FALSE) -> 0 | S19: =IFERROR(Table4[[#This Row],[Bottle]]/Table4[[#This Row],[ပါဝင်မှု]]+Table4[[#This Row],[SalesPK]],0) -> 0 | U19: =Table4[[#This Row],[ပါဝင်မှု]]*Table4[[#This Row],[SalesPK]]+Table4[[#This Row],[Bottle]] -> 0 | V19: =Table4[[#This Row],[SalesBot]]*Table4[[#This Row],[ML]] -> 0 | W19: =VLOOKUP(N19,Stock[#Data],6,FALSE) -> 0 | X19: =+Table4[[#This Row],[SalesBot]]*Table4[[#This Row],[နှုံး]] -> 0 | Y19: 4806000 | AB19: 46035 | AC19: 4806000 | AF19: =Table4[[#This Row],[စာရင်းဖွင့်]]+Table4[[#This Row],[သင့်ငွေ]]-Table4[[#This Row],[ဈေးဟောင်းလျှော့]]-Table4[[#This Row],[‌ကော်မရှင်]]-Table4[[#This Row],[ကြွေးရငွေ]]-Table4[[#This Row],[ကြွေးရငွေ2]] -> 0 | AH19: =Table4[[#This Row],[Date]] -> 46023 | AI19: =TEXT(AH19,"mmm") -> Jan | AJ19: =TEXT(AH19,"yyyy") -> 2026 | AK19: =Table4[[#This Row],[ကုန်သည်အမည်]] -> ကျော်စတား | AL19: =Table4[[#This Row],[Township]] -> Yay | AM19: =Table4[[#This Row],[WholeSales]] -> WholeSales | AN19: =Table4[[#This Row],[Particular]] -> ကုန်ရောင်း(အကြွေး) | AO19: =Table4[[#This Row],[StockName]] -> BE | AP19: =Table4[[#This Row],[Parking]] -> 0 | AQ19: =Table4[[#This Row],[SalesBot]] -> 0 | AR19: =Table4[[#This Row],[Liter]] -> 0
A20: =YEAR(C20) -> 2026 | B20: =MONTH(C20) -> 1 | C20: 46023 | D20: =TODAY() -> 46097 | E20: =DATEDIF(C20,D20,"M")&"-Months" -> 2-Months | F20: =VLOOKUP(N20,Stock[#Data],5,FALSE) -> BE | I20: Ko Htike Soe | J20: =VLOOKUP(I20,Customers[#Data],2,FALSE) -> ကိုထိုက်စိုး | K20: =VLOOKUP(I20,Customers[#Data],4,FALSE) -> Yay | L20: =VLOOKUP(I20,Customers[#Data],5,FALSE) -> WholeSales | M20: ကုန်ရောင်း(အကြွေး) | N20: BE Debtors Opening | O20: =VLOOKUP(N20,Stock[#Data],2,FALSE) -> BE | P20: =VLOOKUP(N20,Stock[#Data],3,FALSE) -> 0 | Q20: =VLOOKUP(N20,Stock[#Data],4,FALSE) -> 0 | S20: =IFERROR(Table4[[#This Row],[Bottle]]/Table4[[#This Row],[ပါဝင်မှု]]+Table4[[#This Row],[SalesPK]],0) -> 0 | U20: =Table4[[#This Row],[ပါဝင်မှု]]*Table4[[#This Row],[SalesPK]]+Table4[[#This Row],[Bottle]] -> 0 | V20: =Table4[[#This Row],[SalesBot]]*Table4[[#This Row],[ML]] -> 0 | W20: =VLOOKUP(N20,Stock[#Data],6,FALSE) -> 0 | X20: =+Table4[[#This Row],[SalesBot]]*Table4[[#This Row],[နှုံး]] -> 0 | Y20: 9936000 | AF20: =Table4[[#This Row],[စာရင်းဖွင့်]]+Table4[[#This Row],[သင့်ငွေ]]-Table4[[#This Row],[ဈေးဟောင်းလျှော့]]-Table4[[#This Row],[‌ကော်မရှင်]]-Table4[[#This Row],[ကြွေးရငွေ]]-Table4[[#This Row],[ကြွေးရငွေ2]] -> 9936000 | AH20: =Table4[[#This Row],[Date]] -> 46023 | AI20: =TEXT(AH20,"mmm") -> Jan | AJ20: =TEXT(AH20,"yyyy") -> 2026 | AK20: =Table4[[#This Row],[ကုန်သည်အမည်]] -> ကိုထိုက်စိုး | AL20: =Table4[[#This Row],[Township]] -> Yay | AM20: =Table4[[#This Row],[WholeSales]] -> WholeSales | AN20: =Table4[[#This Row],[Particular]] -> ကုန်ရောင်း(အကြွေး) | AO20: =Table4[[#This Row],[StockName]] -> BE | AP20: =Table4[[#This Row],[Parking]] -> 0 | AQ20: =Table4[[#This Row],[SalesBot]] -> 0 | AR20: =Table4[[#This Row],[Liter]] -> 0
A21: =YEAR(C21) -> 2026 | B21: =MONTH(C21) -> 1 | C21: 46023 | D21: =TODAY() -> 46097 | E21: =DATEDIF(C21,D21,"M")&"-Months" -> 2-Months | F21: =VLOOKUP(N21,Stock[#Data],5,FALSE) -> BE | I21: Ko Mg+Ma Thu Zar | J21: =VLOOKUP(I21,Customers[#Data],2,FALSE) -> ကိုမောင်+မသူဇာ | K21: =VLOOKUP(I21,Customers[#Data],4,FALSE) -> Yay | L21: =VLOOKUP(I21,Customers[#Data],5,FALSE) -> WholeSales | M21: ကုန်ရောင်း(အကြွေး) | N21: BE Debtors Opening | O21: =VLOOKUP(N21,Stock[#Data],2,FALSE) -> BE | P21: =VLOOKUP(N21,Stock[#Data],3,FALSE) -> 0 | Q21: =VLOOKUP(N21,Stock[#Data],4,FALSE) -> 0 | S21: =IFERROR(Table4[[#This Row],[Bottle]]/Table4[[#This Row],[ပါဝင်မှု]]+Table4[[#This Row],[SalesPK]],0) -> 0 | U21: =Table4[[#This Row],[ပါဝင်မှု]]*Table4[[#This Row],[SalesPK]]+Table4[[#This Row],[Bottle]] -> 0 | V21: =Table4[[#This Row],[SalesBot]]*Table4[[#This Row],[ML]] -> 0 | W21: =VLOOKUP(N21,Stock[#Data],6,FALSE) -> 0 | X21: =+Table4[[#This Row],[SalesBot]]*Table4[[#This Row],[နှုံး]] -> 0 | Y21: 2052000 | AB21: 46034 | AC21: 2052000 | AF21: =Table4[[#This Row],[စာရင်းဖွင့်]]+Table4[[#This Row],[သင့်ငွေ]]-Table4[[#This Row],[ဈေးဟောင်းလျှော့]]-Table4[[#This Row],[‌ကော်မရှင်]]-Table4[[#This Row],[ကြွေးရငွေ]]-Table4[[#This Row],[ကြွေးရငွေ2]] -> 0 | AH21: =Table4[[#This Row],[Date]] -> 46023 | AI21: =TEXT(AH21,"mmm") -> Jan | AJ21: =TEXT(AH21,"yyyy") -> 2026 | AK21: =Table4[[#This Row],[ကုန်သည်အမည်]] -> ကိုမောင်+မသူဇာ | AL21: =Table4[[#This Row],[Township]] -> Yay | AM21: =Table4[[#This Row],[WholeSales]] -> WholeSales | AN21: =Table4[[#This Row],[Particular]] -> ကုန်ရောင်း(အကြွေး) | AO21: =Table4[[#This Row],[StockName]] -> BE | AP21: =Table4[[#This Row],[Parking]] -> 0 | AQ21: =Table4[[#This Row],[SalesBot]] -> 0 | AR21: =Table4[[#This Row],[Liter]] -> 0
A22: =YEAR(C22) -> 2026 | B22: =MONTH(C22) -> 1 | C22: 46023 | D22: =TODAY() -> 46097 | E22: =DATEDIF(C22,D22,"M")&"-Months" -> 2-Months | F22: =VLOOKUP(N22,Stock[#Data],5,FALSE) -> BE | I22: Ko Mg+Ma Thu Zar | J22: =VLOOKUP(I22,Customers[#Data],2,FALSE) -> ကိုမောင်+မသူဇာ | K22: =VLOOKUP(I22,Customers[#Data],4,FALSE) -> Yay | L22: =VLOOKUP(I22,Customers[#Data],5,FALSE) -> WholeSales | M22: ကုန်ရောင်း(အကြွေး) | N22: BE Debtors Opening | O22: =VLOOKUP(N22,Stock[#Data],2,FALSE) -> BE | P22: =VLOOKUP(N22,Stock[#Data],3,FALSE) -> 0 | Q22: =VLOOKUP(N22,Stock[#Data],4,FALSE) -> 0 | S22: =IFERROR(Table4[[#This Row],[Bottle]]/Table4[[#This Row],[ပါဝင်မှု]]+Table4[[#This Row],[SalesPK]],0) -> 0 | U22: =Table4[[#This Row],[ပါဝင်မှု]]*Table4[[#This Row],[SalesPK]]+Table4[[#This Row],[Bottle]] -> 0 | V22: =Table4[[#This Row],[SalesBot]]*Table4[[#This Row],[ML]] -> 0 | W22: =VLOOKUP(N22,Stock[#Data],6,FALSE) -> 0 | X22: =+Table4[[#This Row],[SalesBot]]*Table4[[#This Row],[နှုံး]] -> 0 | Y22: 2052000 | AB22: 46034 | AC22: 2052000 | AF22: =Table4[[#This Row],[စာရင်းဖွင့်]]+Table4[[#This Row],[သင့်ငွေ]]-Table4[[#This Row],[ဈေးဟောင်းလျှော့]]-Table4[[#This Row],[‌ကော်မရှင်]]-Table4[[#This Row],[ကြွေးရငွေ]]-Table4[[#This Row],[ကြွေးရငွေ2]] -> 0 | AH22: =Table4[[#This Row],[Date]] -> 46023 | AI22: =TEXT(AH22,"mmm") -> Jan | AJ22: =TEXT(AH22,"yyyy") -> 2026 | AK22: =Table4[[#This Row],[ကုန်သည်အမည်]] -> ကိုမောင်+မသူဇာ | AL22: =Table4[[#This Row],[Township]] -> Yay | AM22: =Table4[[#This Row],[WholeSales]] -> WholeSales | AN22: =Table4[[#This Row],[Particular]] -> ကုန်ရောင်း(အကြွေး) | AO22: =Table4[[#This Row],[StockName]] -> BE | AP22: =Table4[[#This Row],[Parking]] -> 0 | AQ22: =Table4[[#This Row],[SalesBot]] -> 0 | AR22: =Table4[[#This Row],[Liter]] -> 0
A23: =YEAR(C23) -> 2026 | B23: =MONTH(C23) -> 1 | C23: 46023 | D23: =TODAY() -> 46097 | E23: =DATEDIF(C23,D23,"M")&"-Months" -> 2-Months | F23: =VLOOKUP(N23,Stock[#Data],5,FALSE) -> BE | I23: Ko Mg+Ma Thu Zar | J23: =VLOOKUP(I23,Customers[#Data],2,FALSE) -> ကိုမောင်+မသူဇာ | K23: =VLOOKUP(I23,Customers[#Data],4,FALSE) -> Yay | L23: =VLOOKUP(I23,Customers[#Data],5,FALSE) -> WholeSales | M23: ကုန်ရောင်း(အကြွေး) | N23: BE Debtors Opening | O23: =VLOOKUP(N23,Stock[#Data],2,FALSE) -> BE | P23: =VLOOKUP(N23,Stock[#Data],3,FALSE) -> 0 | Q23: =VLOOKUP(N23,Stock[#Data],4,FALSE) -> 0 | S23: =IFERROR(Table4[[#This Row],[Bottle]]/Table4[[#This Row],[ပါဝင်မှု]]+Table4[[#This Row],[SalesPK]],0) -> 0 | U23: =Table4[[#This Row],[ပါဝင်မှု]]*Table4[[#This Row],[SalesPK]]+Table4[[#This Row],[Bottle]] -> 0 | V23: =Table4[[#This Row],[SalesBot]]*Table4[[#This Row],[ML]] -> 0 | W23: =VLOOKUP(N23,Stock[#Data],6,FALSE) -> 0 | X23: =+Table4[[#This Row],[SalesBot]]*Table4[[#This Row],[နှုံး]] -> 0 | Y23: 1026000 | AB23: 46024 | AC23: 1026000 | AF23: =Table4[[#This Row],[စာရင်းဖွင့်]]+Table4[[#This Row],[သင့်ငွေ]]-Table4[[#This Row],[ဈေးဟောင်းလျှော့]]-Table4[[#This Row],[‌ကော်မရှင်]]-Table4[[#This Row],[ကြွေးရငွေ]]-Table4[[#This Row],[ကြွေးရငွေ2]] -> 0 | AH23: =Table4[[#This Row],[Date]] -> 46023 | AI23: =TEXT(AH23,"mmm") -> Jan | AJ23: =TEXT(AH23,"yyyy") -> 2026 | AK23: =Table4[[#This Row],[ကုန်သည်အမည်]] -> ကိုမောင်+မသူဇာ | AL23: =Table4[[#This Row],[Township]] -> Yay | AM23: =Table4[[#This Row],[WholeSales]] -> WholeSales | AN23: =Table4[[#This Row],[Particular]] -> ကုန်ရောင်း(အကြွေး) | AO23: =Table4[[#This Row],[StockName]] -> BE | AP23: =Table4[[#This Row],[Parking]] -> 0 | AQ23: =Table4[[#This Row],[SalesBot]] -> 0 | AR23: =Table4[[#This Row],[Liter]] -> 0
A24: =YEAR(C24) -> 2026 | B24: =MONTH(C24) -> 1 | C24: 46023 | D24: =TODAY() -> 46097 | E24: =DATEDIF(C24,D24,"M")&"-Months" -> 2-Months | F24: =VLOOKUP(N24,Stock[#Data],5,FALSE) -> BE | I24: Ko Mg+Ma Thu Zar | J24: =VLOOKUP(I24,Customers[#Data],2,FALSE) -> ကိုမောင်+မသူဇာ | K24: =VLOOKUP(I24,Customers[#Data],4,FALSE) -> Yay | L24: =VLOOKUP(I24,Customers[#Data],5,FALSE) -> WholeSales | M24: ကုန်ရောင်း(အကြွေး) | N24: BE Debtors Opening | O24: =VLOOKUP(N24,Stock[#Data],2,FALSE) -> BE | P24: =VLOOKUP(N24,Stock[#Data],3,FALSE) -> 0 | Q24: =VLOOKUP(N24,Stock[#Data],4,FALSE) -> 0 | S24: =IFERROR(Table4[[#This Row],[Bottle]]/Table4[[#This Row],[ပါဝင်မှု]]+Table4[[#This Row],[SalesPK]],0) -> 0 | U24: =Table4[[#This Row],[ပါဝင်မှု]]*Table4[[#This Row],[SalesPK]]+Table4[[#This Row],[Bottle]] -> 0 | V24: =Table4[[#This Row],[SalesBot]]*Table4[[#This Row],[ML]] -> 0 | W24: =VLOOKUP(N24,Stock[#Data],6,FALSE) -> 0 | X24: =+Table4[[#This Row],[SalesBot]]*Table4[[#This Row],[နှုံး]] -> 0 | Y24: 615600 | AB24: 46024 | AC24: 615600 | AF24: =Table4[[#This Row],[စာရင်းဖွင့်]]+Table4[[#This Row],[သင့်ငွေ]]-Table4[[#This Row],[ဈေးဟောင်းလျှော့]]-Table4[[#This Row],[‌ကော်မရှင်]]-Table4[[#This Row],[ကြွေးရငွေ]]-Table4[[#This Row],[ကြွေးရငွေ2]] -> 0 | AH24: =Table4[[#This Row],[Date]] -> 46023 | AI24: =TEXT(AH24,"mmm") -> Jan | AJ24: =TEXT(AH24,"yyyy") -> 2026 | AK24: =Table4[[#This Row],[ကုန်သည်အမည်]] -> ကိုမောင်+မသူဇာ | AL24: =Table4[[#This Row],[Township]] -> Yay | AM24: =Table4[[#This Row],[WholeSales]] -> WholeSales | AN24: =Table4[[#This Row],[Particular]] -> ကုန်ရောင်း(အကြွေး) | AO24: =Table4[[#This Row],[StockName]] -> BE | AP24: =Table4[[#This Row],[Parking]] -> 0 | AQ24: =Table4[[#This Row],[SalesBot]] -> 0 | AR24: =Table4[[#This Row],[Liter]] -> 0
A25: =YEAR(C25) -> 2026 | B25: =MONTH(C25) -> 1 | C25: 46023 | D25: =TODAY() -> 46097 | E25: =DATEDIF(C25,D25,"M")&"-Months" -> 2-Months | F25: =VLOOKUP(N25,Stock[#Data],5,FALSE) -> BE | I25: Ko Mg+Ma Thu Zar | J25: =VLOOKUP(I25,Customers[#Data],2,FALSE) -> ကိုမောင်+မသူဇာ | K25: =VLOOKUP(I25,Customers[#Data],4,FALSE) -> Yay | L25: =VLOOKUP(I25,Customers[#Data],5,FALSE) -> WholeSales | M25: ကုန်ရောင်း(အကြွေး) | N25: BE Debtors Opening | O25: =VLOOKUP(N25,Stock[#Data],2,FALSE) -> BE | P25: =VLOOKUP(N25,Stock[#Data],3,FALSE) -> 0 | Q25: =VLOOKUP(N25,Stock[#Data],4,FALSE) -> 0 | S25: =IFERROR(Table4[[#This Row],[Bottle]]/Table4[[#This Row],[ပါဝင်မှု]]+Table4[[#This Row],[SalesPK]],0) -> 0 | U25: =Table4[[#This Row],[ပါဝင်မှု]]*Table4[[#This Row],[SalesPK]]+Table4[[#This Row],[Bottle]] -> 0 | V25: =Table4[[#This Row],[SalesBot]]*Table4[[#This Row],[ML]] -> 0 | W25: =VLOOKUP(N25,Stock[#Data],6,FALSE) -> 0 | X25: =+Table4[[#This Row],[SalesBot]]*Table4[[#This Row],[နှုံး]] -> 0 | Y25: 410400 | AB25: 46024 | AC25: 410400 | AF25: =Table4[[#This Row],[စာရင်းဖွင့်]]+Table4[[#This Row],[သင့်ငွေ]]-Table4[[#This Row],[ဈေးဟောင်းလျှော့]]-Table4[[#This Row],[‌ကော်မရှင်]]-Table4[[#This Row],[ကြွေးရငွေ]]-Table4[[#This Row],[ကြွေးရငွေ2]] -> 0 | AH25: =Table4[[#This Row],[Date]] -> 46023 | AI25: =TEXT(AH25,"mmm") -> Jan | AJ25: =TEXT(AH25,"yyyy") -> 2026 | AK25: =Table4[[#This Row],[ကုန်သည်အမည်]] -> ကိုမောင်+မသူဇာ | AL25: =Table4[[#This Row],[Township]] -> Yay | AM25: =Table4[[#This Row],[WholeSales]] -> WholeSales | AN25: =Table4[[#This Row],[Particular]] -> ကုန်ရောင်း(အကြွေး) | AO25: =Table4[[#This Row],[StockName]] -> BE | AP25: =Table4[[#This Row],[Parking]] -> 0 | AQ25: =Table4[[#This Row],[SalesBot]] -> 0 | AR25: =Table4[[#This Row],[Liter]] -> 0
A26: =YEAR(C26) -> 2026 | B26: =MONTH(C26) -> 1 | C26: 46023 | D26: =TODAY() -> 46097 | E26: =DATEDIF(C26,D26,"M")&"-Months" -> 2-Months | F26: =VLOOKUP(N26,Stock[#Data],5,FALSE) -> BE | I26: Ko Mg+Ma Thu Zar | J26: =VLOOKUP(I26,Customers[#Data],2,FALSE) -> ကိုမောင်+မသူဇာ | K26: =VLOOKUP(I26,Customers[#Data],4,FALSE) -> Yay | L26: =VLOOKUP(I26,Customers[#Data],5,FALSE) -> WholeSales | M26: ကုန်ရောင်း(အကြွေး) | N26: BE Debtors Opening | O26: =VLOOKUP(N26,Stock[#Data],2,FALSE) -> BE | P26: =VLOOKUP(N26,Stock[#Data],3,FALSE) -> 0 | Q26: =VLOOKUP(N26,Stock[#Data],4,FALSE) -> 0 | S26: =IFERROR(Table4[[#This Row],[Bottle]]/Table4[[#This Row],[ပါဝင်မှု]]+Table4[[#This Row],[SalesPK]],0) -> 0 | U26: =Table4[[#This Row],[ပါဝင်မှု]]*Table4[[#This Row],[SalesPK]]+Table4[[#This Row],[Bottle]] -> 0 | V26: =Table4[[#This Row],[SalesBot]]*Table4[[#This Row],[ML]] -> 0 | W26: =VLOOKUP(N26,Stock[#Data],6,FALSE) -> 0 | X26: =+Table4[[#This Row],[SalesBot]]*Table4[[#This Row],[နှုံး]] -> 0 | Y26: 1026000 | AB26: 46041 | AC26: 1026000 | AF26: =Table4[[#This Row],[စာရင်းဖွင့်]]+Table4[[#This Row],[သင့်ငွေ]]-Table4[[#This Row],[ဈေးဟောင်းလျှော့]]-Table4[[#This Row],[‌ကော်မရှင်]]-Table4[[#This Row],[ကြွေးရငွေ]]-Table4[[#This Row],[ကြွေးရငွေ2]] -> 0 | AH26: =Table4[[#This Row],[Date]] -> 46023 | AI26: =TEXT(AH26,"mmm") -> Jan | AJ26: =TEXT(AH26,"yyyy") -> 2026 | AK26: =Table4[[#This Row],[ကုန်သည်အမည်]] -> ကိုမောင်+မသူဇာ | AL26: =Table4[[#This Row],[Township]] -> Yay | AM26: =Table4[[#This Row],[WholeSales]] -> WholeSales | AN26: =Table4[[#This Row],[Particular]] -> ကုန်ရောင်း(အကြွေး) | AO26: =Table4[[#This Row],[StockName]] -> BE | AP26: =Table4[[#This Row],[Parking]] -> 0 | AQ26: =Table4[[#This Row],[SalesBot]] -> 0 | AR26: =Table4[[#This Row],[Liter]] -> 0
A27: =YEAR(C27) -> 2026 | B27: =MONTH(C27) -> 1 | C27: 46023 | D27: =TODAY() -> 46097 | E27: =DATEDIF(C27,D27,"M")&"-Months" -> 2-Months | F27: =VLOOKUP(N27,Stock[#Data],5,FALSE) -> BE | I27: Ko Mg+Ma Thu Zar | J27: =VLOOKUP(I27,Customers[#Data],2,FALSE) -> ကိုမောင်+မသူဇာ | K27: =VLOOKUP(I27,Customers[#Data],4,FALSE) -> Yay | L27: =VLOOKUP(I27,Customers[#Data],5,FALSE) -> WholeSales | M27: ကုန်ရောင်း(အကြွေး) | N27: BE Debtors Opening | O27: =VLOOKUP(N27,Stock[#Data],2,FALSE) -> BE | P27: =VLOOKUP(N27,Stock[#Data],3,FALSE) -> 0 | Q27: =VLOOKUP(N27,Stock[#Data],4,FALSE) -> 0 | S27: =IFERROR(Table4[[#This Row],[Bottle]]/Table4[[#This Row],[ပါဝင်မှု]]+Table4[[#This Row],[SalesPK]],0) -> 0 | U27: =Table4[[#This Row],[ပါဝင်မှု]]*Table4[[#This Row],[SalesPK]]+Table4[[#This Row],[Bottle]] -> 0 | V27: =Table4[[#This Row],[SalesBot]]*Table4[[#This Row],[ML]] -> 0 | W27: =VLOOKUP(N27,Stock[#Data],6,FALSE) -> 0 | X27: =+Table4[[#This Row],[SalesBot]]*Table4[[#This Row],[နှုံး]] -> 0 | Y27: 1026000 | AB27: 46041 | AC27: 1026000 | AF27: =Table4[[#This Row],[စာရင်းဖွင့်]]+Table4[[#This Row],[သင့်ငွေ]]-Table4[[#This Row],[ဈေးဟောင်းလျှော့]]-Table4[[#This Row],[‌ကော်မရှင်]]-Table4[[#This Row],[ကြွေးရငွေ]]-Table4[[#This Row],[ကြွေးရငွေ2]] -> 0 | AH27: =Table4[[#This Row],[Date]] -> 46023 | AI27: =TEXT(AH27,"mmm") -> Jan | AJ27: =TEXT(AH27,"yyyy") -> 2026 | AK27: =Table4[[#This Row],[ကုန်သည်အမည်]] -> ကိုမောင်+မသူဇာ | AL27: =Table4[[#This Row],[Township]] -> Yay | AM27: =Table4[[#This Row],[WholeSales]] -> WholeSales | AN27: =Table4[[#This Row],[Particular]] -> ကုန်ရောင်း(အကြွေး) | AO27: =Table4[[#This Row],[StockName]] -> BE | AP27: =Table4[[#This Row],[Parking]] -> 0 | AQ27: =Table4[[#This Row],[SalesBot]] -> 0 | AR27: =Table4[[#This Row],[Liter]] -> 0
A28: =YEAR(C28) -> 2026 | B28: =MONTH(C28) -> 1 | C28: 46023 | D28: =TODAY() -> 46097 | E28: =DATEDIF(C28,D28,"M")&"-Months" -> 2-Months | F28: =VLOOKUP(N28,Stock[#Data],5,FALSE) -> BE | I28: Ko Mg+Ma Thu Zar | J28: =VLOOKUP(I28,Customers[#Data],2,FALSE) -> ကိုမောင်+မသူဇာ | K28: =VLOOKUP(I28,Customers[#Data],4,FALSE) -> Yay | L28: =VLOOKUP(I28,Customers[#Data],5,FALSE) -> WholeSales | M28: ကုန်ရောင်း(အကြွေး) | N28: BE Debtors Opening | O28: =VLOOKUP(N28,Stock[#Data],2,FALSE) -> BE | P28: =VLOOKUP(N28,Stock[#Data],3,FALSE) -> 0 | Q28: =VLOOKUP(N28,Stock[#Data],4,FALSE) -> 0 | S28: =IFERROR(Table4[[#This Row],[Bottle]]/Table4[[#This Row],[ပါဝင်မှု]]+Table4[[#This Row],[SalesPK]],0) -> 0 | U28: =Table4[[#This Row],[ပါဝင်မှု]]*Table4[[#This Row],[SalesPK]]+Table4[[#This Row],[Bottle]] -> 0 | V28: =Table4[[#This Row],[SalesBot]]*Table4[[#This Row],[ML]] -> 0 | W28: =VLOOKUP(N28,Stock[#Data],6,FALSE) -> 0 | X28: =+Table4[[#This Row],[SalesBot]]*Table4[[#This Row],[နှုံး]] -> 0 | Y28: 4104000 | AB28: 46041 | AC28: 4104000 | AF28: =Table4[[#This Row],[စာရင်းဖွင့်]]+Table4[[#This Row],[သင့်ငွေ]]-Table4[[#This Row],[ဈေးဟောင်းလျှော့]]-Table4[[#This Row],[‌ကော်မရှင်]]-Table4[[#This Row],[ကြွေးရငွေ]]-Table4[[#This Row],[ကြွေးရငွေ2]] -> 0 | AH28: =Table4[[#This Row],[Date]] -> 46023 | AI28: =TEXT(AH28,"mmm") -> Jan | AJ28: =TEXT(AH28,"yyyy") -> 2026 | AK28: =Table4[[#This Row],[ကုန်သည်အမည်]] -> ကိုမောင်+မသူဇာ | AL28: =Table4[[#This Row],[Township]] -> Yay | AM28: =Table4[[#This Row],[WholeSales]] -> WholeSales | AN28: =Table4[[#This Row],[Particular]] -> ကုန်ရောင်း(အကြွေး) | AO28: =Table4[[#This Row],[StockName]] -> BE | AP28: =Table4[[#This Row],[Parking]] -> 0 | AQ28: =Table4[[#This Row],[SalesBot]] -> 0 | AR28: =Table4[[#This Row],[Liter]] -> 0
A29: =YEAR(C29) -> 2026 | B29: =MONTH(C29) -> 1 | C29: 46023 | D29: =TODAY() -> 46097 | E29: =DATEDIF(C29,D29,"M")&"-Months" -> 2-Months | F29: =VLOOKUP(N29,Stock[#Data],5,FALSE) -> BE | I29: Ko Mg+Ma Thu Zar | J29: =VLOOKUP(I29,Customers[#Data],2,FALSE) -> ကိုမောင်+မသူဇာ | K29: =VLOOKUP(I29,Customers[#Data],4,FALSE) -> Yay | L29: =VLOOKUP(I29,Customers[#Data],5,FALSE) -> WholeSales | M29: ကုန်ရောင်း(အကြွေး) | N29: BE Debtors Opening | O29: =VLOOKUP(N29,Stock[#Data],2,FALSE) -> BE | P29: =VLOOKUP(N29,Stock[#Data],3,FALSE) -> 0 | Q29: =VLOOKUP(N29,Stock[#Data],4,FALSE) -> 0 | S29: =IFERROR(Table4[[#This Row],[Bottle]]/Table4[[#This Row],[ပါဝင်မှု]]+Table4[[#This Row],[SalesPK]],0) -> 0 | U29: =Table4[[#This Row],[ပါဝင်မှု]]*Table4[[#This Row],[SalesPK]]+Table4[[#This Row],[Bottle]] -> 0 | V29: =Table4[[#This Row],[SalesBot]]*Table4[[#This Row],[ML]] -> 0 | W29: =VLOOKUP(N29,Stock[#Data],6,FALSE) -> 0 | X29: =+Table4[[#This Row],[SalesBot]]*Table4[[#This Row],[နှုံး]] -> 0 | Y29: 1026000 | AB29: 46043 | AC29: 1026000 | AF29: =Table4[[#This Row],[စာရင်းဖွင့်]]+Table4[[#This Row],[သင့်ငွေ]]-Table4[[#This Row],[ဈေးဟောင်းလျှော့]]-Table4[[#This Row],[‌ကော်မရှင်]]-Table4[[#This Row],[ကြွေးရငွေ]]-Table4[[#This Row],[ကြွေးရငွေ2]] -> 0 | AH29: =Table4[[#This Row],[Date]] -> 46023 | AI29: =TEXT(AH29,"mmm") -> Jan | AJ29: =TEXT(AH29,"yyyy") -> 2026 | AK29: =Table4[[#This Row],[ကုန်သည်အမည်]] -> ကိုမောင်+မသူဇာ | AL29: =Table4[[#This Row],[Township]] -> Yay | AM29: =Table4[[#This Row],[WholeSales]] -> WholeSales | AN29: =Table4[[#This Row],[Particular]] -> ကုန်ရောင်း(အကြွေး) | AO29: =Table4[[#This Row],[StockName]] -> BE | AP29: =Table4[[#This Row],[Parking]] -> 0 | AQ29: =Table4[[#This Row],[SalesBot]] -> 0 | AR29: =Table4[[#This Row],[Liter]] -> 0
A30: =YEAR(C30) -> 2026 | B30: =MONTH(C30) -> 1 | C30: 46023 | D30: =TODAY() -> 46097 | E30: =DATEDIF(C30,D30,"M")&"-Months" -> 2-Months | F30: =VLOOKUP(N30,Stock[#Data],5,FALSE) -> BE | I30: Ko Mg+Ma Thu Zar | J30: =VLOOKUP(I30,Customers[#Data],2,FALSE) -> ကိုမောင်+မသူဇာ | K30: =VLOOKUP(I30,Customers[#Data],4,FALSE) -> Yay | L30: =VLOOKUP(I30,Customers[#Data],5,FALSE) -> WholeSales | M30: ကုန်ရောင်း(အကြွေး) | N30: BE Debtors Opening | O30: =VLOOKUP(N30,Stock[#Data],2,FALSE) -> BE | P30: =VLOOKUP(N30,Stock[#Data],3,FALSE) -> 0 | Q30: =VLOOKUP(N30,Stock[#Data],4,FALSE) -> 0 | S30: =IFERROR(Table4[[#This Row],[Bottle]]/Table4[[#This Row],[ပါဝင်မှု]]+Table4[[#This Row],[SalesPK]],0) -> 0 | U30: =Table4[[#This Row],[ပါဝင်မှု]]*Table4[[#This Row],[SalesPK]]+Table4[[#This Row],[Bottle]] -> 0 | V30: =Table4[[#This Row],[SalesBot]]*Table4[[#This Row],[ML]] -> 0 | W30: =VLOOKUP(N30,Stock[#Data],6,FALSE) -> 0 | X30: =+Table4[[#This Row],[SalesBot]]*Table4[[#This Row],[နှုံး]] -> 0 | Y30: 1026000 | AB30: 46043 | AC30: 1026000 | AF30: =Table4[[#This Row],[စာရင်းဖွင့်]]+Table4[[#This Row],[သင့်ငွေ]]-Table4[[#This Row],[ဈေးဟောင်းလျှော့]]-Table4[[#This Row],[‌ကော်မရှင်]]-Table4[[#This Row],[ကြွေးရငွေ]]-Table4[[#This Row],[ကြွေးရငွေ2]] -> 0 | AH30: =Table4[[#This Row],[Date]] -> 46023 | AI30: =TEXT(AH30,"mmm") -> Jan | AJ30: =TEXT(AH30,"yyyy") -> 2026 | AK30: =Table4[[#This Row],[ကုန်သည်အမည်]] -> ကိုမောင်+မသူဇာ | AL30: =Table4[[#This Row],[Township]] -> Yay | AM30: =Table4[[#This Row],[WholeSales]] -> WholeSales | AN30: =Table4[[#This Row],[Particular]] -> ကုန်ရောင်း(အကြွေး) | AO30: =Table4[[#This Row],[StockName]] -> BE | AP30: =Table4[[#This Row],[Parking]] -> 0 | AQ30: =Table4[[#This Row],[SalesBot]] -> 0 | AR30: =Table4[[#This Row],[Liter]] -> 0
