Workbook
Name a: #REF!
Name aa: #REF!
Name aaa: #REF!
Name aaaaa: #REF!
Name aaaaaaa: #REF!
Name asd: '[1]Market ( Mar) '!#REF!
Name atr: #REF!
Name b: #REF!
Name bb: #REF!
Name Beg_Bal: #REF!
Name Cash_Cr: #REF!
Name Cash_Dr: #REF!
Name cc: #REF!
Name ccc: #REF!
Name cft: #REF!
Name cr: #REF!
Name crs: #REF!
Name cvvvv: #REF!
Name cwer: #REF!
Name Data: #REF!
Name dd: #REF!
Name ddd: #REF!
Name dddd: #N/A
Name dr: #REF!
Name drs: #REF!
Name dsfas: #REF!
Name eeee: #REF!
Name End_Bal: #REF!
Name Extra_Pay: #REF!
Name fgf: #REF!
Name fgjhj: #REF!
Name fhh: MATCH(0.01,End_Bal,-1)+1
Name ftyu: #REF!
Name Full_Print: #REF!
Name fusales4: #REF!
Name gg: #REF!
Name gggggg: #REF!
Name Header_Row: ROW(#REF!)
Name hjj: #REF!
Name hjjj: #REF!
Name hjkjk: #REF!
Name hmjhj: #REF!
Name ii: #REF!
Name III: #REF!
Name Int: #REF!
Name Interest_Rate: #REF!
Name jbkjkl: #REF!
Name Journal_Cr: #REF!
Name Journal_Dr: #REF!
Name kdt: #REF!
Name khbgfc: Scheduled_Payment+Extra_Payment
Name kluyufuf: #REF!
Name Last_Row: IF(Values_Entered,Header_Row+Number_of_Payments,Header_Row)
Name Loan_Amount: #REF!
Name Loan_Start: #REF!
Name Loan_Years: #REF!
Name LSO: #REF!
Name lsoq: #REF!
Name lsoq1: #REF!
Name mms: #REF!

Sheet 7-MTL
A1: Meiktila Region ( Townwise Report ) (2024, 2025,2026) (BE Bottle & Liter)
A2: No | B2: TownShip | C2: Van | D2: 45292 | F2: 45323 | H2: 45352 | J2: 45383 | L2: 45413 | N2: 45444 | P2: 45474 | R2: 45505 | T2: 45536 | V2: 45566 | X2: 45597 | Z2: 45627 | AB2: 2024 Total | AD2: 2024 Average | AF2: 45658 | AH2: 45689 | AJ2: 45717 | AL2: 45748 | AN2: 45778 | AP2: 45809 | AR2: 45839 | AT2: 45870 | AV2: 45901 | AX2: 45931 | AZ2: 45962 | BB2: 45992 | BD2: Total | BF2: Average | BH2: Town wise Contribution | BI2: Contirbution wise Priority Town | BJ2: 46023 | BL2: 46054 | BN2: 46082 | BP2: 46113 | BR2: 46143 | BT2: 46174 | BV2: 46204 | BX2: 46235 | BZ2: 46266 | CB2: 46296 | CD2: 46327 | CF2: 46357 | CH2: Total | CJ2: Average | CL2: Town wise Contribution | CM2: Contirbution wise Priority Town
D3: Bottle | E3: Liter | F3: Bottle | G3: Liter | H3: Bottle | I3: Liter | J3: Bottle | K3: Liter | L3: Bottle | M3: Liter | N3: Bottle | O3: Liter | P3: Bottle | Q3: Liter | R3: Bottle | S3: Liter | T3: Bottle | U3: Liter | V3: Bottle | W3: Liter | X3: Bottle | Y3: Liter | Z3: Bottle | AA3: Liter | AB3: Bottle | AC3: Liter | AD3: Bottle | AE3: Litre | AF3: Bottle | AG3: Litre | AH3: Bottle | AI3: Litre | AJ3: Bottle | AK3: Litre | AL3: Bottle | AM3: Litre | AN3: Bottle | AO3: Litre | AP3: Bottle | AQ3: Litre | AR3: Bottle | AS3: Litre | AT3: Bottle | AU3: Litre | AV3: Bottle | AW3: Litre | AX3: Bottle | AY3: Litre | AZ3: Bottle | BA3: Litre | BB3: Bottle | BC3: Litre | BD3: Bottle | BE3: Liter | BF3: Bottle | BG3: Liter | BJ3: Bottle | BK3: Litre | BL3: Bottle | BM3: Litre | BN3: Bottle | BO3: Litre | BP3: Bottle | BQ3: Litre | BR3: Bottle | BS3: Litre | BT3: Bottle | BU3: Litre | BV3: Bottle | BW3: Litre | BX3: Bottle | BY3: Litre | BZ3: Bottle | CA3: Litre | CB3: Bottle | CC3: Litre | CD3: Bottle | CE3: Litre | CF3: Bottle | CG3: Litre | CH3: Bottle | CI3: Liter | CJ3: Bottle | CK3: Liter
A4: 1 | B4: Meiktila | D4: =Meiktila!F147 | E4: =Meiktila!G147 | F4: =Meiktila!I147 | G4: =Meiktila!J147 | H4: =Meiktila!L147 | I4: =Meiktila!M147 | J4: =Meiktila!O147 | K4: =Meiktila!P147 | L4: =Meiktila!R147 | M4: =Meiktila!S147 | N4: =Meiktila!U147 | O4: =Meiktila!V147 | P4: =Meiktila!X147 | Q4: =Meiktila!Y147 | R4: =Meiktila!AA147 | S4: =Meiktila!AB147 | T4: =Meiktila!AD147 | U4: =Meiktila!AE147 | V4: =Meiktila!AG147 | W4: =Meiktila!AH147 | X4: =Meiktila!AJ147 | Y4: =Meiktila!AK147 | Z4: =Meiktila!AM147 | AA4: =Meiktila!AN147 | AB4: =SUM(D4+F4+H4+J4+L4+N4+P4+R4+T4+V4+X4+Z4) | AC4: =SUM(E4+G4+I4+K4+M4+O4+Q4+S4+U4+W4+Y4+AA4) | AD4: =AB4/12 | AE4: =AC4/12 | AF4: 367121 | AG4: 240101.32 | AH4: 295933 | AI4: 191759.08 | AJ4: 340823 | AK4: 221689.16 | AL4: 301632 | AM4: 197593.51 | AN4: 328803 | AO4: 215845.55 | AP4: 327493 | AQ4: 214991.94 | AR4: 363784 | AS4: 237539.67 | AT4: 316803 | AU4: 208645.68 | AV4: 362709 | AW4: 239448.24 | AX4: 355551 | AY4: 234021.54 | AZ4: 335794 | BA4: 220363.84 | BB4: 358228 | BC4: 235248.88 | BD4: =AF4+AH4+AJ4+AL4+AN4+AP4+AR4+AT4+AV4+AX4+AZ4+BB4 | BE4: =AG4+AI4+AK4+AM4+AO4+AQ4+AS4+AU4+AW4+AY4+BA4+BC4 | BF4: =BD4/12 | BG4: =BE4/12 | BH4: =BF4/$BF$16% | BI4: 14 | BJ4: 120 | BK4: 84 | BL4: 108 | BM4: 75.6 | BN4: 132 | BO4: 92.4 | CH4: =BJ4+BL4+BN4+BP4+BR4+BT4+BV4+BX4+BZ4+CB4+CD4+CF4 | CI4: =BK4+BM4+BO4+BQ4+BS4+BU4+BW4+BY4+CA4+CC4+CE4+CG4 | CJ4: =CH4/2 | CK4: =CI4/2 | CL4: =CJ4/$CJ$16% | CM4: 14
A5: 2 | B5: Tharzi | D5: =Tharzi!F147 | E5: =Tharzi!G147 | F5: =Tharzi!I147 | G5: =Tharzi!J147 | H5: =Tharzi!L147 | I5: =Tharzi!M147 | J5: =Tharzi!O147 | K5: =Tharzi!P147 | L5: =Tharzi!R147 | M5: =Tharzi!S147 | N5: =Tharzi!U147 | O5: =Tharzi!V147 | P5: =Tharzi!X147 | Q5: =Tharzi!Y147 | R5: =Tharzi!AA147 | S5: =Tharzi!AB147 | T5: =Tharzi!AD147 | U5: =Tharzi!AE147 | V5: =Tharzi!AG147 | W5: =Tharzi!AH147 | X5: =Tharzi!AJ147 | Y5: =Tharzi!AK147 | Z5: =Tharzi!AM147 | AA5: =Tharzi!AN147 | AB5: =SUM(D5+F5+H5+J5+L5+N5+P5+R5+T5+V5+X5+Z5) | AC5: =SUM(E5+G5+I5+K5+M5+O5+Q5+S5+U5+W5+Y5+AA5) | AD5: =AB5/12 | AE5: =AC5/12 | AF5: 26879 | AG5: 17997.2 | AH5: 20688 | AI5: 13724.64 | AJ5: 25006 | AK5: 16658.32 | AL5: 25958 | AM5: 17155.04 | AN5: 31590 | AO5: 20595.6 | AP5: 24888 | AQ5: 16422.96 | AR5: 26869 | AS5: 17950.84 | AT5: 19814 | AU5: 12893.12 | AV5: 19787 | AW5: 13005.2 | AX5: 21474 | AY5: 14065.92 | AZ5: 17408 | BA5: 11460.32 | BB5: 16484 | BC5: 10877.84 | BD5: =AF5+AH5+AJ5+AL5+AN5+AP5+AR5+AT5+AV5+AX5+AZ5+BB5 | BE5: =AG5+AI5+AK5+AM5+AO5+AQ5+AS5+AU5+AW5+AY5+BA5+BC5 | BF5: =BD5/12 | BG5: =BE5/12 | BH5: =BF5/$BF$16% | BI5: 2 | BJ5: 72 | BK5: 72 | BL5: 14245 | BM5: 9623.2 | CH5: =BJ5+BL5+BN5+BP5+BR5+BT5+BV5+BX5+BZ5+CB5+CD5+CF5 | CI5: =BK5+BM5+BO5+BQ5+BS5+BU5+BW5+BY5+CA5+CC5+CE5+CG5 | CJ5: =CH5/2 | CK5: =CI5/2 | CL5: =CJ5/$CJ$16% | CM5: 2
A6: 3 | B6: PyawBwe | D6: ='Pyaw Bwe'!F147 | E6: ='Pyaw Bwe'!G147 | F6: ='Pyaw Bwe'!I147 | G6: ='Pyaw Bwe'!J147 | H6: ='Pyaw Bwe'!L147 | I6: ='Pyaw Bwe'!M147 | J6: ='Pyaw Bwe'!O147 | K6: ='Pyaw Bwe'!P147 | L6: ='Pyaw Bwe'!R147 | M6: ='Pyaw Bwe'!S147 | N6: ='Pyaw Bwe'!U147 | O6: ='Pyaw Bwe'!V147 | P6: ='Pyaw Bwe'!X147 | Q6: ='Pyaw Bwe'!Y147 | R6: ='Pyaw Bwe'!AA147 | S6: ='Pyaw Bwe'!AB147 | T6: ='Pyaw Bwe'!AD147 | U6: ='Pyaw Bwe'!AE147 | V6: ='Pyaw Bwe'!AG147 | W6: ='Pyaw Bwe'!AH147 | X6: ='Pyaw Bwe'!AJ147 | Y6: ='Pyaw Bwe'!AK147 | Z6: ='Pyaw Bwe'!AM147 | AA6: ='Pyaw Bwe'!AN147 | AB6: =SUM(D6+F6+H6+J6+L6+N6+P6+R6+T6+V6+X6+Z6) | AC6: =SUM(E6+G6+I6+K6+M6+O6+Q6+S6+U6+W6+Y6+AA6) | AD6: =AB6/12 | AE6: =AC6/12 | AF6: 124810 | AG6: 80790.4 | AH6: 112556 | AI6: 72950.72 | AJ6: 140474 | AK6: 94063.04 | AL6: 99650 | AM6: 65613.92 | AN6: 125493 | AO6: 81712.56 | AP6: 117388 | AQ6: 76063.6 | AR6: 102118 | AS6: 67226.56 | AT6: 103610 | AU6: 67743.68 | AV6: 88610 | AW6: 58556.48 | AX6: 122032 | AY6: 79956.4 | AZ6: 128298 | BA6: 83945.52 | BB6: 123988 | BC6: 81845.44 | BD6: =AF6+AH6+AJ6+AL6+AN6+AP6+AR6+AT6+AV6+AX6+AZ6+BB6 | BE6: =AG6+AI6+AK6+AM6+AO6+AQ6+AS6+AU6+AW6+AY6+BA6+BC6 | BF6: =BD6/12 | BG6: =BE6/12 | BH6: =BF6/$BF$16% | BI6: 11 | BJ6: 103606 | BK6: 68727.52 | BL6: 88786 | BM6: 58781.92 | CH6: =BJ6+BL6+BN6+BP6+BR6+BT6+BV6+BX6+BZ6+CB6+CD6+CF6 | CI6: =BK6+BM6+BO6+BQ6+BS6+BU6+BW6+BY6+CA6+CC6+CE6+CG6 | CJ6: =CH6/2 | CK6: =CI6/2 | CL6: =CJ6/$CJ$16% | CM6: 11
A7: 4 | B7: Want Twin | D7: ='Want Twin'!F147 | E7: ='Want Twin'!G147 | F7: ='Want Twin'!I147 | G7: ='Want Twin'!J147 | H7: ='Want Twin'!L147 | I7: ='Want Twin'!M147 | J7: ='Want Twin'!O147 | K7: ='Want Twin'!P147 | L7: ='Want Twin'!R147 | M7: ='Want Twin'!S147 | N7: ='Want Twin'!U147 | O7: ='Want Twin'!V147 | P7: ='Want Twin'!X147 | Q7: ='Want Twin'!Y147 | R7: ='Want Twin'!AA147 | S7: ='Want Twin'!AB147 | T7: ='Want Twin'!AD147 | U7: ='Want Twin'!AE147 | V7: ='Want Twin'!AG147 | W7: ='Want Twin'!AH147 | X7: ='Want Twin'!AJ147 | Y7: ='Want Twin'!AK147 | Z7: ='Want Twin'!AM147 | AA7: ='Want Twin'!AN147 | AB7: =SUM(D7+F7+H7+J7+L7+N7+P7+R7+T7+V7+X7+Z7) | AC7: =SUM(E7+G7+I7+K7+M7+O7+Q7+S7+U7+W7+Y7+AA7) | AD7: =AB7/12 | AE7: =AC7/12 | AF7: 121257 | AG7: 79375.32 | AH7: 102976 | AI7: 67630.72 | AJ7: 172705 | AK7: 112072.6 | AL7: 98169 | AM7: 64360.14 | AN7: 109072 | AO7: 71152.3 | AP7: 104102 | AQ7: 68080.88 | AR7: 111468 | AS7: 73472.4 | AT7: 115998 | AU7: 76069.44 | AV7: 101637 | AW7: 67569.72 | AX7: 106609 | AY7: 70354.96 | AZ7: 98541 | BA7: 65446.2 | BB7: 117214 | BC7: 77714.56 | BD7: =AF7+AH7+AJ7+AL7+AN7+AP7+AR7+AT7+AV7+AX7+AZ7+BB7 | BE7: =AG7+AI7+AK7+AM7+AO7+AQ7+AS7+AU7+AW7+AY7+BA7+BC7 | BF7: =BD7/12 | BG7: =BE7/12 | BH7: =BF7/$BF$16% | BI7: 8 | BJ7: 98732 | BK7: 67023.68 | BL7: 107762 | BM7: 71280.8 | CH7: =BJ7+BL7+BN7+BP7+BR7+BT7+BV7+BX7+BZ7+CB7+CD7+CF7 | CI7: =BK7+BM7+BO7+BQ7+BS7+BU7+BW7+BY7+CA7+CC7+CE7+CG7 | CJ7: =CH7/2 | CK7: =CI7/2 | CL7: =CJ7/$CJ$16% | CM7: 8
A8: 5 | B8: Mahaling | D8: =Mahaling!F147 | E8: =Mahaling!G147 | F8: =Mahaling!I147 | G8: =Mahaling!J147 | H8: =Mahaling!L147 | I8: =Mahaling!M147 | J8: =Mahaling!O147 | K8: =Mahaling!P147 | L8: =Mahaling!R147 | M8: =Mahaling!S147 | N8: =Mahaling!U147 | O8: =Mahaling!V147 | P8: =Mahaling!X147 | Q8: =Mahaling!Y147 | R8: =Mahaling!AA147 | S8: =Mahaling!AB147 | T8: =Mahaling!AD147 | U8: =Mahaling!AE147 | V8: =Mahaling!AG147 | W8: =Mahaling!AH147 | X8: =Mahaling!AJ147 | Y8: =Mahaling!AK147 | Z8: =Mahaling!AM147 | AA8: =Mahaling!AN147 | AB8: =SUM(D8+F8+H8+J8+L8+N8+P8+R8+T8+V8+X8+Z8) | AC8: =SUM(E8+G8+I8+K8+M8+O8+Q8+S8+U8+W8+Y8+AA8) | AD8: =AB8/12 | AE8: =AC8/12 | AF8: 72384 | AG8: 47186.88 | AH8: 73604 | AI8: 48058.4 | AJ8: 89488 | AK8: 59433.52 | AL8: 73784 | AM8: 47479.4 | AN8: 52660 | AO8: 33983.2 | AP8: 78604 | AQ8: 52190.8 | AR8: 44890 | AS8: 29518 | AT8: 53780 | AU8: 35513.6 | AV8: 53268 | AW8: 35894.4 | AX8: 53598 | AY8: 36118.56 | AZ8: 75914 | BA8: 49677.2 | BB8: 59430 | BC8: 40238.4 | BD8: =AF8+AH8+AJ8+AL8+AN8+AP8+AR8+AT8+AV8+AX8+AZ8+BB8 | BE8: =AG8+AI8+AK8+AM8+AO8+AQ8+AS8+AU8+AW8+AY8+BA8+BC8 | BF8: =BD8/12 | BG8: =BE8/12 | BH8: =BF8/$BF$16% | BI8: 7 | BJ8: 65364 | BK8: 43015.2 | BL8: 65314 | BM8: 43141.6 | CH8: =BJ8+BL8+BN8+BP8+BR8+BT8+BV8+BX8+BZ8+CB8+CD8+CF8 | CI8: =BK8+BM8+BO8+BQ8+BS8+BU8+BW8+BY8+CA8+CC8+CE8+CG8 | CJ8: =CH8/2 | CK8: =CI8/2 | CL8: =CJ8/$CJ$16% | CM8: 7
A9: 6 | B9: Yamaethin | D9: =Yamethin!F147 | E9: =Yamethin!G147 | F9: =Yamethin!I147 | G9: =Yamethin!J147 | H9: =Yamethin!L147 | I9: =Yamethin!M147 | J9: =Yamethin!O147 | K9: =Yamethin!P147 | L9: =Yamethin!R147 | M9: =Yamethin!S147 | N9: =Yamethin!U147 | O9: =Yamethin!V147 | P9: =Yamethin!X147 | Q9: =Yamethin!Y147 | R9: =Yamethin!AA147 | S9: =Yamethin!AB147 | T9: =Yamethin!AD147 | U9: =Yamethin!AE147 | V9: =Yamethin!AG147 | W9: =Yamethin!AH147 | X9: =Yamethin!AJ147 | Y9: =Yamethin!AK147 | Z9: =Yamethin!AM147 | AA9: =Yamethin!AN147 | AB9: =SUM(D9+F9+H9+J9+L9+N9+P9+R9+T9+V9+X9+Z9) | AC9: =SUM(E9+G9+I9+K9+M9+O9+Q9+S9+U9+W9+Y9+AA9) | AD9: =AB9/12 | AE9: =AC9/12 | AF9: 26950 | AG9: 17476.96 | AH9: 27775 | AI9: 17899.96 | AJ9: 29226 | AK9: 20856.96 | AL9: 19738 | AM9: 12947.2 | AN9: 22802 | AO9: 14639.84 | AP9: 16112 | AQ9: 10622.24 | AR9: 24958 | AS9: 16216 | AT9: 18990 | AU9: 12657.6 | AV9: 25892 | AW9: 16641.2 | AX9: 22330 | AY9: 14778.4 | AZ9: 21736 | BA9: 14419.6 | BB9: 25310 | BC9: 16887.44 | BD9: =AF9+AH9+AJ9+AL9+AN9+AP9+AR9+AT9+AV9+AX9+AZ9+BB9 | BE9: =AG9+AI9+AK9+AM9+AO9+AQ9+AS9+AU9+AW9+AY9+BA9+BC9 | BF9: =BD9/12 | BG9: =BE9/12 | BH9: =BF9/$BF$16% | BI9: 10 | BJ9: 26618 | BK9: 17964.32 | BL9: 26738 | BM9: 17555.92 | CH9: =BJ9+BL9+BN9+BP9+BR9+BT9+BV9+BX9+BZ9+CB9+CD9+CF9 | CI9: =BK9+BM9+BO9+BQ9+BS9+BU9+BW9+BY9+CA9+CC9+CE9+CG9 | CJ9: =CH9/2 | CK9: =CI9/2 | CL9: =CJ9/$CJ$16% | CM9: 10
A10: 7 | B10: Kyaukpadaung | D10: =Kyaukpadaung!F147 | E10: =Kyaukpadaung!G147 | F10: =Kyaukpadaung!I147 | G10: =Kyaukpadaung!J147 | H10: =Kyaukpadaung!L147 | I10: =Kyaukpadaung!M147 | J10: =Kyaukpadaung!O147 | K10: =Kyaukpadaung!P147 | L10: =Kyaukpadaung!R147 | M10: =Kyaukpadaung!S147 | N10: =Kyaukpadaung!U147 | O10: =Kyaukpadaung!V147 | P10: =Kyaukpadaung!X147 | Q10: =Kyaukpadaung!Y147 | R10: =Kyaukpadaung!AA147 | S10: =Kyaukpadaung!AB147 | T10: =Kyaukpadaung!AD147 | U10: =Kyaukpadaung!AE147 | V10: =Kyaukpadaung!AG147 | W10: =Kyaukpadaung!AH147 | X10: =Kyaukpadaung!AJ147 | Y10: =Kyaukpadaung!AK147 | Z10: =Kyaukpadaung!AM147 | AA10: =Kyaukpadaung!AN147 | AB10: =SUM(D10+F10+H10+J10+L10+N10+P10+R10+T10+V10+X10+Z10) | AC10: =SUM(E10+G10+I10+K10+M10+O10+Q10+S10+U10+W10+Y10+AA10) | AD10: =AB10/12 | AE10: =AC10/12 | AF10: 140720 | AG10: 92830.64 | AH10: 119242 | AI10: 76066.48 | AJ10: 111430 | AK10: 75932.8 | AL10: 129640 | AM10: 83255.68 | AN10: 142342 | AO10: 94764.84 | AP10: 152574 | AQ10: 99846.48 | AR10: 120600 | AS10: 80598.48 | AT10: 149447 | AU10: 99127.16 | AV10: 147026 | AW10: 100454.24 | AX10: 144199 | AY10: 98587.6 | AZ10: 181990 | BA10: 119403.28 | BB10: 160582 | BC10: 106776.4 | BD10: =AF10+AH10+AJ10+AL10+AN10+AP10+AR10+AT10+AV10+AX10+AZ10+BB10 | BE10: =AG10+AI10+AK10+AM10+AO10+AQ10+AS10+AU10+AW10+AY10+BA10+BC10 | BF10: =BD10/12 | BG10: =BE10/12 | BH10: =BF10/$BF$16% | BI10: 6 | BJ10: 128272 | BK10: 85297.84 | BL10: 100088 | BM10: 68544.32 | CH10: =BJ10+BL10+BN10+BP10+BR10+BT10+BV10+BX10+BZ10+CB10+CD10+CF10 | CI10: =BK10+BM10+BO10+BQ10+BS10+BU10+BW10+BY10+CA10+CC10+CE10+CG10 | CJ10: =CH10/2 | CK10: =CI10/2 | CL10: =CJ10/$CJ$16% | CM10: 6
A11: 8 | B11: Taungthar | D11: =Taungthar!F147 | E11: =Taungthar!G147 | F11: =Taungthar!I147 | G11: =Taungthar!J147 | H11: =Taungthar!L147 | I11: =Taungthar!M147 | J11: =Taungthar!O147 | K11: =Taungthar!P147 | L11: =Taungthar!R147 | M11: =Taungthar!S147 | N11: =Taungthar!U147 | O11: =Taungthar!V147 | P11: =Taungthar!X147 | Q11: =Taungthar!Y147 | R11: =Taungthar!AA147 | S11: =Taungthar!AB147 | T11: =Taungthar!AD147 | U11: =Taungthar!AE147 | V11: =Taungthar!AG147 | W11: =Taungthar!AH147 | X11: =Taungthar!AJ147 | Y11: =Taungthar!AK147 | Z11: =Taungthar!AM147 | AA11: =Taungthar!AN147 | AB11: =SUM(D11+F11+H11+J11+L11+N11+P11+R11+T11+V11+X11+Z11) | AC11: =SUM(E11+G11+I11+K11+M11+O11+Q11+S11+U11+W11+Y11+AA11) | AD11: =AB11/12 | AE11: =AC11/12 | AF11: 20980 | AG11: 13960 | AH11: 18740 | AI11: 12512 | AJ11: 14700 | AK11: 9408 | AL11: 15700 | AM11: 10048 | AN11: 15230 | AO11: 9965.6 | AP11: 16140 | AQ11: 10329.6 | AR11: 6300 | AS11: 4032 | AT11: 17040 | AU11: 10992 | AV11: 4240 | AW11: 2972.8 | AX11: 17338 | AY11: 12910.72 | AZ11: 13960 | BA11: 9064 | BB11: 34960 | BC11: 22916.8 | BD11: =AF11+AH11+AJ11+AL11+AN11+AP11+AR11+AT11+AV11+AX11+AZ11+BB11 | BE11: =AG11+AI11+AK11+AM11+AO11+AQ11+AS11+AU11+AW11+AY11+BA11+BC11 | BF11: =BD11/12 | BG11: =BE11/12 | BH11: =BF11/$BF$16% | BI11: 16 | BJ11: 1200 | BK11: 1200 | BL11: 5900 | BM11: 4640 | CH11: =BJ11+BL11+BN11+BP11+BR11+BT11+BV11+BX11+BZ11+CB11+CD11+CF11 | CI11: =BK11+BM11+BO11+BQ11+BS11+BU11+BW11+BY11+CA11+CC11+CE11+CG11 | CJ11: =CH11/2 | CK11: =CI11/2 | CL11: =CJ11/$CJ$16% | CM11: 16
A12: 9 | B12: Myingyan | D12: =Myingyan!F147 | E12: =Myingyan!G147 | F12: =Myingyan!I147 | G12: =Myingyan!J147 | H12: =Myingyan!L147 | I12: =Myingyan!M147 | J12: =Myingyan!O147 | K12: =Myingyan!P147 | L12: =Myingyan!R147 | M12: =Myingyan!S147 | N12: =Myingyan!U147 | O12: =Myingyan!V147 | P12: =Myingyan!X147 | Q12: =Myingyan!Y147 | R12: =Myingyan!AA147 | S12: =Myingyan!AB147 | T12: =Myingyan!AD147 | U12: =Myingyan!AE147 | V12: =Myingyan!AG147 | W12: =Myingyan!AH147 | X12: =Myingyan!AJ147 | Y12: =Myingyan!AK147 | Z12: =Myingyan!AM147 | AA12: =Myingyan!AN147 | AB12: =SUM(D12+F12+H12+J12+L12+N12+P12+R12+T12+V12+X12+Z12) | AC12: =SUM(E12+G12+I12+K12+M12+O12+Q12+S12+U12+W12+Y12+AA12) | AD12: =AB12/12 | AE12: =AC12/12 | AF12: 15360 | AG12: 9830.4 | AH12: 10820 | AI12: 7032.8 | AJ12: 16260 | AK12: 10406.4 | AL12: 2800 | AM12: 1792 | AN12: 24748 | AO12: 16137.52 | AP12: 14390 | AQ12: 9227.6 | AR12: 12780 | AS12: 8197.2 | AT12: 9066 | AU12: 5809.44 | AV12: 7610 | AW12: 4924.4 | AX12: 3500 | AY12: 2240 | AZ12: 5100 | BA12: 3336 | BB12: 8652 | BC12: 5645.28 | BD12: =AF12+AH12+AJ12+AL12+AN12+AP12+AR12+AT12+AV12+AX12+AZ12+BB12 | BE12: =AG12+AI12+AK12+AM12+AO12+AQ12+AS12+AU12+AW12+AY12+BA12+BC12 | BF12: =BD12/12 | BG12: =BE12/12 | BH12: =BF12/$BF$16% | BI12: 17 | BJ12: 12430 | BK12: 7991.2 | BL12: 10600 | BM12: 6838 | CH12: =BJ12+BL12+BN12+BP12+BR12+BT12+BV12+BX12+BZ12+CB12+CD12+CF12 | CI12: =BK12+BM12+BO12+BQ12+BS12+BU12+BW12+BY12+CA12+CC12+CE12+CG12 | CJ12: =CH12/2 | CK12: =CI12/2 | CL12: =CJ12/$CJ$16% | CM12: 17
A13: 10 | B13: Bagan | D13: =Bagan!F147 | E13: =Bagan!G147 | F13: =Bagan!I147 | G13: =Bagan!J147 | H13: =Bagan!L147 | I13: =Bagan!M147 | J13: =Bagan!O147 | K13: =Bagan!P147 | L13: =Bagan!R147 | M13: =Bagan!S147 | N13: =Bagan!U147 | O13: =Bagan!V147 | P13: =Bagan!X147 | Q13: =Bagan!Y147 | R13: =Bagan!AA147 | S13: =Bagan!AB147 | T13: =Bagan!AD147 | U13: =Bagan!AE147 | V13: =Bagan!AG147 | W13: =Bagan!AH147 | X13: =Bagan!AJ147 | Y13: =Bagan!AK147 | Z13: =Bagan!AM147 | AA13: =Bagan!AN147 | AB13: =SUM(D13+F13+H13+J13+L13+N13+P13+R13+T13+V13+X13+Z13) | AC13: =SUM(E13+G13+I13+K13+M13+O13+Q13+S13+U13+W13+Y13+AA13) | AD13: =AB13/12 | AE13: =AC13/12 | AF13: 17991 | AG13: 11819.76 | AH13: 12551 | AI13: 8736.56 | AJ13: 51722 | AK13: 37107.92 | AL13: 7248 | AM13: 4652.16 | AN13: 13432 | AO13: 9081.28 | AP13: 6406 | AQ13: 4196.3 | AR13: 30534 | AS13: 22794.24 | AT13: 19225 | AU13: 12910.92 | AV13: 27022 | AW13: 21013.36 | AX13: 32225 | AY13: 26940.68 | AZ13: 17660 | BA13: 14564 | BB13: 25332 | BC13: 20067.84 | BD13: =AF13+AH13+AJ13+AL13+AN13+AP13+AR13+AT13+AV13+AX13+AZ13+BB13 | BE13: =AG13+AI13+AK13+AM13+AO13+AQ13+AS13+AU13+AW13+AY13+BA13+BC13 | BF13: =BD13/12 | BG13: =BE13/12 | BH13: =BF13/$BF$16% | BI13: 19 | BJ13: 9450 | BK13: 7948.8 | BL13: 19816 | BM13: 15159.04 | CH13: =BJ13+BL13+BN13+BP13+BR13+BT13+BV13+BX13+BZ13+CB13+CD13+CF13 | CI13: =BK13+BM13+BO13+BQ13+BS13+BU13+BW13+BY13+CA13+CC13+CE13+CG13 | CJ13: =CH13/2 | CK13: =CI13/2 | CL13: =CJ13/$CJ$16% | CM13: 19
A14: 11 | B14: Pakokku | D14: =Pakokku!F147 | E14: =Pakokku!G147 | F14: =Pakokku!I147 | G14: =Pakokku!J147 | H14: =Pakokku!L147 | I14: =Pakokku!M147 | J14: =Pakokku!O147 | K14: =Pakokku!P147 | L14: =Pakokku!R147 | M14: =Pakokku!S147 | N14: =Pakokku!U147 | O14: =Pakokku!V147 | P14: =Pakokku!X147 | Q14: =Pakokku!Y147 | R14: =Pakokku!AA147 | S14: =Pakokku!AB147 | T14: =Pakokku!AD147 | U14: =Pakokku!AE147 | V14: =Pakokku!AG147 | W14: =Pakokku!AH147 | X14: =Pakokku!AJ147 | Y14: =Pakokku!AK147 | Z14: =Pakokku!AM147 | AA14: =Pakokku!AN147 | AB14: =SUM(D14+F14+H14+J14+L14+N14+P14+R14+T14+V14+X14+Z14) | AC14: =SUM(E14+G14+I14+K14+M14+O14+Q14+S14+U14+W14+Y14+AA14) | AD14: =AB14/12 | AE14: =AC14/12 | AF14: 31300 | AG14: 20464 | AH14: 23966 | AI14: 16457.12 | AJ14: 28720 | AK14: 19720 | AL14: 28780 | AM14: 19715.2 | AN14: 22568 | AO14: 15303.2 | AP14: 26150 | AQ14: 16640 | AR14: 19402 | AS14: 13712.8 | AT14: 24920 | AU14: 16371.2 | AV14: 28400 | AW14: 23360 | AX14: 20180 | AY14: 13779.2 | AZ14: 32280 | BA14: 25104 | BB14: 26616 | BC14: 18762.24 | BD14: =AF14+AH14+AJ14+AL14+AN14+AP14+AR14+AT14+AV14+AX14+AZ14+BB14 | BE14: =AG14+AI14+AK14+AM14+AO14+AQ14+AS14+AU14+AW14+AY14+BA14+BC14 | BF14: =BD14/12 | BG14: =BE14/12 | BH14: =BF14/$BF$16% | BI14: 5 | BJ14: 21600 | BK14: 14040 | BL14: 3860 | BM14: 2456 | CH14: =BJ14+BL14+BN14+BP14+BR14+BT14+BV14+BX14+BZ14+CB14+CD14+CF14 | CI14: =BK14+BM14+BO14+BQ14+BS14+BU14+BW14+BY14+CA14+CC14+CE14+CG14 | CJ14: =CH14/2 | CK14: =CI14/2 | CL14: =CJ14/$CJ$16% | CM14: 5
AB15: =SUM(D15+F15+H15+J15+L15+N15+P15+R15+T15+V15+X15+Z15) | AC15: =SUM(E15+G15+I15+K15+M15+O15+Q15+S15+U15+W15+Y15+AA15)
B16: Wholesales Total | C16: =SUM(C4:C15) | D16: =SUM(D4:D15) | E16: =SUM(E4:E15) | F16: =SUM(F4:F15) | G16: =SUM(G4:G15) | H16: =SUM(H4:H14) | I16: =SUM(I4:I15) | J16: =SUM(J4:J15) | K16: =SUM(K4:K15) | L16: =SUM(L4:L15) | M16: =SUM(M4:M15) | N16: =SUM(N4:N15) | O16: =SUM(O4:O15) | P16: =SUM(P4:P15) | ... AH16: =SUM(AH4:AH15) | AI16: =SUM(AI4:AI14) | AJ16: =SUM(AJ4:AJ15) | AK16: =SUM(AK4:AK15) | AL16: =SUM(AL4:AL15) | AM16: =SUM(AM4:AM15) | AN16: =SUM(AN4:AN15) | AO16: =SUM(AO4:AO15) | AP16: 884247 | AQ16: 578612.4 | AR16: =SUM(AR4:AR15) | AS16: =SUM(AS4:AS15) | AT16: =SUM(AT4:AT15) | AU16: =SUM(AU4:AU15) | AV16: =SUM(AV4:AV15) | AW16: =SUM(AW4:AW15) | AX16: =SUM(AX4:AX15) | AY16: =SUM(AY4:AY15) | ... BG16: =SUM(BG4:BG15) | BH16: 100% | BJ16: =SUM(BJ4:BJ15) | BK16: =SUM(BK4:BK15) | BL16: =SUM(BL4:BL15) | BM16: =SUM(BM4:BM15) | BN16: =SUM(BN4:BN15) | BO16: =SUM(BO4:BO15) | BP16: =SUM(BP4:BP15) | BQ16: =SUM(BQ4:BQ15) | ... CK16: =SUM(CK4:CK15) | CL16: 100%
A18: 1 | BH18: Town wise Contribution | BI18: Contirbution wise Priority Town | CL18: Town wise Contribution | CM18: Contirbution wise Priority Town
A19: No | B19: TownShip | C19: Van | D19: 45292 | F19: 45323 | H19: 45352 | J19: 45383 | L19: 45413 | N19: 45444 | P19: 45474 | R19: 45505 | T19: 45536 | V19: 45566 | X19: 45597 | Z19: 45627 | AB19: 2024 Total | AD19: 2024 Average | AF19: January | AH19: February | AJ19: March | AL19: April | AN19: May | AP19: June | AR19: July | AT19: August | AV19: September | AX19: October | AZ19: November | BB19: December | BD19: =+BD2 | BF19: =+BF2 | BJ19: January | BL19: February | BN19: March | BP19: April | BR19: May | BT19: June | BV19: July | BX19: August | BZ19: September | CB19: October | CD19: November | CF19: December | CH19: =+CH2 | CJ19: =+CJ2
D20: Bottle | E20: Liter | F20: Bottle | G20: Liter | H20: Bottle | I20: Liter | J20: Bottle | K20: Liter | L20: Bottle | M20: Liter | N20: Bottle | O20: Liter | P20: Bottle | Q20: Liter | R20: Bottle | S20: Liter | T20: Bottle | U20: Liter | V20: Bottle | W20: Liter | X20: Bottle | Y20: Liter | Z20: Bottle | AA20: Liter | AB20: Bottle | AC20: Liter | AD20: Bottle | AE20: Litre | AF20: Bottle | AG20: Liter | AH20: Bottle | AI20: Liter | AJ20: Bottle | AK20: Liter | AL20: Bottle | AM20: Liter | AN20: Bottle | AO20: Liter | AP20: Bottle | AQ20: Liter | AR20: Bottle | AS20: Liter | AT20: Bottle | AU20: Liter | AV20: Bottle | AW20: Liter | AX20: Bottle | AY20: Liter | AZ20: Bottle | BA20: Liter | BB20: Bottle | BC20: Liter | BD20: Bottle | BE20: Liter | BF20: Bottle | BG20: Liter | BJ20: Bottle | BK20: Liter | BL20: Bottle | BM20: Liter | BN20: Bottle | BO20: Liter | BP20: Bottle | BQ20: Liter | BR20: Bottle | BS20: Liter | BT20: Bottle | BU20: Liter | BV20: Bottle | BW20: Liter | BX20: Bottle | BY20: Liter | BZ20: Bottle | CA20: Liter | CB20: Bottle | CC20: Liter | CD20: Bottle | CE20: Liter | CF20: Bottle | CG20: Liter | CH20: Bottle | CI20: Liter | CJ20: Bottle | CK20: Liter
A21: 1 | B21: Market | C21: Van 1 | D21: 12 | E21: 8 | F21: 13517 | G21: 9154 | H21: 13924 | I21: 9213 | J21: 14653 | K21: 9575 | L21: 31501 | M21: 20544 | N21: 32840 | O21: 21855 | P21: 34638 | Q21: 23709 | R21: 43416 | S21: 28851 | T21: 36593 | U21: 24154 | V21: 55297 | W21: 37016 | X21: 34346 | Y21: 22847 | Z21: 35277 | AA21: 24195 | AB21: =D21+F21+H21+J21+L21+N21+P21+R21+T21+V21+X21+Z21 | AC21: =E21+G21+I21+K21+M21+O21+Q21+S21+U21+W21+Y21+AA21 | AD21: =AB21/12 | AE21: =AC21/12 | AF21: 50057 | AG21: 34922.96 | AH21: 43950 | AI21: 29455.56 | AJ21: 41944 | AK21: 30418.24 | AL21: 36496 | AM21: 25269.76 | AN21: 47040 | AO21: 33407.19 | AP21: 42746 | AQ21: 29883.78 | AR21: 48692 | AS21: 35518.16 | AT21: 47776 | AU21: 35118.72 | AV21: 37922 | AW21: 28595.36 | AX21: 42806 | AY21: 35427.08 | AZ21: 44494 | BA21: 33803.2 | BB21: 51658 | BC21: 39741.76 | BD21: =AF21+AH21+AJ21+AL21+AN21+AP21+AR21+AT21+AV21+AX21+AZ21+BB21 | BE21: =AG21+AI21+AK21+AM21+AO21+AS21+AU21+AW21+AY21+BA21+BC21+AQ21 | BF21: =BD21/12 | BG21: =BE21/12 | BH21: =BF21/$BF$23% | BI21: 8 | BJ21: 40498 | BK21: 31656.16 | BL21: 35848 | BM21: 29065.2 | CH21: =BJ21+BL21+BN21+BP21+BR21+BT21+BV21+BX21+BZ21+CB21+CD21+CF21 | CI21: =BK21+BM21+BO21+BQ21+BS21+BU21+BW21+BY21+CA21+CC21+CE21+CG21 | CJ21: =CH21/2 | CK21: =CI21/2 | CL21: =CJ21/$CJ$23% | CM21: 8
A22: 2 | B22: Market | C22: Van 2 | D22: 16581 | E22: 10834 | F22: 25778 | G22: 17053 | H22: 31634 | I22: 20807 | J22: 36125 | K22: 24045 | L22: 29150 | M22: 19004 | N22: 28236 | O22: 18460 | P22: 30251 | Q22: 20188 | R22: 32780 | S22: 21641 | T22: 25279 | U22: 16813 | V22: 22381 | W22: 15108 | X22: 25808 | Y22: 16920 | Z22: 28618 | AA22: 19351 | AB22: =D22+F22+H22+J22+L22+N22+P22+R22+T22+V22+X22+Z22 | AC22: =E22+G22+I22+K22+M22+O22+Q22+S22+U22+W22+Y22+AA22 | AD22: =AB22/12 | AE22: =AC22/12 | AF22: 35003 | AG22: 24170.8 | AH22: 27497 | AI22: 18905.96 | AJ22: 31865 | AK22: 21550.7 | AL22: 27454 | AM22: 18587.99 | AN22: 34213 | AO22: 23019.51 | AP22: 34259 | AQ22: 22892.26 | AR22: 33745 | AS22: 23232.27 | AT22: 28585 | AU22: 19379.92 | AV22: 27271 | AW22: 19403.32 | AX22: 17824 | AY22: 11979.22 | AZ22: 21525 | BA22: 15236.28 | BB22: 21852 | BC22: 15407.28 | BD22: =AF22+AH22+AJ22+AL22+AN22+AP22+AR22+AT22+AV22+AX22+AZ22+BB22 | BE22: =AG22+AI22+AK22+AM22+AO22+AS22+AU22+AW22+AY22+BA22+BC22+AQ22 | BF22: =BD22/12 | BG22: =BE22/12 | BH22: =BF22/$BF$23% | BI22: 14 | BJ22: 25083 | BK22: 17968.32 | BL22: 21503 | BM22: 15355.52 | CH22: =BJ22+BL22+BN22+BP22+BR22+BT22+BV22+BX22+BZ22+CB22+CD22+CF22 | CI22: =BK22+BM22+BO22+BQ22+BS22+BU22+BW22+BY22+CA22+CC22+CE22+CG22 | CJ22: =CH22/2 | CK22: =CI22/2 | CL22: =CJ22/$CJ$23% | CM22: 14
B23: Market Total | D23: =SUM(D21:D22) | E23: =SUM(E21:E22) | F23: =SUM(F21:F22) | G23: =SUM(G21:G22) | H23: =SUM(H21:H22) | I23: =SUM(I21:I22) | J23: =SUM(J21:J22) | K23: =SUM(K21:K22) | ... AO23: =SUM(AO21:AO22) | AP23: 77005 | AQ23: 52776.04 | AR23: =SUM(AR21:AR22) | AS23: =SUM(AS21:AS22) | AT23: =SUM(AT21:AT22) | AU23: =SUM(AU21:AU22) | AV23: =SUM(AV21:AV22) | AW23: =SUM(AW21:AW22) | AX23: =SUM(AX21:AX22) | AY23: =SUM(AY21:AY22) | ... BG23: =SUM(BG21:BG22) | BH23: 100% | BJ23: =SUM(BJ21:BJ22) | BK23: =SUM(BK21:BK22) | BL23: =SUM(BL21:BL22) | BM23: =SUM(BM21:BM22) | BN23: =SUM(BN21:BN22) | BO23: =SUM(BO21:BO22) | BP23: =SUM(BP21:BP22) | BQ23: =SUM(BQ21:BQ22) | ... BS23: =SUM(BS21:BS22) | BV23: =SUM(BV21:BV22) | BW23: =SUM(BW21:BW22) | BX23: =SUM(BX21:BX22) | BY23: =SUM(BY21:BY22) | BZ23: =SUM(BZ21:BZ22) | CA23: =SUM(CA21:CA22) | CB23: =SUM(CB21:CB22) | CC23: =SUM(CC21:CC22) | ... CK23: =SUM(CK21:CK22) | CL23: 100%
A25: Sale Data Percentage
A26: No | B26: Names | C26: Van | D26: 45292 | F26: 45323 | H26: 45352 | J26: 45383 | L26: 45413 | N26: 45444 | P26: 45474 | R26: 45505 | T26: 45536 | V26: 45566 | X26: 45597 | Z26: 45627 | AB26: 2024 Total | AD26: 2024 Average | AF26: January | AH26: February | AJ26: March | AL26: April | AN26: May | AP26: June | AR26: July | AT26: August | AV26: September | AX26: October | AZ26: November | BB26: December | BD26: =+BD19 | BF26: Average | BJ26: January | BL26: February | BN26: March | BP26: April | BR26: May | BT26: June | BV26: July | BX26: August | BZ26: September | CB26: October | CD26: November | CF26: December | CH26: =+CH19 | CJ26: Average
D27: Bottle | E27: Liter | F27: Bottle | G27: Liter | H27: Bottle | I27: Liter | J27: Bottle | K27: Liter | L27: Bottle | M27: Liter | N27: Bottle | O27: Liter | P27: Bottle | Q27: Liter | R27: Bottle | S27: Liter | T27: Bottle | U27: Liter | V27: Bottle | W27: Liter | X27: Bottle | Y27: Liter | Z27: Bottle | AA27: Liter | AB27: Bottle | AC27: Liter | AD27: Bottle | AE27: Litre | AF27: Bottle | AG27: Liter | AH27: Bottle | AI27: Liter | AJ27: Bottle | AK27: Liter | AL27: Bottle | AM27: Liter | AN27: Bottle | AO27: Liter | AP27: Bottle | AQ27: Liter | AR27: Bottle | AS27: Liter | AT27: Bottle | AU27: Liter | AV27: Bottle | AW27: Liter | AX27: Bottle | AY27: Liter | AZ27: Bottle | BA27: Liter | BB27: Bottle | BC27: Liter | BD27: Bottle | BE27: Liter | BF27: Bottle | BG27: Liter | BJ27: Bottle | BK27: Liter | BL27: Bottle | BM27: Liter | BN27: Bottle | BO27: Liter | BP27: Bottle | BQ27: Liter | BR27: Bottle | BS27: Liter | BT27: Bottle | BU27: Liter | BV27: Bottle | BW27: Liter | BX27: Bottle | BY27: Liter | BZ27: Bottle | CA27: Liter | CB27: Bottle | CC27: Liter | CD27: Bottle | CE27: Liter | CF27: Bottle | CG27: Liter | CH27: Bottle | CI27: Liter | CJ27: Bottle | CK27: Liter
A28: 1 | B28: Wholesales+Semi Wholesales | D28: =D16-D29 | E28: =E16-E29 | F28: =F16-F29 | G28: =G16-G29 | H28: =H16-H29 | I28: =I16-I29 | J28: =J16-J29 | K28: =K16-K23 | L28: =L16-L29 | M28: =M16-M23 | N28: =N16-N29 | O28: =O16-O23 | P28: =P16-P29 | Q28: =Q16-Q23 | R28: =R16-R29 | S28: =S16-S29 | T28: =T16-T29 | U28: =U16-U29 | V28: =V16-V29 | W28: =W16-W29 | X28: =X16-X29 | Y28: =Y16-Y23 | Z28: =Z16-Z29 | AA28: =AA16-AA23 | AB28: =AB16-AB29 | AC28: =AC16-AC23 | AD28: =AD16-AD23 | AE28: =AE16-AE29 | AF28: =AF16-AF29 | AG28: =AG16-AG29 | AH28: =AH16-AH29 | AI28: =AI16-AI29 | AJ28: =AJ16-AJ29 | AK28: =AK16-AK23 | AL28: =AL16-AL29 | AM28: =AM16-AM23 | AN28: =AN16-AN29 | AO28: =AO16-AO23 | AP28: =AP16-AP29 | AQ28: =AQ16-AQ23 | AR28: =AR16-AR29 | AS28: =AS16-AS23 | AT28: =AT16-AT29 | AU28: =AU16-AU23 | AV28: =AV16-AV29 | AW28: =AW16-AW23 | AX28: =AX16-AX29 | AY28: =AY16-AY23 | AZ28: =AZ16-AZ29 | BA28: =BA16-BA23 | BB28: =BB16-BB29 | BC28: =BC16-BC23 | BD28: =BD16-BD29 | BE28: =BE16-BE23 | BF28: =BD28/12 | BG28: =BE28/12 | BJ28: =BJ16-BJ29 | BK28: =BK16-BK29 | BL28: =BL16-BL29 | BM28: =BM16-BM29 | BN28: =BN16-BN29 | BO28: =BO16-BO23 | BP28: =BP16-BP29 | BQ28: =BQ16-BQ23 | BR28: =BR16-BR29 | BS28: =BS16-BS23 | BT28: =BT16-BT29 | BU28: =BU16-BU23 | BV28: =BV16-BV29 | BW28: =BW16-BW23 | BX28: =BX16-BX29 | BY28: =BY16-BY23 | BZ28: =BZ16-BZ29 | CA28: =CA16-CA23 | CB28: =CB16-CB29 | CC28: =CC16-CC23 | CD28: =CD16-CD29 | CE28: =CE16-CE23 | CF28: =CF16-CF29 | CG28: =CG16-CG23 | CH28: =CH16-CH29 | CI28: =CI16-CI23 | CJ28: =CH28/2 | CK28: =CI28/2
A29: 2 | B29: Market | D29: =D23 | E29: =E23 | F29: =F23 | G29: =G23 | H29: =H23 | I29: =I23 | J29: =J23 | K29: =K23 | ... AB29: =AB23 | AC29: =AB23 | AD29: =AD23 | AE29: =AE23 | AF29: =AF23 | AG29: =AG23 | AH29: =AH23 | AI29: =AI23 | AJ29: =AJ23 | AK29: =AK23 | ... BE29: =BE23 | BF29: =BD29/12 | BG29: =BE29/12 | BJ29: =BJ23 | BK29: =BK23 | BL29: =BL23 | BM29: =BM23 | BN29: =BN23 | BO29: =BO23 | BP29: =BP23 | BQ29: =BQ23 | ... CI29: =CI23 | CJ29: =CH29/2 | CK29: =CI29/2
A30: Total Sales | D30: =SUM(D28:D29) | E30: =SUM(E28:E29) | F30: =SUM(F28:F29) | G30: =SUM(G28:G29) | H30: =SUM(H28:H29) | I30: =SUM(I28:I29) | J30: =SUM(J28:J29) | K30: =SUM(K28:K29) | ... BG30: =SUM(BG28:BG29) | BJ30: =SUM(BJ28:BJ29) | BK30: =SUM(BK28:BK29) | BL30: =SUM(BL28:BL29) | BM30: =SUM(BM28:BM29) | BN30: =SUM(BN28:BN29) | BO30: =SUM(BO28:BO29) | BP30: =SUM(BP28:BP29) | BQ30: =SUM(BQ28:BQ29) | ... CK30: =SUM(CK28:CK29)
A31: 1 | B31: Wholesales (%) | D31: =D28/D30 | E31: =E28/E30 | F31: =F28/F30 | G31: =G28/G30 | H31: =H28/H30 | I31: =I28/I30 | J31: =J28/J30 | K31: =K28/K30 | ... BF31: =BF28/BF30 | BG31: =BG30/BG28 | BJ31: =BJ28/BJ30 | BK31: =BK28/BK30 | BL31: =BL28/BL30 | BM31: =BM28/BM30 | BN31: =BN28/BN30 | BO31: =BO28/BO30 | BP31: =BP28/BP30 | BQ31: =BQ28/BQ30 | ... CK31: =CK28/CK30
A32: 2 | B32: Market (%) | D32: =D29/D30 | E32: =E29/E30 | F32: =F29/F30 | G32: =G29/G30 | H32: =H29/H30 | I32: =I29/I30 | J32: =J29/J30 | K32: =K29/K30 | ... BG32: =BG29/BG30 | BJ32: =BJ29/BJ30 | BK32: =BK29/BK30 | BL32: =BL29/BL30 | BM32: =BM29/BM30 | BN32: =BN29/BN30 | BO32: =BO29/BO30 | BP32: =BP29/BP30 | BQ32: =BQ29/BQ30 | ... CK32: =CK29/CK30

Sheet Meiktila
B1: 2024 - Sales Details Meiktila (MeiktilaTownship)
A2: Sr | B2: Product Name | C2: Ml | D2: Packing | E2: 45292 | H2: 45323 | K2: 45352 | N2: 45383 | Q2: 45413 | T2: 45444 | W2: 45474 | Z2: 45505 | AC2: 45536 | AF2: 45566 | AI2: 45597 | AL2: 45627 | AO2: 2024 Total | AR2: 2024 Average | AT2: 45658 | AW2: 45689 | AZ2: 45717 | BC2: 45748 | BF2: 45778 | BI2: 45809 | BL2: 45839 | BO2: 45870 | BR2: 45901 | BU2: 45931 | BX2: 45962 | CA2: 45992 | CD2: 2025 -Total | CG2: 2025 Average | CI2: 46023 | CL2: 46054 | CO2: 46082 | CR2: 46113 | CU2: 46143 | CX2: 46174 | DA2: 46204 | DD2: 46235 | DG2: 46266 | DJ2: 46296 | DM2: 46327 | DP2: 46357 | DS2: 2026 -Total | DV2: 2026 Average
E3: PK | F3: Bottle | G3: Liter | H3: PK | I3: Bottle | J3: Liter | K3: PK | L3: Bottle | M3: Liter | N3: PK | O3: Bottle | P3: Liter | Q3: PK | R3: Bottle | S3: Liter | T3: PK | U3: Bottle | V3: Liter | W3: PK | X3: Bottle | Y3: Liter | Z3: PK | AA3: Bottle | AB3: Liter | AC3: PK | AD3: Bottle | AE3: Liter | AF3: PK | AG3: Bottle | AH3: Liter | AI3: PK | AJ3: Bottle | AK3: Liter | AL3: PK | AM3: Bottle | AN3: Liter | AO3: PK | AP3: Bottle | AQ3: Liter | AR3: Bottle | AS3: Liter | AT3: PK | AU3: Bottle | AV3: Liter | AW3: PK | AX3: Bottle | AY3: Liter | AZ3: PK | BA3: Bottle | BB3: Liter | BC3: PK | BD3: Bottle | BE3: Liter | BF3: PK | BG3: Bottle | BH3: Liter | BI3: PK | BJ3: Bottle | BK3: Liter | BL3: PK | BM3: Bottle | BN3: Liter | BO3: PK | BP3: Bottle | BQ3: Liter | BR3: PK | BS3: Bottle | BT3: Liter | BU3: PK | BV3: Bottle | BW3: Liter | BX3: PK | BY3: Bottle | BZ3: Liter | CA3: PK | CB3: Bottle | CC3: Liter | CD3: PK | CE3: Bottle | CF3: Liter | CG3: Bottle | CH3: Liter | CI3: PK | CJ3: Bottle | CK3: Liter | CL3: PK | CM3: Bottle | CN3: Liter | CO3: PK | CP3: Bottle | CQ3: Liter | CR3: PK | CS3: Bottle | CT3: Liter | CU3: PK | CV3: Bottle | CW3: Liter | CX3: PK | CY3: Bottle | CZ3: Liter | DA3: PK | DB3: Bottle | DC3: Liter | DD3: PK | DE3: Bottle | DF3: Liter | DG3: PK | DH3: Bottle | DI3: Liter | DJ3: PK | DK3: Bottle | DL3: Liter | DM3: PK | DN3: Bottle | DO3: Liter | DP3: PK | DQ3: Bottle | DR3: Liter | DS3: PK | DT3: Bottle | DU3: Liter | DV3: Bottle | DW3: Liter
A4: 1 | B4: "Zay" Vodka 700-ml | C4: 0.7 | D4: 1 * 12 | E4: 35 | F4: 420 | G4: =F4*$C4 | H4: 3 | I4: 36 | J4: =I4*$C4 | K4: 12 | L4: 144 | M4: =L4*$C4 | N4: 25 | O4: 300 | P4: =O4*$C4 | T4: 1 | U4: 12 | V4: =U4*$C4 | W4: 11 | X4: 138 | Y4: =X4*$C4 | AB4: =AA4*$C4 | AC4: 10 | AD4: 120 | AE4: =AD4*$C4 | AH4: =AG4*$C4 | AN4: =AM4*$C4 | AO4: =E4+H4+K4+N4+Q4+T4+W4+Z4+AC4+AF4+AI4+AL4 | AP4: =F4+I4+L4+O4+R4+U4+X4+AA4+AD4+AG4+AJ4+AM4 | AQ4: =G4+J4+M4+P4+S4+V4+Y4+AB4+AE4+AH4+AK4+AN4 | AR4: =+AP4/12 | AS4: =+AQ4/12 | AY4: =AX4*$C4 | BK4: =BJ4*$C4 | BN4: =BM4*C4 | BQ4: =BP4*C4 | BS4: 2 | BT4: =BS4*C4 | BW4: =BV4*C4 | BZ4: =BY4*C4 | CC4: =CB4*C4 | CD4: =AT4+AW4+AZ4+BC4+BF4+BI4+BL4+BO4+BR4+BU4+BX4+CA4 | CE4: =AU4+AX4+BA4+BD4+BG4+BJ4+BM4+BP4+BS4+BV4+BY4+CB4 | CF4: =AV4+AY4+BB4+BE4+BH4+BK4+BN4+BQ4+BT4+BW4+BZ4+CC4 | CG4: =+CE4/12 | CH4: =+CF4/12 | CI4: 10 | CJ4: 120 | CK4: =CJ4*C4 | CL4: 9 | CM4: 108 | CN4: =CM4*C4 | CO4: 11 | CP4: 132 | CQ4: 92.4 | DS4: =CI4+CL4+CO4+CR4+CU4+CX4+DA4+DD4+DG4+DJ4+DM4+DP4 | DT4: =CJ4+CM4+CP4+CS4+CV4+CY4+DB4+DE4+DH4+DK4+DN4+DQ4 | DU4: =CK4+CN4+CQ4+CT4+CW4+CZ4+DC4+DF4+DI4+DL4+DO4+DR4
G5: =F5*$C5 | J5: =I5*$C5 | M5: =L5*$C5 | P5: =O5*$C5 | V5: =U5*$C5 | Y5: =X5*$C5 | AB5: =AA5*$C5 | AE5: =AD5*$C5 | AH5: =AG5*$C5 | AN5: =AM5*$C5 | AO5: =E5+H5+K5+N5+Q5+T5+W5+Z5+AC5+AF5+AI5+AL5 | AP5: =F5+I5+L5+O5+R5+U5+X5+AA5+AD5+AG5+AJ5+AM5 | AQ5: =G5+J5+M5+P5+S5+V5+Y5+AB5+AE5+AH5+AK5+AN5 | AR5: =+AP5/12 | AS5: =+AQ5/12 | AY5: =AX5*$C5 | BK5: =BJ5*$C5 | BN5: =BM5*C5 | BQ5: =BP5*C5 | BT5: =BS5*C5 | BW5: =BV5*C5 | BZ5: =BY5*C5 | CC5: =CB5*C5 | CD5: =AT5+AW5+AZ5+BC5+BF5+BI5+BL5+BO5+BR5+BU5+BX5+CA5 | CE5: =AU5+AX5+BA5+BD5+BG5+BJ5+BM5+BP5+BS5+BV5+BY5+CB5 | CF5: =AV5+AY5+BB5+BE5+BH5+BK5+BN5+BQ5+BT5+BW5+BZ5+CC5 | CG5: =+CE5/12 | CH5: =+CF5/12 | CK5: =CJ5*C5 | CN5: =CM5*C5 | DS5: =CI5+CL5+CO5+CR5+CU5+CX5+DA5+DD5+DG5+DJ5+DM5+DP5 | DT5: =CJ5+CM5+CP5+CS5+CV5+CY5+DB5+DE5+DH5+DK5+DN5+DQ5 | DU5: =CK5+CN5+CQ5+CT5+CW5+CZ5+DC5+DF5+DI5+DL5+DO5+DR5
A6: 2 | B6: "Zay" Vodka (1 Liter) | C6: 1 | D6: 1 * 12 | G6: =F6*$C6 | J6: =I6*$C6 | M6: =L6*$C6 | P6: =O6*$C6 | V6: =U6*$C6 | Y6: =X6*$C6 | AB6: =AA6*$C6 | AE6: =AD6*$C6 | AH6: =AG6*$C6 | AN6: =AM6*$C6 | AO6: =E6+H6+K6+N6+Q6+T6+W6+Z6+AC6+AF6+AI6+AL6 | AP6: =F6+I6+L6+O6+R6+U6+X6+AA6+AD6+AG6+AJ6+AM6 | AQ6: =G6+J6+M6+P6+S6+V6+Y6+AB6+AE6+AH6+AK6+AN6 | AR6: =+AP6/12 | AS6: =+AQ6/12 | AY6: =AX6*$C6 | BK6: =BJ6*$C6 | BN6: =BM6*C6 | BQ6: =BP6*C6 | BT6: =BS6*C6 | BW6: =BV6*C6 | BZ6: =BY6*C6 | CC6: =CB6*C6 | CD6: =AT6+AW6+AZ6+BC6+BF6+BI6+BL6+BO6+BR6+BU6+BX6+CA6 | CE6: =AU6+AX6+BA6+BD6+BG6+BJ6+BM6+BP6+BS6+BV6+BY6+CB6 | CF6: =AV6+AY6+BB6+BE6+BH6+BK6+BN6+BQ6+BT6+BW6+BZ6+CC6 | CG6: =+CE6/12 | CH6: =+CF6/12 | CK6: =CJ6*C6 | CN6: =CM6*C6 | DS6: =CI6+CL6+CO6+CR6+CU6+CX6+DA6+DD6+DG6+DJ6+DM6+DP6 | DT6: =CJ6+CM6+CP6+CS6+CV6+CY6+DB6+DE6+DH6+DK6+DN6+DQ6 | DU6: =CK6+CN6+CQ6+CT6+CW6+CZ6+DC6+DF6+DI6+DL6+DO6+DR6
A7: 3 | B7: "Zay" (1 Liter) | C7: 1 | D7: 1 * 12 | G7: =F7*$C7 | J7: =I7*$C7 | M7: =L7*$C7 | P7: =O7*$C7 | V7: =U7*$C7 | Y7: =X7*$C7 | AB7: =AA7*$C7 | AE7: =AD7*$C7 | AH7: =AG7*$C7 | AN7: =AM7*$C7 | AO7: =E7+H7+K7+N7+Q7+T7+W7+Z7+AC7+AF7+AI7+AL7 | AP7: =F7+I7+L7+O7+R7+U7+X7+AA7+AD7+AG7+AJ7+AM7 | AQ7: =G7+J7+M7+P7+S7+V7+Y7+AB7+AE7+AH7+AK7+AN7 | AR7: =+AP7/12 | AS7: =+AQ7/12 | AY7: =AX7*$C7 | BK7: =BJ7*$C7 | BL7: 2 | BM7: 24 | BN7: =BM7*C7 | BQ7: =BP7*C7 | BT7: =BS7*C7 | BW7: =BV7*C7 | BZ7: =BY7*C7 | CC7: =CB7*C7 | CD7: =AT7+AW7+AZ7+BC7+BF7+BI7+BL7+BO7+BR7+BU7+BX7+CA7 | CE7: =AU7+AX7+BA7+BD7+BG7+BJ7+BM7+BP7+BS7+BV7+BY7+CB7 | CF7: =AV7+AY7+BB7+BE7+BH7+BK7+BN7+BQ7+BT7+BW7+BZ7+CC7 | CG7: =+CE7/12 | CH7: =+CF7/12 | CK7: =CJ7*C7 | CN7: =CM7*C7 | DS7: =CI7+CL7+CO7+CR7+CU7+CX7+DA7+DD7+DG7+DJ7+DM7+DP7 | DT7: =CJ7+CM7+CP7+CS7+CV7+CY7+DB7+DE7+DH7+DK7+DN7+DQ7 | DU7: =CK7+CN7+CQ7+CT7+CW7+CZ7+DC7+DF7+DI7+DL7+DO7+DR7
A8: 4 | B8: "Zay" (0.6 Liter) | C8: 0.6 | D8: 1 * 12 | G8: =F8*$C8 | J8: =I8*$C8 | M8: =L8*$C8 | P8: =O8*$C8 | V8: =U8*$C8 | Y8: =X8*$C8 | AB8: =AA8*$C8 | AE8: =AD8*$C8 | AH8: =AG8*$C8 | AN8: =AM8*$C8 | AO8: =E8+H8+K8+N8+Q8+T8+W8+Z8+AC8+AF8+AI8+AL8 | AP8: =F8+I8+L8+O8+R8+U8+X8+AA8+AD8+AG8+AJ8+AM8 | AQ8: =G8+J8+M8+P8+S8+V8+Y8+AB8+AE8+AH8+AK8+AN8 | AR8: =+AP8/12 | AS8: =+AQ8/12 | AY8: =AX8*$C8 | BK8: =BJ8*$C8 | BN8: =BM8*C8 | BQ8: =BP8*C8 | BT8: =BS8*C8 | BW8: =BV8*C8 | BZ8: =BY8*C8 | CC8: =CB8*C8 | CD8: =AT8+AW8+AZ8+BC8+BF8+BI8+BL8+BO8+BR8+BU8+BX8+CA8 | CE8: =AU8+AX8+BA8+BD8+BG8+BJ8+BM8+BP8+BS8+BV8+BY8+CB8 | CF8: =AV8+AY8+BB8+BE8+BH8+BK8+BN8+BQ8+BT8+BW8+BZ8+CC8 | CG8: =+CE8/12 | CH8: =+CF8/12 | CK8: =CJ8*C8 | CN8: =CM8*C8 | DS8: =CI8+CL8+CO8+CR8+CU8+CX8+DA8+DD8+DG8+DJ8+DM8+DP8 | DT8: =CJ8+CM8+CP8+CS8+CV8+CY8+DB8+DE8+DH8+DK8+DN8+DQ8 | DU8: =CK8+CN8+CQ8+CT8+CW8+CZ8+DC8+DF8+DI8+DL8+DO8+DR8
A9: 5 | B9: "Zay" (0.35 Liter) | C9: 0.35 | D9: 1 * 40 | G9: =F9*$C9 | J9: =I9*$C9 | M9: =L9*$C9 | P9: =O9*$C9 | V9: =U9*$C9 | Y9: =X9*$C9 | AB9: =AA9*$C9 | AE9: =AD9*$C9 | AH9: =AG9*$C9 | AN9: =AM9*$C9 | AO9: =E9+H9+K9+N9+Q9+T9+W9+Z9+AC9+AF9+AI9+AL9 | AP9: =F9+I9+L9+O9+R9+U9+X9+AA9+AD9+AG9+AJ9+AM9 | AQ9: =G9+J9+M9+P9+S9+V9+Y9+AB9+AE9+AH9+AK9+AN9 | AR9: =+AP9/12 | AS9: =+AQ9/12 | AY9: =AX9*$C9 | BK9: =BJ9*$C9 | BN9: =BM9*C9 | BQ9: =BP9*C9 | BT9: =BS9*C9 | BW9: =BV9*C9 | BZ9: =BY9*C9 | CC9: =CB9*C9 | CD9: =AT9+AW9+AZ9+BC9+BF9+BI9+BL9+BO9+BR9+BU9+BX9+CA9 | CE9: =AU9+AX9+BA9+BD9+BG9+BJ9+BM9+BP9+BS9+BV9+BY9+CB9 | CF9: =AV9+AY9+BB9+BE9+BH9+BK9+BN9+BQ9+BT9+BW9+BZ9+CC9 | CG9: =+CE9/12 | CH9: =+CF9/12 | CK9: =CJ9*C9 | CN9: =CM9*C9 | DS9: =CI9+CL9+CO9+CR9+CU9+CX9+DA9+DD9+DG9+DJ9+DM9+DP9 | DT9: =CJ9+CM9+CP9+CS9+CV9+CY9+DB9+DE9+DH9+DK9+DN9+DQ9 | DU9: =CK9+CN9+CQ9+CT9+CW9+CZ9+DC9+DF9+DI9+DL9+DO9+DR9
A10: 6 | B10: "Zay" Vodka | C10: 0.7 | D10: 1 * 24 | G10: =F10*$C10 | J10: =I10*$C10 | M10: =L10*$C10 | P10: =O10*$C10 | V10: =U10*$C10 | Y10: =X10*$C10 | AB10: =AA10*$C10 | AE10: =AD10*$C10 | AH10: =AG10*$C10 | AN10: =AM10*$C10 | AO10: =E10+H10+K10+N10+Q10+T10+W10+Z10+AC10+AF10+AI10+AL10 | AP10: =F10+I10+L10+O10+R10+U10+X10+AA10+AD10+AG10+AJ10+AM10 | AQ10: =G10+J10+M10+P10+S10+V10+Y10+AB10+AE10+AH10+AK10+AN10 | AR10: =+AP10/12 | AS10: =+AQ10/12 | AY10: =AX10*$C10 | BK10: =BJ10*$C10 | BN10: =BM10*C10 | BQ10: =BP10*C10 | BT10: =BS10*C10 | BW10: =BV10*C10 | BZ10: =BY10*C10 | CC10: =CB10*C10 | CD10: =AT10+AW10+AZ10+BC10+BF10+BI10+BL10+BO10+BR10+BU10+BX10+CA10 | CE10: =AU10+AX10+BA10+BD10+BG10+BJ10+BM10+BP10+BS10+BV10+BY10+CB10 | CF10: =AV10+AY10+BB10+BE10+BH10+BK10+BN10+BQ10+BT10+BW10+BZ10+CC10 | CG10: =+CE10/12 | CH10: =+CF10/12 | CK10: =CJ10*C10 | CN10: =CM10*C10 | DS10: =CI10+CL10+CO10+CR10+CU10+CX10+DA10+DD10+DG10+DJ10+DM10+DP10 | DT10: =CJ10+CM10+CP10+CS10+CV10+CY10+DB10+DE10+DH10+DK10+DN10+DQ10 | DU10: =CK10+CN10+CQ10+CT10+CW10+CZ10+DC10+DF10+DI10+DL10+DO10+DR10
A11: 7 | B11: "Zay" - 640ml | C11: 0.64 | D11: 1 * 24 | G11: =F11*$C11 | J11: =I11*$C11 | M11: =L11*$C11 | P11: =O11*$C11 | V11: =U11*$C11 | Y11: =X11*$C11 | AB11: =AA11*$C11 | AE11: =AD11*$C11 | AH11: =AG11*$C11 | AN11: =AM11*$C11 | AO11: =E11+H11+K11+N11+Q11+T11+W11+Z11+AC11+AF11+AI11+AL11 | AP11: =F11+I11+L11+O11+R11+U11+X11+AA11+AD11+AG11+AJ11+AM11 | AQ11: =G11+J11+M11+P11+S11+V11+Y11+AB11+AE11+AH11+AK11+AN11 | AR11: =+AP11/12 | AS11: =+AQ11/12 | AY11: =AX11*$C11 | BK11: =BJ11*$C11 | BN11: =BM11*C11 | BQ11: =BP11*C11 | BT11: =BS11*C11 | BW11: =BV11*C11 | BZ11: =BY11*C11 | CC11: =CB11*C11 | CD11: =AT11+AW11+AZ11+BC11+BF11+BI11+BL11+BO11+BR11+BU11+BX11+CA11 | CE11: =AU11+AX11+BA11+BD11+BG11+BJ11+BM11+BP11+BS11+BV11+BY11+CB11 | CF11: =AV11+AY11+BB11+BE11+BH11+BK11+BN11+BQ11+BT11+BW11+BZ11+CC11 | CG11: =+CE11/12 | CH11: =+CF11/12 | CK11: =CJ11*C11 | CN11: =CM11*C11 | DS11: =CI11+CL11+CO11+CR11+CU11+CX11+DA11+DD11+DG11+DJ11+DM11+DP11 | DT11: =CJ11+CM11+CP11+CS11+CV11+CY11+DB11+DE11+DH11+DK11+DN11+DQ11 | DU11: =CK11+CN11+CQ11+CT11+CW11+CZ11+DC11+DF11+DI11+DL11+DO11+DR11
A12: 8 | B12: "Zay" - 640ml | C12: 0.64 | D12: 1 * 14 | E12: 2691 | F12: 37674 | G12: =F12*$C12 | H12: 2290 | I12: 32060 | J12: =I12*$C12 | K12: 2332 | L12: 32648 | M12: =L12*$C12 | N12: 2366 | O12: 33124 | P12: =O12*$C12 | Q12: 2615 | R12: 36616 | S12: =R12*$C12 | T12: 2075 | U12: 29059 | V12: =U12*$C12 | W12: 2262 | X12: 31675 | Y12: =X12*$C12 | Z12: 2380 | AA12: 33329 | AB12: =AA12*$C12 | AC12: 2589 | AD12: 36246 | AE12: =AD12*$C12 | AF12: 2481 | AG12: 34734 | AH12: =AG12*$C12 | AI12: 2464 | AJ12: 34496 | AK12: =AJ12*$C12 | AL12: 2694 | AM12: 37716 | AN12: =AM12*$C12 | AO12: =E12+H12+K12+N12+Q12+T12+W12+Z12+AC12+AF12+AI12+AL12 | AP12: =F12+I12+L12+O12+R12+U12+X12+AA12+AD12+AG12+AJ12+AM12 | AQ12: =G12+J12+M12+P12+S12+V12+Y12+AB12+AE12+AH12+AK12+AN12 | AR12: =+AP12/12 | AS12: =+AQ12/12 | AT12: 2503 | AU12: 35045 | AV12: 22428.8 | AW12: 2402 | AX12: 33628 | AY12: 21521.92 | AZ12: 2256 | BA12: 31584 | BB12: =BA12*$C12 | BC12: 2103 | BD12: 29442 | BE12: =BD12*$C12 | BF12: 2253 | BG12: 31546 | BH12: =BG12*$C12 | BI12: 2376 | BJ12: 33270 | BK12: =BJ12*$C12 | BL12: 2727 | BM12: 38187 | BN12: =BM12*C12 | BO12: 2267 | BP12: 31738 | BQ12: =BP12*C12 | BR12: 2456 | BS12: 34394 | BT12: =BS12*C12 | BU12: 2460 | BV12: 34446 | BW12: =BV12*C12 | BX12: 2293 | BY12: 32102 | BZ12: =BY12*C12 | CA12: 2433 | CB12: 34069 | CC12: =CB12*C12 | CD12: =AT12+AW12+AZ12+BC12+BF12+BI12+BL12+BO12+BR12+BU12+BX12+CA12 | CE12: =AU12+AX12+BA12+BD12+BG12+BJ12+BM12+BP12+BS12+BV12+BY12+CB12 | CF12: =AV12+AY12+BB12+BE12+BH12+BK12+BN12+BQ12+BT12+BW12+BZ12+CC12 | CG12: =+CE12/12 | CH12: =+CF12/12 | CI12: 2124 | CJ12: 29736 | CK12: =CJ12*C12 | CL12: 2032 | CM12: 28453 | CN12: =CM12*C12 | DS12: =CI12+CL12+CO12+CR12+CU12+CX12+DA12+DD12+DG12+DJ12+DM12+DP12 | DT12: =CJ12+CM12+CP12+CS12+CV12+CY12+DB12+DE12+DH12+DK12+DN12+DQ12 | DU12: =CK12+CN12+CQ12+CT12+CW12+CZ12+DC12+DF12+DI12+DL12+DO12+DR12
A13: 9 | B13: "Zay" - 640ml | C13: 0.64 | D13: 1 * 12 | G13: =F13*$C13 | J13: =I13*$C13 | M13: =L13*$C13 | P13: =O13*$C13 | S13: =R13*$C13 | V13: =U13*$C13 | Y13: =X13*$C13 | AB13: =AA13*$C13 | AE13: =AD13*$C13 | AH13: =AG13*$C13 | AK13: =AJ13*$C13 | AN13: =AM13*$C13 | AO13: =E13+H13+K13+N13+Q13+T13+W13+Z13+AC13+AF13+AI13+AL13 | AP13: =F13+I13+L13+O13+R13+U13+X13+AA13+AD13+AG13+AJ13+AM13 | AQ13: =G13+J13+M13+P13+S13+V13+Y13+AB13+AE13+AH13+AK13+AN13 | AR13: =+AP13/12 | AS13: =+AQ13/12 | AY13: =AX13*$C13 | BB13: =BA13*$C13 | BE13: =BD13*$C13 | BH13: =BG13*$C13 | BK13: =BJ13*$C13 | BN13: =BM13*C13 | BQ13: =BP13*C13 | BT13: =BS13*C13 | BW13: =BV13*C13 | BZ13: =BY13*C13 | CC13: =CB13*C13 | CD13: =AT13+AW13+AZ13+BC13+BF13+BI13+BL13+BO13+BR13+BU13+BX13+CA13 | CE13: =AU13+AX13+BA13+BD13+BG13+BJ13+BM13+BP13+BS13+BV13+BY13+CB13 | CF13: =AV13+AY13+BB13+BE13+BH13+BK13+BN13+BQ13+BT13+BW13+BZ13+CC13 | CG13: =+CE13/12 | CH13: =+CF13/12 | CK13: =CJ13*C13 | CN13: =CM13*C13 | DS13: =CI13+CL13+CO13+CR13+CU13+CX13+DA13+DD13+DG13+DJ13+DM13+DP13 | DT13: =CJ13+CM13+CP13+CS13+CV13+CY13+DB13+DE13+DH13+DK13+DN13+DQ13 | DU13: =CK13+CN13+CQ13+CT13+CW13+CZ13+DC13+DF13+DI13+DL13+DO13+DR13
A14: 10 | B14: "Zay" - 640ml | C14: 0.64 | D14: 1 * 14 | G14: =F14*$C14 | M14: =L14*$C14 | P14: =O14*$C14 | S14: =R14*$C14 | V14: =U14*$C14 | Y14: =X14*$C14 | AB14: =AA14*$C14 | AE14: =AD14*$C14 | AH14: =AG14*$C14 | AK14: =AJ14*$C14 | AN14: =AM14*$C14 | AO14: =E14+H14+K14+N14+Q14+T14+W14+Z14+AC14+AF14+AI14+AL14 | AP14: =F14+I14+L14+O14+R14+U14+X14+AA14+AD14+AG14+AJ14+AM14 | AQ14: =G14+J14+M14+P14+S14+V14+Y14+AB14+AE14+AH14+AK14+AN14 | AR14: =+AP14/12 | AS14: =+AQ14/12 | BB14: =BA14*$C14 | BE14: =BD14*$C14 | BH14: =BG14*$C14 | BK14: =BJ14*$C14 | BN14: =BM14*C14 | BQ14: =BP14*C14 | BT14: =BS14*C14 | BW14: =BV14*C14 | BZ14: =BY14*C14 | CC14: =CB14*C14 | CD14: =AT14+AW14+AZ14+BC14+BF14+BI14+BL14+BO14+BR14+BU14+BX14+CA14 | CE14: =AU14+AX14+BA14+BD14+BG14+BJ14+BM14+BP14+BS14+BV14+BY14+CB14 | CF14: =AV14+AY14+BB14+BE14+BH14+BK14+BN14+BQ14+BT14+BW14+BZ14+CC14 | CG14: =+CE14/12 | CH14: =+CF14/12 | CK14: =CJ14*C14 | CN14: =CM14*C14 | DS14: =CI14+CL14+CO14+CR14+CU14+CX14+DA14+DD14+DG14+DJ14+DM14+DP14 | DT14: =CJ14+CM14+CP14+CS14+CV14+CY14+DB14+DE14+DH14+DK14+DN14+DQ14 | DU14: =CK14+CN14+CQ14+CT14+CW14+CZ14+DC14+DF14+DI14+DL14+DO14+DR14
G15: =F15*$C15 | J15: =I15*$C15 | M15: =L15*$C15 | P15: =O15*$C15 | S15: =R15*$C15 | V15: =U15*$C15 | Y15: =X15*$C15 | AB15: =AA15*$C15 | AE15: =AD15*$C15 | AH15: =AG15*$C15 | AK15: =AJ15*$C15 | AN15: =AM15*$C15 | AO15: =E15+H15+K15+N15+Q15+T15+W15+Z15+AC15+AF15+AI15+AL15 | AP15: =F15+I15+L15+O15+R15+U15+X15+AA15+AD15+AG15+AJ15+AM15 | AQ15: =G15+J15+M15+P15+S15+V15+Y15+AB15+AE15+AH15+AK15+AN15 | AR15: =+AP15/12 | AS15: =+AQ15/12 | AY15: =AX15*$C15 | BB15: =BA15*$C15 | BE15: =BD15*$C15 | BH15: =BG15*$C15 | BK15: =BJ15*$C15 | BN15: =BM15*C15 | BQ15: =BP15*C15 | BT15: =BS15*C15 | BW15: =BV15*C15 | BZ15: =BY15*C15 | CC15: =CB15*C15 | CD15: =AT15+AW15+AZ15+BC15+BF15+BI15+BL15+BO15+BR15+BU15+BX15+CA15 | CE15: =AU15+AX15+BA15+BD15+BG15+BJ15+BM15+BP15+BS15+BV15+BY15+CB15 | CF15: =AV15+AY15+BB15+BE15+BH15+BK15+BN15+BQ15+BT15+BW15+BZ15+CC15 | CG15: =+CE15/12 | CH15: =+CF15/12 | CK15: =CJ15*C15 | CN15: =CM15*C15 | DS15: =CI15+CL15+CO15+CR15+CU15+CX15+DA15+DD15+DG15+DJ15+DM15+DP15 | DT15: =CJ15+CM15+CP15+CS15+CV15+CY15+DB15+DE15+DH15+DK15+DN15+DQ15 | DU15: =CK15+CN15+CQ15+CT15+CW15+CZ15+DC15+DF15+DI15+DL15+DO15+DR15
A16: 11 | B16: Kaung Kyi (1 Liter)_25% | C16: 1 | D16: 1 * 12 | E16: 570 | F16: 6840 | G16: =F16*$C16 | H16: 460 | I16: 5520 | J16: =I16*$C16 | K16: 391 | L16: 4692 | M16: =L16*$C16 | N16: 455 | O16: 5460 | P16: =O16*$C16 | Q16: 447 | R16: 5364 | S16: =R16*$C16 | T16: 488 | U16: 5856 | V16: =U16*$C16 | W16: 690 | X16: 8280 | Y16: =X16*$C16 | Z16: 690 | AA16: 8280 | AB16: =AA16*$C16 | AC16: 890 | AD16: 10680 | AE16: =AD16*$C16 | AF16: 1050 | AG16: 12600 | AH16: =AG16*$C16 | AI16: 800 | AJ16: 9600 | AK16: =AJ16*$C16 | AL16: 1015 | AM16: 12180 | AN16: =AM16*$C16 | AO16: =E16+H16+K16+N16+Q16+T16+W16+Z16+AC16+AF16+AI16+AL16 | AP16: =F16+I16+L16+O16+R16+U16+X16+AA16+AD16+AG16+AJ16+AM16 | AQ16: =G16+J16+M16+P16+S16+V16+Y16+AB16+AE16+AH16+AK16+AN16 | AR16: =+AP16/12 | AS16: =+AQ16/12 | AT16: 1162 | AU16: 13944 | AV16: 13944 | AW16: 555 | AX16: 6660 | AY16: 6660 | AZ16: 825 | BA16: 9900 | BB16: =BA16*$C16 | BC16: 980 | BD16: 11760 | BE16: =BD16*$C16 | BF16: 1099 | BG16: 13188 | BH16: =BG16*$C16 | BI16: 1175 | BJ16: 14100 | BK16: =BJ16*$C16 | BL16: 1077 | BM16: 12924 | BN16: =BM16*C16 | BO16: 1385 | BP16: 16620 | BQ16: =BP16*C16 | BR16: 1680 | BS16: 20160 | BT16: =BS16*C16 | BU16: 1500 | BV16: 18000 | BW16: =BV16*C16 | BX16: 1226 | BY16: 14712 | BZ16: =BY16*C16 | CA16: 1370 | CB16: 16440 | CC16: =CB16*C16 | CD16: =AT16+AW16+AZ16+BC16+BF16+BI16+BL16+BO16+BR16+BU16+BX16+CA16 | CE16: =AU16+AX16+BA16+BD16+BG16+BJ16+BM16+BP16+BS16+BV16+BY16+CB16 | CF16: =AV16+AY16+BB16+BE16+BH16+BK16+BN16+BQ16+BT16+BW16+BZ16+CC16 | CG16: =+CE16/12 | CH16: =+CF16/12 | CI16: 1802 | CJ16: 21628 | CK16: =CJ16*C16 | CL16: 1079 | CM16: 12952 | CN16: =CM16*C16 | DS16: =CI16+CL16+CO16+CR16+CU16+CX16+DA16+DD16+DG16+DJ16+DM16+DP16 | DT16: =CJ16+CM16+CP16+CS16+CV16+CY16+DB16+DE16+DH16+DK16+DN16+DQ16 | DU16: =CK16+CN16+CQ16+CT16+CW16+CZ16+DC16+DF16+DI16+DL16+DO16+DR16
A17: 12 | B17: Kaung Kyi (1 Liter)_40% | C17: 1 | D17: 1 * 12 | G17: =F17*$C17 | J17: =I17*$C17 | M17: =L17*$C17 | P17: =O17*$C17 | S17: =R17*$C17 | V17: =U17*$C17 | Y17: =X17*$C17 | AB17: =AA17*$C17 | AE17: =AD17*$C17 | AH17: =AG17*$C17 | AK17: =AJ17*$C17 | AN17: =AM17*$C17 | AO17: =E17+H17+K17+N17+Q17+T17+W17+Z17+AC17+AF17+AI17+AL17 | AP17: =F17+I17+L17+O17+R17+U17+X17+AA17+AD17+AG17+AJ17+AM17 | AQ17: =G17+J17+M17+P17+S17+V17+Y17+AB17+AE17+AH17+AK17+AN17 | AR17: =+AP17/12 | AS17: =+AQ17/12 | AY17: =AX17*$C17 | BB17: =BA17*$C17 | BE17: =BD17*$C17 | BH17: =BG17*$C17 | BK17: =BJ17*$C17 | BN17: =BM17*C17 | BQ17: =BP17*C17 | BT17: =BS17*C17 | BW17: =BV17*C17 | BZ17: =BY17*C17 | CC17: =CB17*C17 | CD17: =AT17+AW17+AZ17+BC17+BF17+BI17+BL17+BO17+BR17+BU17+BX17+CA17 | CE17: =AU17+AX17+BA17+BD17+BG17+BJ17+BM17+BP17+BS17+BV17+BY17+CB17 | CF17: =AV17+AY17+BB17+BE17+BH17+BK17+BN17+BQ17+BT17+BW17+BZ17+CC17 | CG17: =+CE17/12 | CH17: =+CF17/12 | CK17: =CJ17*C17 | CN17: =CM17*C17 | DS17: =CI17+CL17+CO17+CR17+CU17+CX17+DA17+DD17+DG17+DJ17+DM17+DP17 | DT17: =CJ17+CM17+CP17+CS17+CV17+CY17+DB17+DE17+DH17+DK17+DN17+DQ17 | DU17: =CK17+CN17+CQ17+CT17+CW17+CZ17+DC17+DF17+DI17+DL17+DO17+DR17
A18: 13 | B18: Kaung Kyi (0.6 Liter)_25% | C18: 0.6 | D18: 1 * 12 | E18: 45 | F18: 540 | G18: =F18*$C18 | H18: 25 | I18: 300 | J18: =I18*$C18 | K18: 41 | L18: 492 | M18: =L18*$C18 | N18: 6 | O18: 72 | P18: =O18*$C18 | S18: =R18*$C18 | T18: 3 | U18: 36 | V18: =U18*$C18 | W18: 21 | X18: 252 | Y18: =X18*$C18 | AB18: =AA18*$C18 | AC18: 50 | AD18: 600 | AE18: =AD18*$C18 | AF18: 50 | AG18: 600 | AH18: =AG18*$C18 | AI18: 80 | AJ18: 960 | AK18: =AJ18*$C18 | AL18: 10 | AM18: 120 | AN18: =AM18*$C18 | AO18: =E18+H18+K18+N18+Q18+T18+W18+Z18+AC18+AF18+AI18+AL18 | AP18: =F18+I18+L18+O18+R18+U18+X18+AA18+AD18+AG18+AJ18+AM18 | AQ18: =G18+J18+M18+P18+S18+V18+Y18+AB18+AE18+AH18+AK18+AN18 | AR18: =+AP18/12 | AS18: =+AQ18/12 | AT18: 21 | AU18: 252 | AV18: 151.2 | AW18: 35 | AX18: 420 | AY18: 252 | AZ18: 20 | BA18: 240 | BB18: =BA18*$C18 | BC18: 15 | BD18: 180 | BE18: =BD18*$C18 | BF18: 40 | BG18: 480 | BH18: =BG18*$C18 | BI18: 20 | BJ18: 240 | BK18: =BJ18*$C18 | BL18: 20 | BM18: 240 | BN18: =BM18*C18 | BO18: 20 | BP18: 240 | BQ18: =BP18*C18 | BR18: 30 | BS18: 360 | BT18: =BS18*C18 | BU18: 35 | BV18: 420 | BW18: =BV18*C18 | BZ18: =BY18*C18 | CA18: 20 | CB18: 240 | CC18: =CB18*C18 | CD18: =AT18+AW18+AZ18+BC18+BF18+BI18+BL18+BO18+BR18+BU18+BX18+CA18 | CE18: =AU18+AX18+BA18+BD18+BG18+BJ18+BM18+BP18+BS18+BV18+BY18+CB18 | CF18: =AV18+AY18+BB18+BE18+BH18+BK18+BN18+BQ18+BT18+BW18+BZ18+CC18 | CG18: =+CE18/12 | CH18: =+CF18/12 | CK18: =CJ18*C18 | CN18: =CM18*C18 | DS18: =CI18+CL18+CO18+CR18+CU18+CX18+DA18+DD18+DG18+DJ18+DM18+DP18 | DT18: =CJ18+CM18+CP18+CS18+CV18+CY18+DB18+DE18+DH18+DK18+DN18+DQ18 | DU18: =CK18+CN18+CQ18+CT18+CW18+CZ18+DC18+DF18+DI18+DL18+DO18+DR18
A19: 14 | B19: Kaung Kyi (0.6 Liter)_40% | C19: 0.6 | D19: 1 * 12 | G19: =F19*$C19 | J19: =I19*$C19 | M19: =L19*$C19 | P19: =O19*$C19 | S19: =R19*$C19 | V19: =U19*$C19 | Y19: =X19*$C19 | AB19: =AA19*$C19 | AE19: =AD19*$C19 | AH19: =AG19*$C19 | AK19: =AJ19*$C19 | AN19: =AM19*$C19 | AO19: =E19+H19+K19+N19+Q19+T19+W19+Z19+AC19+AF19+AI19+AL19 | AP19: =F19+I19+L19+O19+R19+U19+X19+AA19+AD19+AG19+AJ19+AM19 | AQ19: =G19+J19+M19+P19+S19+V19+Y19+AB19+AE19+AH19+AK19+AN19 | AR19: =+AP19/12 | AS19: =+AQ19/12 | AY19: =AX19*$C19 | BB19: =BA19*$C19 | BE19: =BD19*$C19 | BH19: =BG19*$C19 | BK19: =BJ19*$C19 | BN19: =BM19*C19 | BQ19: =BP19*C19 | BT19: =BS19*C19 | BW19: =BV19*C19 | BZ19: =BY19*C19 | CC19: =CB19*C19 | CD19: =AT19+AW19+AZ19+BC19+BF19+BI19+BL19+BO19+BR19+BU19+BX19+CA19 | CE19: =AU19+AX19+BA19+BD19+BG19+BJ19+BM19+BP19+BS19+BV19+BY19+CB19 | CF19: =AV19+AY19+BB19+BE19+BH19+BK19+BN19+BQ19+BT19+BW19+BZ19+CC19 | CG19: =+CE19/12 | CH19: =+CF19/12 | CK19: =CJ19*C19 | CN19: =CM19*C19 | DS19: =CI19+CL19+CO19+CR19+CU19+CX19+DA19+DD19+DG19+DJ19+DM19+DP19 | DT19: =CJ19+CM19+CP19+CS19+CV19+CY19+DB19+DE19+DH19+DK19+DN19+DQ19 | DU19: =CK19+CN19+CQ19+CT19+CW19+CZ19+DC19+DF19+DI19+DL19+DO19+DR19
A20: 15 | B20: Kaung Kyi (0.35 Liter)_25% | C20: 0.35 | D20: 1 * 40 | G20: =F20*$C20 | J20: =I20*$C20 | M20: =L20*$C20 | P20: =O20*$C20 | S20: =R20*$C20 | V20: =U20*$C20 | Y20: =X20*$C20 | AB20: =AA20*$C20 | AE20: =AD20*$C20 | AH20: =AG20*$C20 | AK20: =AJ20*$C20 | AN20: =AM20*$C20 | AO20: =E20+H20+K20+N20+Q20+T20+W20+Z20+AC20+AF20+AI20+AL20 | AP20: =F20+I20+L20+O20+R20+U20+X20+AA20+AD20+AG20+AJ20+AM20 | AQ20: =G20+J20+M20+P20+S20+V20+Y20+AB20+AE20+AH20+AK20+AN20 | AR20: =+AP20/12 | AS20: =+AQ20/12 | AY20: =AX20*$C20 | BB20: =BA20*$C20 | BE20: =BD20*$C20 | BH20: =BG20*$C20 | BK20: =BJ20*$C20 | BN20: =BM20*C20 | BQ20: =BP20*C20 | BT20: =BS20*C20 | BW20: =BV20*C20 | BZ20: =BY20*C20 | CC20: =CB20*C20 | CD20: =AT20+AW20+AZ20+BC20+BF20+BI20+BL20+BO20+BR20+BU20+BX20+CA20 | CE20: =AU20+AX20+BA20+BD20+BG20+BJ20+BM20+BP20+BS20+BV20+BY20+CB20 | CF20: =AV20+AY20+BB20+BE20+BH20+BK20+BN20+BQ20+BT20+BW20+BZ20+CC20 | CG20: =+CE20/12 | CH20: =+CF20/12 | CK20: =CJ20*C20 | CN20: =CM20*C20 | DS20: =CI20+CL20+CO20+CR20+CU20+CX20+DA20+DD20+DG20+DJ20+DM20+DP20 | DT20: =CJ20+CM20+CP20+CS20+CV20+CY20+DB20+DE20+DH20+DK20+DN20+DQ20 | DU20: =CK20+CN20+CQ20+CT20+CW20+CZ20+DC20+DF20+DI20+DL20+DO20+DR20
A21: 16 | B21: Kaung Kyi ( 0.35 Liter) - 40% | C21: 0.35 | D21: 1 * 40 | G21: =F21*$C21 | J21: =I21*$C21 | M21: =L21*$C21 | P21: =O21*$C21 | S21: =R21*$C21 | V21: =U21*$C21 | Y21: =X21*$C21 | AB21: =AA21*$C21 | AE21: =AD21*$C21 | AH21: =AG21*$C21 | AK21: =AJ21*$C21 | AN21: =AM21*$C21 | AO21: =E21+H21+K21+N21+Q21+T21+W21+Z21+AC21+AF21+AI21+AL21 | AP21: =F21+I21+L21+O21+R21+U21+X21+AA21+AD21+AG21+AJ21+AM21 | AQ21: =G21+J21+M21+P21+S21+V21+Y21+AB21+AE21+AH21+AK21+AN21 | AR21: =+AP21/12 | AS21: =+AQ21/12 | AY21: =AX21*$C21 | BB21: =BA21*$C21 | BE21: =BD21*$C21 | BH21: =BG21*$C21 | BK21: =BJ21*$C21 | BN21: =BM21*C21 | BQ21: =BP21*C21 | BT21: =BS21*C21 | BW21: =BV21*C21 | BZ21: =BY21*C21 | CC21: =CB21*C21 | CD21: =AT21+AW21+AZ21+BC21+BF21+BI21+BL21+BO21+BR21+BU21+BX21+CA21 | CE21: =AU21+AX21+BA21+BD21+BG21+BJ21+BM21+BP21+BS21+BV21+BY21+CB21 | CF21: =AV21+AY21+BB21+BE21+BH21+BK21+BN21+BQ21+BT21+BW21+BZ21+CC21 | CG21: =+CE21/12 | CH21: =+CF21/12 | CK21: =CJ21*C21 | CN21: =CM21*C21 | DS21: =CI21+CL21+CO21+CR21+CU21+CX21+DA21+DD21+DG21+DJ21+DM21+DP21 | DT21: =CJ21+CM21+CP21+CS21+CV21+CY21+DB21+DE21+DH21+DK21+DN21+DQ21 | DU21: =CK21+CN21+CQ21+CT21+CW21+CZ21+DC21+DF21+DI21+DL21+DO21+DR21
A22: 17 | B22: Kaung Kyi | C22: 0.64 | D22: 1 * 14 | E22: 2817 | F22: 39438 | G22: =F22*$C22 | H22: 1867 | I22: 26144 | J22: =I22*$C22 | K22: 2439 | L22: 34146 | M22: =L22*$C22 | N22: 1962 | O22: 27468 | P22: =O22*$C22 | Q22: 2186 | R22: 30610 | S22: =R22*$C22 | T22: 2058 | U22: 28812 | V22: =U22*$C22 | W22: 2040 | X22: 28564 | Y22: =X22*$C22 | Z22: 1903 | AA22: 26642 | AB22: =AA22*$C22 | AC22: 2209 | AD22: 30926 | AE22: =AD22*$C22 | AF22: 2230 | AG22: 31220 | AH22: =AG22*$C22 | AI22: 2634 | AJ22: 36876 | AK22: =AJ22*$C22 | AL22: 3346 | AM22: 46844 | AN22: =AM22*$C22 | AO22: =E22+H22+K22+N22+Q22+T22+W22+Z22+AC22+AF22+AI22+AL22 | AP22: =F22+I22+L22+O22+R22+U22+X22+AA22+AD22+AG22+AJ22+AM22 | AQ22: =G22+J22+M22+P22+S22+V22+Y22+AB22+AE22+AH22+AK22+AN22 | AR22: =+AP22/12 | AS22: =+AQ22/12 | AT22: 3057 | AU22: 42798 | AV22: 27390.72 | AW22: 2022 | AX22: 28308 | AY22: 18117.12 | AZ22: 2227 | BA22: 31178 | BB22: =BA22*$C22 | BC22: 2562 | BD22: 35868 | BE22: =BD22*$C22 | BF22: 2506 | BG22: 35087 | BH22: =BG22*$C22 | BI22: 2301 | BJ22: 32225 | BK22: =BJ22*$C22 | BL22: 2440 | BM22: 34167 | BN22: =BM22*C22 | BO22: 2165 | BP22: 30310 | BQ22: =BP22*C22 | BR22: 2356 | BS22: 32993 | BT22: =BS22*C22 | BU22: 2421 | BV22: 33894 | BW22: =BV22*C22 | BX22: 2401 | BY22: 33614 | BZ22: =BY22*C22 | CA22: 2475 | CB22: 34650 | CC22: =CB22*C22 | CD22: =AT22+AW22+AZ22+BC22+BF22+BI22+BL22+BO22+BR22+BU22+BX22+CA22 | CE22: =AU22+AX22+BA22+BD22+BG22+BJ22+BM22+BP22+BS22+BV22+BY22+CB22 | CF22: =AV22+AY22+BB22+BE22+BH22+BK22+BN22+BQ22+BT22+BW22+BZ22+CC22 | CG22: =+CE22/12 | CH22: =+CF22/12 | CI22: 2093 | CJ22: 29302 | CK22: =CJ22*C22 | CL22: 2066 | CM22: 28924 | CN22: =CM22*C22 | DS22: =CI22+CL22+CO22+CR22+CU22+CX22+DA22+DD22+DG22+DJ22+DM22+DP22 | DT22: =CJ22+CM22+CP22+CS22+CV22+CY22+DB22+DE22+DH22+DK22+DN22+DQ22 | DU22: =CK22+CN22+CQ22+CT22+CW22+CZ22+DC22+DF22+DI22+DL22+DO22+DR22
A23: 18 | B23: Kaung Kyi (40%) | C23: 0.64 | D23: 1 * 14 | G23: =F23*$C23 | J23: =I23*$C23 | M23: =L23*$C23 | P23: =O23*$C23 | S23: =R23*$C23 | V23: =U23*$C23 | Y23: =X23*$C23 | AB23: =AA23*$C23 | AE23: =AD23*$C23 | AH23: =AG23*$C23 | AK23: =AJ23*$C23 | AN23: =AM23*$C23 | AO23: =E23+H23+K23+N23+Q23+T23+W23+Z23+AC23+AF23+AI23+AL23 | AP23: =F23+I23+L23+O23+R23+U23+X23+AA23+AD23+AG23+AJ23+AM23 | AQ23: =G23+J23+M23+P23+S23+V23+Y23+AB23+AE23+AH23+AK23+AN23 | AR23: =+AP23/12 | AS23: =+AQ23/12 | AY23: =AX23*$C23 | BB23: =BA23*$C23 | BE23: =BD23*$C23 | BH23: =BG23*$C23 | BK23: =BJ23*$C23 | BN23: =BM23*C23 | BQ23: =BP23*C23 | BT23: =BS23*C23 | BW23: =BV23*C23 | BZ23: =BY23*C23 | CC23: =CB23*C23 | CD23: =AT23+AW23+AZ23+BC23+BF23+BI23+BL23+BO23+BR23+BU23+BX23+CA23 | CE23: =AU23+AX23+BA23+BD23+BG23+BJ23+BM23+BP23+BS23+BV23+BY23+CB23 | CF23: =AV23+AY23+BB23+BE23+BH23+BK23+BN23+BQ23+BT23+BW23+BZ23+CC23 | CG23: =+CE23/12 | CH23: =+CF23/12 | CK23: =CJ23*C23 | CN23: =CM23*C23 | DS23: =CI23+CL23+CO23+CR23+CU23+CX23+DA23+DD23+DG23+DJ23+DM23+DP23 | DT23: =CJ23+CM23+CP23+CS23+CV23+CY23+DB23+DE23+DH23+DK23+DN23+DQ23 | DU23: =CK23+CN23+CQ23+CT23+CW23+CZ23+DC23+DF23+DI23+DL23+DO23+DR23
A24: 19 | B24: Kaung Kyi (46%) | C24: 0.64 | D24: 1 * 14 | G24: =F24*$C24 | J24: =I24*$C24 | M24: =L24*$C24 | P24: =O24*$C24 | S24: =R24*$C24 | V24: =U24*$C24 | Y24: =X24*$C24 | AB24: =AA24*$C24 | AE24: =AD24*$C24 | AH24: =AG24*$C24 | AK24: =AJ24*$C24 | AN24: =AM24*$C24 | AO24: =E24+H24+K24+N24+Q24+T24+W24+Z24+AC24+AF24+AI24+AL24 | AP24: =F24+I24+L24+O24+R24+U24+X24+AA24+AD24+AG24+AJ24+AM24 | AQ24: =G24+J24+M24+P24+S24+V24+Y24+AB24+AE24+AH24+AK24+AN24 | AR24: =+AP24/12 | AS24: =+AQ24/12 | AY24: =AX24*$C24 | BB24: =BA24*$C24 | BE24: =BD24*$C24 | BH24: =BG24*$C24 | BK24: =BJ24*$C24 | BN24: =BM24*C24 | BQ24: =BP24*C24 | BT24: =BS24*C24 | BW24: =BV24*C24 | BZ24: =BY24*C24 | CC24: =CB24*C24 | CD24: =AT24+AW24+AZ24+BC24+BF24+BI24+BL24+BO24+BR24+BU24+BX24+CA24 | CE24: =AU24+AX24+BA24+BD24+BG24+BJ24+BM24+BP24+BS24+BV24+BY24+CB24 | CF24: =AV24+AY24+BB24+BE24+BH24+BK24+BN24+BQ24+BT24+BW24+BZ24+CC24 | CG24: =+CE24/12 | CH24: =+CF24/12 | CK24: =CJ24*C24 | CN24: =CM24*C24 | DS24: =CI24+CL24+CO24+CR24+CU24+CX24+DA24+DD24+DG24+DJ24+DM24+DP24 | DT24: =CJ24+CM24+CP24+CS24+CV24+CY24+DB24+DE24+DH24+DK24+DN24+DQ24 | DU24: =CK24+CN24+CQ24+CT24+CW24+CZ24+DC24+DF24+DI24+DL24+DO24+DR24
